package sokobanMod.common.gen.easy;

import net.minecraft.block.Block;
import net.minecraft.item.Item;
import net.minecraft.item.ItemStack;
import net.minecraft.tileentity.TileEntityChest;
import net.minecraft.tileentity.TileEntitySign;
import net.minecraft.util.WeightedRandomChestContent;
import net.minecraft.world.World;
import sokobanMod.common.SokobanMod;
import sokobanMod.common.TileEntityLootGenerator;
import sokobanMod.common.TileEntityTargetBox;
import sokobanMod.common.gen.ISokobanLevel;
import sokobanMod.common.gen.LevelGenBase;

/**
 * Sokoban Mod
 * @author MineMaarten, level designed by Lego_World_7307
 * www.minemaarten.com
 * @license Lesser GNU Public License v3 (http://www.gnu.org/licenses/lgpl.html)
 */

public class EasyLevel6Gen implements ISokobanLevel{
    private static final int[] levelBounds = {27, 9, 13};
    private static final int[] entranceCoords = {5, 2, 0, 5, 2, 13, 5, 3, 0, 5, 3, 13, 5, 4, 0, 5, 4, 13, 12, 2, 0, 12, 3, 0, 12, 4, 0, 16, 2, 13, 16, 3, 13, 16, 4, 13, 24, 2, 0, 24, 3, 0, 24, 4, 0, 27, 2, 10, 27, 3, 10, 27, 4, 10};
    public static final ItemStack[] staticInventoryContents_13_2_6 = new ItemStack[]{new ItemStack(Item.compass), new ItemStack(Item.map), new ItemStack(Item.book)};
    public static final WeightedRandomChestContent[] randomInventoryContents_13_2_6 = new WeightedRandomChestContent[]{new WeightedRandomChestContent(Item.emerald.itemID, 0, 1, 3, 10), new WeightedRandomChestContent(Item.ingotIron.itemID, 0, 7, 10, 100), new WeightedRandomChestContent(SokobanMod.ItemLevelGeneratorTutorial.itemID, 0, 1, 1, 100), new WeightedRandomChestContent(Item.legsChain.itemID, 0, 1, 1, 40), new WeightedRandomChestContent(Item.bootsChain.itemID, 0, 1, 1, 40), new WeightedRandomChestContent(Item.plateChain.itemID, 0, 1, 1, 40), new WeightedRandomChestContent(Item.helmetChain.itemID, 0, 1, 1, 40)};

    @Override
    public int getLevelNumber(){
        return 1005;
    }

    @Override
    public int[] getLevelBounds(){
        return levelBounds;
    }

    @Override
    public int[] getEntranceCoords(){
        return entranceCoords;
    }

    @Override
    public String getLevelName(){
        return "The Maze";
    }

    @Override
    public String getAuthorName(){
        return "Lego_World_7307";
    }

    @Override
    public boolean canGenerateOnSurface(){
        return false;
    }

    @Override
    public boolean canGenerateUnderground(){
        return true;
    }

    @Override
    public boolean generate(World world, ISokobanLevel.EnumGenerationMethod generationMethod, int baseX, int baseY, int baseZ){
        //base blocks
        LevelGenBase.setBlockAndMetadata(world, baseX + 0, baseY + 0, baseZ + 0, SokobanMod.BlockUnbreakableSolids.blockID, 0); //tile.Unbreakable Solid Blocks
        LevelGenBase.setBlockAndMetadata(world, baseX + 0, baseY + 0, baseZ + 1, SokobanMod.BlockUnbreakableSolids.blockID, 0); //tile.Unbreakable Solid Blocks
        LevelGenBase.setBlockAndMetadata(world, baseX + 0, baseY + 0, baseZ + 2, SokobanMod.BlockUnbreakableSolids.blockID, 0); //tile.Unbreakable Solid Blocks
        LevelGenBase.setBlockAndMetadata(world, baseX + 0, baseY + 0, baseZ + 3, SokobanMod.BlockUnbreakableSolids.blockID, 0); //tile.Unbreakable Solid Blocks
        LevelGenBase.setBlockAndMetadata(world, baseX + 0, baseY + 0, baseZ + 4, SokobanMod.BlockUnbreakableSolids.blockID, 0); //tile.Unbreakable Solid Blocks
        LevelGenBase.setBlockAndMetadata(world, baseX + 0, baseY + 0, baseZ + 5, SokobanMod.BlockUnbreakableSolids.blockID, 0); //tile.Unbreakable Solid Blocks
        LevelGenBase.setBlockAndMetadata(world, baseX + 0, baseY + 0, baseZ + 6, SokobanMod.BlockUnbreakableSolids.blockID, 0); //tile.Unbreakable Solid Blocks
        LevelGenBase.setBlockAndMetadata(world, baseX + 0, baseY + 0, baseZ + 7, SokobanMod.BlockUnbreakableSolids.blockID, 0); //tile.Unbreakable Solid Blocks
        LevelGenBase.setBlockAndMetadata(world, baseX + 0, baseY + 0, baseZ + 8, SokobanMod.BlockUnbreakableSolids.blockID, 0); //tile.Unbreakable Solid Blocks
        LevelGenBase.setBlockAndMetadata(world, baseX + 0, baseY + 0, baseZ + 9, SokobanMod.BlockUnbreakableSolids.blockID, 0); //tile.Unbreakable Solid Blocks
        LevelGenBase.setBlockAndMetadata(world, baseX + 0, baseY + 0, baseZ + 10, SokobanMod.BlockUnbreakableSolids.blockID, 0); //tile.Unbreakable Solid Blocks
        LevelGenBase.setBlockAndMetadata(world, baseX + 0, baseY + 0, baseZ + 11, SokobanMod.BlockUnbreakableSolids.blockID, 0); //tile.Unbreakable Solid Blocks
        LevelGenBase.setBlockAndMetadata(world, baseX + 0, baseY + 0, baseZ + 12, SokobanMod.BlockUnbreakableSolids.blockID, 0); //tile.Unbreakable Solid Blocks
        LevelGenBase.setBlockAndMetadata(world, baseX + 0, baseY + 0, baseZ + 13, SokobanMod.BlockUnbreakableSolids.blockID, 0); //tile.Unbreakable Solid Blocks
        LevelGenBase.setBlockAndMetadata(world, baseX + 0, baseY + 1, baseZ + 0, SokobanMod.BlockUnbreakableSolids.blockID, 0); //tile.Unbreakable Solid Blocks
        LevelGenBase.setBlockAndMetadata(world, baseX + 0, baseY + 1, baseZ + 1, SokobanMod.BlockUnbreakableSolids.blockID, 0); //tile.Unbreakable Solid Blocks
        LevelGenBase.setBlockAndMetadata(world, baseX + 0, baseY + 1, baseZ + 2, SokobanMod.BlockUnbreakableSolids.blockID, 0); //tile.Unbreakable Solid Blocks
        LevelGenBase.setBlockAndMetadata(world, baseX + 0, baseY + 1, baseZ + 3, SokobanMod.BlockUnbreakableSolids.blockID, 0); //tile.Unbreakable Solid Blocks
        LevelGenBase.setBlockAndMetadata(world, baseX + 0, baseY + 1, baseZ + 4, SokobanMod.BlockUnbreakableSolids.blockID, 0); //tile.Unbreakable Solid Blocks
        LevelGenBase.setBlockAndMetadata(world, baseX + 0, baseY + 1, baseZ + 5, SokobanMod.BlockUnbreakableSolids.blockID, 0); //tile.Unbreakable Solid Blocks
        LevelGenBase.setBlockAndMetadata(world, baseX + 0, baseY + 1, baseZ + 6, SokobanMod.BlockUnbreakableSolids.blockID, 0); //tile.Unbreakable Solid Blocks
        LevelGenBase.setBlockAndMetadata(world, baseX + 0, baseY + 1, baseZ + 7, SokobanMod.BlockUnbreakableSolids.blockID, 0); //tile.Unbreakable Solid Blocks
        LevelGenBase.setBlockAndMetadata(world, baseX + 0, baseY + 1, baseZ + 8, SokobanMod.BlockUnbreakableSolids.blockID, 0); //tile.Unbreakable Solid Blocks
        LevelGenBase.setBlockAndMetadata(world, baseX + 0, baseY + 1, baseZ + 9, SokobanMod.BlockUnbreakableSolids.blockID, 0); //tile.Unbreakable Solid Blocks
        LevelGenBase.setBlockAndMetadata(world, baseX + 0, baseY + 1, baseZ + 10, SokobanMod.BlockUnbreakableSolids.blockID, 0); //tile.Unbreakable Solid Blocks
        LevelGenBase.setBlockAndMetadata(world, baseX + 0, baseY + 1, baseZ + 11, SokobanMod.BlockUnbreakableSolids.blockID, 0); //tile.Unbreakable Solid Blocks
        LevelGenBase.setBlockAndMetadata(world, baseX + 0, baseY + 1, baseZ + 12, SokobanMod.BlockUnbreakableSolids.blockID, 0); //tile.Unbreakable Solid Blocks
        LevelGenBase.setBlockAndMetadata(world, baseX + 0, baseY + 1, baseZ + 13, SokobanMod.BlockUnbreakableSolids.blockID, 0); //tile.Unbreakable Solid Blocks
        LevelGenBase.setBlockAndMetadata(world, baseX + 0, baseY + 2, baseZ + 0, SokobanMod.BlockUnbreakableSolids.blockID, 0); //tile.Unbreakable Solid Blocks
        LevelGenBase.setBlockAndMetadata(world, baseX + 0, baseY + 2, baseZ + 1, SokobanMod.BlockUnbreakableSolids.blockID, 0); //tile.Unbreakable Solid Blocks
        LevelGenBase.setBlockAndMetadata(world, baseX + 0, baseY + 2, baseZ + 2, SokobanMod.BlockUnbreakableSolids.blockID, 0); //tile.Unbreakable Solid Blocks
        LevelGenBase.setBlockAndMetadata(world, baseX + 0, baseY + 2, baseZ + 3, SokobanMod.BlockUnbreakableSolids.blockID, 0); //tile.Unbreakable Solid Blocks
        LevelGenBase.setBlockAndMetadata(world, baseX + 0, baseY + 2, baseZ + 4, SokobanMod.BlockUnbreakableSolids.blockID, 0); //tile.Unbreakable Solid Blocks
        LevelGenBase.setBlockAndMetadata(world, baseX + 0, baseY + 2, baseZ + 5, SokobanMod.BlockUnbreakableSolids.blockID, 0); //tile.Unbreakable Solid Blocks
        LevelGenBase.setBlockAndMetadata(world, baseX + 0, baseY + 2, baseZ + 6, SokobanMod.BlockUnbreakableSolids.blockID, 0); //tile.Unbreakable Solid Blocks
        LevelGenBase.setBlockAndMetadata(world, baseX + 0, baseY + 2, baseZ + 7, SokobanMod.BlockUnbreakableSolids.blockID, 0); //tile.Unbreakable Solid Blocks
        LevelGenBase.setBlockAndMetadata(world, baseX + 0, baseY + 2, baseZ + 8, SokobanMod.BlockUnbreakableSolids.blockID, 0); //tile.Unbreakable Solid Blocks
        LevelGenBase.setBlockAndMetadata(world, baseX + 0, baseY + 2, baseZ + 9, SokobanMod.BlockUnbreakableSolids.blockID, 0); //tile.Unbreakable Solid Blocks
        LevelGenBase.setBlockAndMetadata(world, baseX + 0, baseY + 2, baseZ + 10, SokobanMod.BlockUnbreakableSolids.blockID, 0); //tile.Unbreakable Solid Blocks
        LevelGenBase.setBlockAndMetadata(world, baseX + 0, baseY + 2, baseZ + 11, SokobanMod.BlockUnbreakableSolids.blockID, 0); //tile.Unbreakable Solid Blocks
        LevelGenBase.setBlockAndMetadata(world, baseX + 0, baseY + 2, baseZ + 12, SokobanMod.BlockUnbreakableSolids.blockID, 0); //tile.Unbreakable Solid Blocks
        LevelGenBase.setBlockAndMetadata(world, baseX + 0, baseY + 2, baseZ + 13, SokobanMod.BlockUnbreakableSolids.blockID, 0); //tile.Unbreakable Solid Blocks
        LevelGenBase.setBlockAndMetadata(world, baseX + 0, baseY + 3, baseZ + 0, SokobanMod.BlockUnbreakableSolids.blockID, 0); //tile.Unbreakable Solid Blocks
        LevelGenBase.setBlockAndMetadata(world, baseX + 0, baseY + 3, baseZ + 1, SokobanMod.BlockUnbreakableSolids.blockID, 0); //tile.Unbreakable Solid Blocks
        LevelGenBase.setBlockAndMetadata(world, baseX + 0, baseY + 3, baseZ + 2, SokobanMod.BlockUnbreakableSolids.blockID, 0); //tile.Unbreakable Solid Blocks
        LevelGenBase.setBlockAndMetadata(world, baseX + 0, baseY + 3, baseZ + 3, SokobanMod.BlockUnbreakableSolids.blockID, 0); //tile.Unbreakable Solid Blocks
        LevelGenBase.setBlockAndMetadata(world, baseX + 0, baseY + 3, baseZ + 4, SokobanMod.BlockUnbreakableSolids.blockID, 0); //tile.Unbreakable Solid Blocks
        LevelGenBase.setBlockAndMetadata(world, baseX + 0, baseY + 3, baseZ + 5, SokobanMod.BlockUnbreakableSolids.blockID, 0); //tile.Unbreakable Solid Blocks
        LevelGenBase.setBlockAndMetadata(world, baseX + 0, baseY + 3, baseZ + 6, SokobanMod.BlockUnbreakableSolids.blockID, 0); //tile.Unbreakable Solid Blocks
        LevelGenBase.setBlockAndMetadata(world, baseX + 0, baseY + 3, baseZ + 7, SokobanMod.BlockUnbreakableSolids.blockID, 0); //tile.Unbreakable Solid Blocks
        LevelGenBase.setBlockAndMetadata(world, baseX + 0, baseY + 3, baseZ + 8, SokobanMod.BlockUnbreakableSolids.blockID, 0); //tile.Unbreakable Solid Blocks
        LevelGenBase.setBlockAndMetadata(world, baseX + 0, baseY + 3, baseZ + 9, SokobanMod.BlockUnbreakableSolids.blockID, 0); //tile.Unbreakable Solid Blocks
        LevelGenBase.setBlockAndMetadata(world, baseX + 0, baseY + 3, baseZ + 10, SokobanMod.BlockUnbreakableSolids.blockID, 0); //tile.Unbreakable Solid Blocks
        LevelGenBase.setBlockAndMetadata(world, baseX + 0, baseY + 3, baseZ + 11, SokobanMod.BlockUnbreakableSolids.blockID, 0); //tile.Unbreakable Solid Blocks
        LevelGenBase.setBlockAndMetadata(world, baseX + 0, baseY + 3, baseZ + 12, SokobanMod.BlockUnbreakableSolids.blockID, 0); //tile.Unbreakable Solid Blocks
        LevelGenBase.setBlockAndMetadata(world, baseX + 0, baseY + 3, baseZ + 13, SokobanMod.BlockUnbreakableSolids.blockID, 0); //tile.Unbreakable Solid Blocks
        LevelGenBase.setBlockAndMetadata(world, baseX + 0, baseY + 4, baseZ + 0, SokobanMod.BlockUnbreakableSolids.blockID, 0); //tile.Unbreakable Solid Blocks
        LevelGenBase.setBlockAndMetadata(world, baseX + 0, baseY + 4, baseZ + 1, SokobanMod.BlockUnbreakableSolids.blockID, 0); //tile.Unbreakable Solid Blocks
        LevelGenBase.setBlockAndMetadata(world, baseX + 0, baseY + 4, baseZ + 2, SokobanMod.BlockUnbreakableSolids.blockID, 0); //tile.Unbreakable Solid Blocks
        LevelGenBase.setBlockAndMetadata(world, baseX + 0, baseY + 4, baseZ + 3, SokobanMod.BlockUnbreakableSolids.blockID, 0); //tile.Unbreakable Solid Blocks
        LevelGenBase.setBlockAndMetadata(world, baseX + 0, baseY + 4, baseZ + 4, SokobanMod.BlockUnbreakableSolids.blockID, 0); //tile.Unbreakable Solid Blocks
        LevelGenBase.setBlockAndMetadata(world, baseX + 0, baseY + 4, baseZ + 5, SokobanMod.BlockUnbreakableSolids.blockID, 0); //tile.Unbreakable Solid Blocks
        LevelGenBase.setBlockAndMetadata(world, baseX + 0, baseY + 4, baseZ + 6, SokobanMod.BlockUnbreakableSolids.blockID, 0); //tile.Unbreakable Solid Blocks
        LevelGenBase.setBlockAndMetadata(world, baseX + 0, baseY + 4, baseZ + 7, SokobanMod.BlockUnbreakableSolids.blockID, 0); //tile.Unbreakable Solid Blocks
        LevelGenBase.setBlockAndMetadata(world, baseX + 0, baseY + 4, baseZ + 8, SokobanMod.BlockUnbreakableSolids.blockID, 0); //tile.Unbreakable Solid Blocks
        LevelGenBase.setBlockAndMetadata(world, baseX + 0, baseY + 4, baseZ + 9, SokobanMod.BlockUnbreakableSolids.blockID, 0); //tile.Unbreakable Solid Blocks
        LevelGenBase.setBlockAndMetadata(world, baseX + 0, baseY + 4, baseZ + 10, SokobanMod.BlockUnbreakableSolids.blockID, 0); //tile.Unbreakable Solid Blocks
        LevelGenBase.setBlockAndMetadata(world, baseX + 0, baseY + 4, baseZ + 11, SokobanMod.BlockUnbreakableSolids.blockID, 0); //tile.Unbreakable Solid Blocks
        LevelGenBase.setBlockAndMetadata(world, baseX + 0, baseY + 4, baseZ + 12, SokobanMod.BlockUnbreakableSolids.blockID, 0); //tile.Unbreakable Solid Blocks
        LevelGenBase.setBlockAndMetadata(world, baseX + 0, baseY + 4, baseZ + 13, SokobanMod.BlockUnbreakableSolids.blockID, 0); //tile.Unbreakable Solid Blocks
        LevelGenBase.setBlockAndMetadata(world, baseX + 0, baseY + 5, baseZ + 0, SokobanMod.BlockUnbreakableLamps.blockID, 0); //tile.Unbreakable Lamp Blocks
        LevelGenBase.setBlockAndMetadata(world, baseX + 0, baseY + 5, baseZ + 1, SokobanMod.BlockUnbreakableLamps.blockID, 0); //tile.Unbreakable Lamp Blocks
        LevelGenBase.setBlockAndMetadata(world, baseX + 0, baseY + 5, baseZ + 2, SokobanMod.BlockUnbreakableLamps.blockID, 0); //tile.Unbreakable Lamp Blocks
        LevelGenBase.setBlockAndMetadata(world, baseX + 0, baseY + 5, baseZ + 3, SokobanMod.BlockUnbreakableLamps.blockID, 0); //tile.Unbreakable Lamp Blocks
        LevelGenBase.setBlockAndMetadata(world, baseX + 0, baseY + 5, baseZ + 4, SokobanMod.BlockUnbreakableLamps.blockID, 0); //tile.Unbreakable Lamp Blocks
        LevelGenBase.setBlockAndMetadata(world, baseX + 0, baseY + 5, baseZ + 5, SokobanMod.BlockUnbreakableLamps.blockID, 0); //tile.Unbreakable Lamp Blocks
        LevelGenBase.setBlockAndMetadata(world, baseX + 0, baseY + 5, baseZ + 6, SokobanMod.BlockUnbreakableLamps.blockID, 0); //tile.Unbreakable Lamp Blocks
        LevelGenBase.setBlockAndMetadata(world, baseX + 0, baseY + 5, baseZ + 7, SokobanMod.BlockUnbreakableLamps.blockID, 0); //tile.Unbreakable Lamp Blocks
        LevelGenBase.setBlockAndMetadata(world, baseX + 0, baseY + 5, baseZ + 8, SokobanMod.BlockUnbreakableLamps.blockID, 0); //tile.Unbreakable Lamp Blocks
        LevelGenBase.setBlockAndMetadata(world, baseX + 0, baseY + 5, baseZ + 9, SokobanMod.BlockUnbreakableLamps.blockID, 0); //tile.Unbreakable Lamp Blocks
        LevelGenBase.setBlockAndMetadata(world, baseX + 0, baseY + 5, baseZ + 10, SokobanMod.BlockUnbreakableLamps.blockID, 0); //tile.Unbreakable Lamp Blocks
        LevelGenBase.setBlockAndMetadata(world, baseX + 0, baseY + 5, baseZ + 11, SokobanMod.BlockUnbreakableLamps.blockID, 0); //tile.Unbreakable Lamp Blocks
        LevelGenBase.setBlockAndMetadata(world, baseX + 0, baseY + 5, baseZ + 12, SokobanMod.BlockUnbreakableLamps.blockID, 0); //tile.Unbreakable Lamp Blocks
        LevelGenBase.setBlockAndMetadata(world, baseX + 0, baseY + 5, baseZ + 13, SokobanMod.BlockUnbreakableLamps.blockID, 0); //tile.Unbreakable Lamp Blocks
        LevelGenBase.setBlockAndMetadata(world, baseX + 0, baseY + 6, baseZ + 0, SokobanMod.BlockUnbreakableSolids.blockID, 0); //tile.Unbreakable Solid Blocks
        LevelGenBase.setBlockAndMetadata(world, baseX + 0, baseY + 6, baseZ + 1, SokobanMod.BlockUnbreakableSolids.blockID, 0); //tile.Unbreakable Solid Blocks
        LevelGenBase.setBlockAndMetadata(world, baseX + 0, baseY + 6, baseZ + 2, SokobanMod.BlockUnbreakableSolids.blockID, 0); //tile.Unbreakable Solid Blocks
        LevelGenBase.setBlockAndMetadata(world, baseX + 0, baseY + 6, baseZ + 3, SokobanMod.BlockUnbreakableSolids.blockID, 0); //tile.Unbreakable Solid Blocks
        LevelGenBase.setBlockAndMetadata(world, baseX + 0, baseY + 6, baseZ + 4, SokobanMod.BlockUnbreakableSolids.blockID, 0); //tile.Unbreakable Solid Blocks
        LevelGenBase.setBlockAndMetadata(world, baseX + 0, baseY + 6, baseZ + 5, SokobanMod.BlockUnbreakableSolids.blockID, 0); //tile.Unbreakable Solid Blocks
        LevelGenBase.setBlockAndMetadata(world, baseX + 0, baseY + 6, baseZ + 6, SokobanMod.BlockUnbreakableSolids.blockID, 0); //tile.Unbreakable Solid Blocks
        LevelGenBase.setBlockAndMetadata(world, baseX + 0, baseY + 6, baseZ + 7, SokobanMod.BlockUnbreakableSolids.blockID, 0); //tile.Unbreakable Solid Blocks
        LevelGenBase.setBlockAndMetadata(world, baseX + 0, baseY + 6, baseZ + 8, SokobanMod.BlockUnbreakableSolids.blockID, 0); //tile.Unbreakable Solid Blocks
        LevelGenBase.setBlockAndMetadata(world, baseX + 0, baseY + 6, baseZ + 9, SokobanMod.BlockUnbreakableSolids.blockID, 0); //tile.Unbreakable Solid Blocks
        LevelGenBase.setBlockAndMetadata(world, baseX + 0, baseY + 6, baseZ + 10, SokobanMod.BlockUnbreakableSolids.blockID, 0); //tile.Unbreakable Solid Blocks
        LevelGenBase.setBlockAndMetadata(world, baseX + 0, baseY + 6, baseZ + 11, SokobanMod.BlockUnbreakableSolids.blockID, 0); //tile.Unbreakable Solid Blocks
        LevelGenBase.setBlockAndMetadata(world, baseX + 0, baseY + 6, baseZ + 12, SokobanMod.BlockUnbreakableSolids.blockID, 0); //tile.Unbreakable Solid Blocks
        LevelGenBase.setBlockAndMetadata(world, baseX + 0, baseY + 6, baseZ + 13, SokobanMod.BlockUnbreakableSolids.blockID, 0); //tile.Unbreakable Solid Blocks
        LevelGenBase.setBlockAndMetadata(world, baseX + 0, baseY + 7, baseZ + 0, SokobanMod.BlockUnbreakableSolids.blockID, 0); //tile.Unbreakable Solid Blocks
        LevelGenBase.setBlockAndMetadata(world, baseX + 0, baseY + 7, baseZ + 1, SokobanMod.BlockUnbreakableGlasses.blockID, 0); //tile.Unbreakable Glass Blocks
        LevelGenBase.setBlockAndMetadata(world, baseX + 0, baseY + 7, baseZ + 2, SokobanMod.BlockUnbreakableGlasses.blockID, 0); //tile.Unbreakable Glass Blocks
        LevelGenBase.setBlockAndMetadata(world, baseX + 0, baseY + 7, baseZ + 3, SokobanMod.BlockUnbreakableGlasses.blockID, 0); //tile.Unbreakable Glass Blocks
        LevelGenBase.setBlockAndMetadata(world, baseX + 0, baseY + 7, baseZ + 4, SokobanMod.BlockUnbreakableGlasses.blockID, 0); //tile.Unbreakable Glass Blocks
        LevelGenBase.setBlockAndMetadata(world, baseX + 0, baseY + 7, baseZ + 5, SokobanMod.BlockUnbreakableGlasses.blockID, 0); //tile.Unbreakable Glass Blocks
        LevelGenBase.setBlockAndMetadata(world, baseX + 0, baseY + 7, baseZ + 6, SokobanMod.BlockUnbreakableGlasses.blockID, 0); //tile.Unbreakable Glass Blocks
        LevelGenBase.setBlockAndMetadata(world, baseX + 0, baseY + 7, baseZ + 7, SokobanMod.BlockUnbreakableGlasses.blockID, 0); //tile.Unbreakable Glass Blocks
        LevelGenBase.setBlockAndMetadata(world, baseX + 0, baseY + 7, baseZ + 8, SokobanMod.BlockUnbreakableGlasses.blockID, 0); //tile.Unbreakable Glass Blocks
        LevelGenBase.setBlockAndMetadata(world, baseX + 0, baseY + 7, baseZ + 9, SokobanMod.BlockUnbreakableGlasses.blockID, 0); //tile.Unbreakable Glass Blocks
        LevelGenBase.setBlockAndMetadata(world, baseX + 0, baseY + 7, baseZ + 10, SokobanMod.BlockUnbreakableGlasses.blockID, 0); //tile.Unbreakable Glass Blocks
        LevelGenBase.setBlockAndMetadata(world, baseX + 0, baseY + 7, baseZ + 11, SokobanMod.BlockUnbreakableGlasses.blockID, 0); //tile.Unbreakable Glass Blocks
        LevelGenBase.setBlockAndMetadata(world, baseX + 0, baseY + 7, baseZ + 12, SokobanMod.BlockUnbreakableGlasses.blockID, 0); //tile.Unbreakable Glass Blocks
        LevelGenBase.setBlockAndMetadata(world, baseX + 0, baseY + 7, baseZ + 13, SokobanMod.BlockUnbreakableSolids.blockID, 0); //tile.Unbreakable Solid Blocks
        LevelGenBase.setBlockAndMetadata(world, baseX + 0, baseY + 8, baseZ + 0, SokobanMod.BlockUnbreakableSolids.blockID, 0); //tile.Unbreakable Solid Blocks
        LevelGenBase.setBlockAndMetadata(world, baseX + 0, baseY + 8, baseZ + 1, SokobanMod.BlockUnbreakableSolids.blockID, 0); //tile.Unbreakable Solid Blocks
        LevelGenBase.setBlockAndMetadata(world, baseX + 0, baseY + 8, baseZ + 2, SokobanMod.BlockUnbreakableSolids.blockID, 0); //tile.Unbreakable Solid Blocks
        LevelGenBase.setBlockAndMetadata(world, baseX + 0, baseY + 8, baseZ + 3, SokobanMod.BlockUnbreakableSolids.blockID, 0); //tile.Unbreakable Solid Blocks
        LevelGenBase.setBlockAndMetadata(world, baseX + 0, baseY + 8, baseZ + 4, SokobanMod.BlockUnbreakableSolids.blockID, 0); //tile.Unbreakable Solid Blocks
        LevelGenBase.setBlockAndMetadata(world, baseX + 0, baseY + 8, baseZ + 5, SokobanMod.BlockUnbreakableSolids.blockID, 0); //tile.Unbreakable Solid Blocks
        LevelGenBase.setBlockAndMetadata(world, baseX + 0, baseY + 8, baseZ + 6, SokobanMod.BlockUnbreakableSolids.blockID, 0); //tile.Unbreakable Solid Blocks
        LevelGenBase.setBlockAndMetadata(world, baseX + 0, baseY + 8, baseZ + 7, SokobanMod.BlockUnbreakableSolids.blockID, 0); //tile.Unbreakable Solid Blocks
        LevelGenBase.setBlockAndMetadata(world, baseX + 0, baseY + 8, baseZ + 8, SokobanMod.BlockUnbreakableSolids.blockID, 0); //tile.Unbreakable Solid Blocks
        LevelGenBase.setBlockAndMetadata(world, baseX + 0, baseY + 8, baseZ + 9, SokobanMod.BlockUnbreakableSolids.blockID, 0); //tile.Unbreakable Solid Blocks
        LevelGenBase.setBlockAndMetadata(world, baseX + 0, baseY + 8, baseZ + 10, SokobanMod.BlockUnbreakableSolids.blockID, 0); //tile.Unbreakable Solid Blocks
        LevelGenBase.setBlockAndMetadata(world, baseX + 0, baseY + 8, baseZ + 11, SokobanMod.BlockUnbreakableSolids.blockID, 0); //tile.Unbreakable Solid Blocks
        LevelGenBase.setBlockAndMetadata(world, baseX + 0, baseY + 8, baseZ + 12, SokobanMod.BlockUnbreakableSolids.blockID, 0); //tile.Unbreakable Solid Blocks
        LevelGenBase.setBlockAndMetadata(world, baseX + 0, baseY + 8, baseZ + 13, SokobanMod.BlockUnbreakableSolids.blockID, 0); //tile.Unbreakable Solid Blocks
        LevelGenBase.setBlockAndMetadata(world, baseX + 0, baseY + 9, baseZ + 0, SokobanMod.BlockUnbreakableSolids.blockID, 0); //tile.Unbreakable Solid Blocks
        LevelGenBase.setBlockAndMetadata(world, baseX + 0, baseY + 9, baseZ + 1, SokobanMod.BlockUnbreakableSolids.blockID, 0); //tile.Unbreakable Solid Blocks
        LevelGenBase.setBlockAndMetadata(world, baseX + 0, baseY + 9, baseZ + 2, SokobanMod.BlockUnbreakableSolids.blockID, 0); //tile.Unbreakable Solid Blocks
        LevelGenBase.setBlockAndMetadata(world, baseX + 0, baseY + 9, baseZ + 3, SokobanMod.BlockUnbreakableSolids.blockID, 0); //tile.Unbreakable Solid Blocks
        LevelGenBase.setBlockAndMetadata(world, baseX + 0, baseY + 9, baseZ + 4, SokobanMod.BlockUnbreakableSolids.blockID, 0); //tile.Unbreakable Solid Blocks
        LevelGenBase.setBlockAndMetadata(world, baseX + 0, baseY + 9, baseZ + 5, SokobanMod.BlockUnbreakableSolids.blockID, 0); //tile.Unbreakable Solid Blocks
        LevelGenBase.setBlockAndMetadata(world, baseX + 0, baseY + 9, baseZ + 6, SokobanMod.BlockUnbreakableSolids.blockID, 0); //tile.Unbreakable Solid Blocks
        LevelGenBase.setBlockAndMetadata(world, baseX + 0, baseY + 9, baseZ + 7, SokobanMod.BlockUnbreakableSolids.blockID, 0); //tile.Unbreakable Solid Blocks
        LevelGenBase.setBlockAndMetadata(world, baseX + 0, baseY + 9, baseZ + 8, SokobanMod.BlockUnbreakableSolids.blockID, 0); //tile.Unbreakable Solid Blocks
        LevelGenBase.setBlockAndMetadata(world, baseX + 0, baseY + 9, baseZ + 9, SokobanMod.BlockUnbreakableSolids.blockID, 0); //tile.Unbreakable Solid Blocks
        LevelGenBase.setBlockAndMetadata(world, baseX + 0, baseY + 9, baseZ + 10, SokobanMod.BlockUnbreakableSolids.blockID, 0); //tile.Unbreakable Solid Blocks
        LevelGenBase.setBlockAndMetadata(world, baseX + 0, baseY + 9, baseZ + 11, SokobanMod.BlockUnbreakableSolids.blockID, 0); //tile.Unbreakable Solid Blocks
        LevelGenBase.setBlockAndMetadata(world, baseX + 0, baseY + 9, baseZ + 12, SokobanMod.BlockUnbreakableSolids.blockID, 0); //tile.Unbreakable Solid Blocks
        LevelGenBase.setBlockAndMetadata(world, baseX + 0, baseY + 9, baseZ + 13, SokobanMod.BlockUnbreakableSolids.blockID, 0); //tile.Unbreakable Solid Blocks
        LevelGenBase.setBlockAndMetadata(world, baseX + 1, baseY + 0, baseZ + 0, SokobanMod.BlockUnbreakableSolids.blockID, 0); //tile.Unbreakable Solid Blocks
        LevelGenBase.setBlockAndMetadata(world, baseX + 1, baseY + 0, baseZ + 1, SokobanMod.BlockUnbreakableSolids.blockID, 0); //tile.Unbreakable Solid Blocks
        LevelGenBase.setBlockAndMetadata(world, baseX + 1, baseY + 0, baseZ + 2, SokobanMod.BlockUnbreakableSolids.blockID, 0); //tile.Unbreakable Solid Blocks
        LevelGenBase.setBlockAndMetadata(world, baseX + 1, baseY + 0, baseZ + 3, SokobanMod.BlockUnbreakableSolids.blockID, 0); //tile.Unbreakable Solid Blocks
        LevelGenBase.setBlockAndMetadata(world, baseX + 1, baseY + 0, baseZ + 4, SokobanMod.BlockUnbreakableSolids.blockID, 0); //tile.Unbreakable Solid Blocks
        LevelGenBase.setBlockAndMetadata(world, baseX + 1, baseY + 0, baseZ + 5, SokobanMod.BlockUnbreakableSolids.blockID, 0); //tile.Unbreakable Solid Blocks
        LevelGenBase.setBlockAndMetadata(world, baseX + 1, baseY + 0, baseZ + 6, SokobanMod.BlockUnbreakableSolids.blockID, 0); //tile.Unbreakable Solid Blocks
        LevelGenBase.setBlockAndMetadata(world, baseX + 1, baseY + 0, baseZ + 7, SokobanMod.BlockUnbreakableSolids.blockID, 0); //tile.Unbreakable Solid Blocks
        LevelGenBase.setBlockAndMetadata(world, baseX + 1, baseY + 0, baseZ + 8, SokobanMod.BlockUnbreakableSolids.blockID, 0); //tile.Unbreakable Solid Blocks
        LevelGenBase.setBlockAndMetadata(world, baseX + 1, baseY + 0, baseZ + 9, SokobanMod.BlockUnbreakableSolids.blockID, 0); //tile.Unbreakable Solid Blocks
        LevelGenBase.setBlockAndMetadata(world, baseX + 1, baseY + 0, baseZ + 10, SokobanMod.BlockUnbreakableSolids.blockID, 0); //tile.Unbreakable Solid Blocks
        LevelGenBase.setBlockAndMetadata(world, baseX + 1, baseY + 0, baseZ + 11, SokobanMod.BlockUnbreakableSolids.blockID, 0); //tile.Unbreakable Solid Blocks
        LevelGenBase.setBlockAndMetadata(world, baseX + 1, baseY + 0, baseZ + 12, SokobanMod.BlockUnbreakableSolids.blockID, 0); //tile.Unbreakable Solid Blocks
        LevelGenBase.setBlockAndMetadata(world, baseX + 1, baseY + 0, baseZ + 13, SokobanMod.BlockUnbreakableSolids.blockID, 0); //tile.Unbreakable Solid Blocks
        LevelGenBase.setBlockAndMetadata(world, baseX + 1, baseY + 1, baseZ + 0, SokobanMod.BlockUnbreakableSolids.blockID, 0); //tile.Unbreakable Solid Blocks
        LevelGenBase.setBlockAndMetadata(world, baseX + 1, baseY + 1, baseZ + 1, SokobanMod.BlockUnbreakableSolids.blockID, 0); //tile.Unbreakable Solid Blocks
        LevelGenBase.setBlockAndMetadata(world, baseX + 1, baseY + 1, baseZ + 2, SokobanMod.BlockUnbreakableSolids.blockID, 0); //tile.Unbreakable Solid Blocks
        LevelGenBase.setBlockAndMetadata(world, baseX + 1, baseY + 1, baseZ + 3, SokobanMod.BlockUnbreakableSolids.blockID, 0); //tile.Unbreakable Solid Blocks
        LevelGenBase.setBlockAndMetadata(world, baseX + 1, baseY + 1, baseZ + 4, SokobanMod.BlockUnbreakableSolids.blockID, 0); //tile.Unbreakable Solid Blocks
        LevelGenBase.setBlockAndMetadata(world, baseX + 1, baseY + 1, baseZ + 5, SokobanMod.BlockUnbreakableSolids.blockID, 0); //tile.Unbreakable Solid Blocks
        LevelGenBase.setBlockAndMetadata(world, baseX + 1, baseY + 1, baseZ + 6, SokobanMod.BlockUnbreakableSolids.blockID, 0); //tile.Unbreakable Solid Blocks
        LevelGenBase.setBlockAndMetadata(world, baseX + 1, baseY + 1, baseZ + 7, SokobanMod.BlockUnbreakableSolids.blockID, 0); //tile.Unbreakable Solid Blocks
        LevelGenBase.setBlockAndMetadata(world, baseX + 1, baseY + 1, baseZ + 8, SokobanMod.BlockUnbreakableSolids.blockID, 0); //tile.Unbreakable Solid Blocks
        LevelGenBase.setBlockAndMetadata(world, baseX + 1, baseY + 1, baseZ + 9, SokobanMod.BlockUnbreakableSolids.blockID, 0); //tile.Unbreakable Solid Blocks
        LevelGenBase.setBlockAndMetadata(world, baseX + 1, baseY + 1, baseZ + 10, SokobanMod.BlockUnbreakableSolids.blockID, 0); //tile.Unbreakable Solid Blocks
        LevelGenBase.setBlockAndMetadata(world, baseX + 1, baseY + 1, baseZ + 11, SokobanMod.BlockUnbreakableSolids.blockID, 0); //tile.Unbreakable Solid Blocks
        LevelGenBase.setBlockAndMetadata(world, baseX + 1, baseY + 1, baseZ + 12, SokobanMod.BlockUnbreakableSolids.blockID, 0); //tile.Unbreakable Solid Blocks
        LevelGenBase.setBlockAndMetadata(world, baseX + 1, baseY + 1, baseZ + 13, SokobanMod.BlockUnbreakableSolids.blockID, 0); //tile.Unbreakable Solid Blocks
        LevelGenBase.setBlockAndMetadata(world, baseX + 1, baseY + 2, baseZ + 0, SokobanMod.BlockUnbreakableSolids.blockID, 0); //tile.Unbreakable Solid Blocks
        LevelGenBase.setBlockAndMetadata(world, baseX + 1, baseY + 2, baseZ + 1, SokobanMod.BlockUnbreakableSolids.blockID, 0); //tile.Unbreakable Solid Blocks
        LevelGenBase.setBlockAndMetadata(world, baseX + 1, baseY + 2, baseZ + 2, SokobanMod.BlockUnbreakableSolids.blockID, 0); //tile.Unbreakable Solid Blocks
        LevelGenBase.setBlockAndMetadata(world, baseX + 1, baseY + 2, baseZ + 3, SokobanMod.BlockUnbreakableSolids.blockID, 0); //tile.Unbreakable Solid Blocks
        LevelGenBase.setBlockAndMetadata(world, baseX + 1, baseY + 2, baseZ + 4, SokobanMod.BlockUnbreakableSolids.blockID, 0); //tile.Unbreakable Solid Blocks
        LevelGenBase.setBlockAndMetadata(world, baseX + 1, baseY + 2, baseZ + 5, SokobanMod.BlockUnbreakableSolids.blockID, 0); //tile.Unbreakable Solid Blocks
        LevelGenBase.setBlockAndMetadata(world, baseX + 1, baseY + 2, baseZ + 6, SokobanMod.BlockUnbreakableSolids.blockID, 0); //tile.Unbreakable Solid Blocks
        LevelGenBase.setBlockAndMetadata(world, baseX + 1, baseY + 2, baseZ + 7, SokobanMod.BlockUnbreakableSolids.blockID, 0); //tile.Unbreakable Solid Blocks
        LevelGenBase.setBlockAndMetadata(world, baseX + 1, baseY + 2, baseZ + 8, SokobanMod.BlockUnbreakableSolids.blockID, 0); //tile.Unbreakable Solid Blocks
        LevelGenBase.setBlockAndMetadata(world, baseX + 1, baseY + 2, baseZ + 9, Block.bedrock.blockID, 0); //tile.bedrock
        LevelGenBase.setBlockAndMetadata(world, baseX + 1, baseY + 2, baseZ + 10, SokobanMod.BlockUnbreakableSolids.blockID, 0); //tile.Unbreakable Solid Blocks
        LevelGenBase.setBlockAndMetadata(world, baseX + 1, baseY + 2, baseZ + 11, SokobanMod.BlockUnbreakableSolids.blockID, 0); //tile.Unbreakable Solid Blocks
        LevelGenBase.setBlockAndMetadata(world, baseX + 1, baseY + 2, baseZ + 12, SokobanMod.BlockUnbreakableSolids.blockID, 0); //tile.Unbreakable Solid Blocks
        LevelGenBase.setBlockAndMetadata(world, baseX + 1, baseY + 2, baseZ + 13, SokobanMod.BlockUnbreakableSolids.blockID, 0); //tile.Unbreakable Solid Blocks
        LevelGenBase.setBlockAndMetadata(world, baseX + 1, baseY + 3, baseZ + 0, SokobanMod.BlockUnbreakableSolids.blockID, 0); //tile.Unbreakable Solid Blocks
        LevelGenBase.setBlockAndMetadata(world, baseX + 1, baseY + 3, baseZ + 1, SokobanMod.BlockUnbreakableSolids.blockID, 0); //tile.Unbreakable Solid Blocks
        LevelGenBase.setBlockAndMetadata(world, baseX + 1, baseY + 3, baseZ + 9, SokobanMod.BlockVaporizingBlock.blockID, 0); //tile.Vaporizing Block
        LevelGenBase.setBlockAndMetadata(world, baseX + 1, baseY + 3, baseZ + 12, Block.chest.blockID, 5); //tile.chest
        if(world.getBlockTileEntity(baseX + 1, baseY + 3, baseZ + 12) instanceof TileEntityChest) {
            TileEntityChest teC = (TileEntityChest)world.getBlockTileEntity(baseX + 1, baseY + 3, baseZ + 12);
            for(int i = 0; i < teC.getSizeInventory(); i++) {
                teC.setInventorySlotContents(i, new ItemStack(Item.goldNugget));
            }
        }
        LevelGenBase.setBlockAndMetadata(world, baseX + 1, baseY + 3, baseZ + 13, SokobanMod.BlockUnbreakableSolids.blockID, 0); //tile.Unbreakable Solid Blocks
        LevelGenBase.setBlockAndMetadata(world, baseX + 1, baseY + 4, baseZ + 0, SokobanMod.BlockUnbreakableSolids.blockID, 0); //tile.Unbreakable Solid Blocks
        LevelGenBase.setBlockAndMetadata(world, baseX + 1, baseY + 4, baseZ + 1, Block.bedrock.blockID, 0); //tile.bedrock
        LevelGenBase.setBlockAndMetadata(world, baseX + 1, baseY + 4, baseZ + 9, SokobanMod.BlockVaporizingBlock.blockID, 0); //tile.Vaporizing Block
        LevelGenBase.setBlockAndMetadata(world, baseX + 1, baseY + 4, baseZ + 13, SokobanMod.BlockUnbreakableSolids.blockID, 0); //tile.Unbreakable Solid Blocks
        LevelGenBase.setBlockAndMetadata(world, baseX + 1, baseY + 5, baseZ + 0, SokobanMod.BlockUnbreakableLamps.blockID, 0); //tile.Unbreakable Lamp Blocks
        LevelGenBase.setBlockAndMetadata(world, baseX + 1, baseY + 5, baseZ + 1, SokobanMod.BlockVaporizingBlock.blockID, 0); //tile.Vaporizing Block
        LevelGenBase.setBlockAndMetadata(world, baseX + 1, baseY + 5, baseZ + 2, SokobanMod.BlockUnbreakableLamps.blockID, 0); //tile.Unbreakable Lamp Blocks
        LevelGenBase.setBlockAndMetadata(world, baseX + 1, baseY + 5, baseZ + 3, SokobanMod.BlockUnbreakableLamps.blockID, 0); //tile.Unbreakable Lamp Blocks
        LevelGenBase.setBlockAndMetadata(world, baseX + 1, baseY + 5, baseZ + 4, SokobanMod.BlockUnbreakableLamps.blockID, 0); //tile.Unbreakable Lamp Blocks
        LevelGenBase.setBlockAndMetadata(world, baseX + 1, baseY + 5, baseZ + 5, SokobanMod.BlockUnbreakableLamps.blockID, 0); //tile.Unbreakable Lamp Blocks
        LevelGenBase.setBlockAndMetadata(world, baseX + 1, baseY + 5, baseZ + 6, SokobanMod.BlockUnbreakableLamps.blockID, 0); //tile.Unbreakable Lamp Blocks
        LevelGenBase.setBlockAndMetadata(world, baseX + 1, baseY + 5, baseZ + 7, SokobanMod.BlockUnbreakableLamps.blockID, 0); //tile.Unbreakable Lamp Blocks
        LevelGenBase.setBlockAndMetadata(world, baseX + 1, baseY + 5, baseZ + 8, SokobanMod.BlockUnbreakableLamps.blockID, 0); //tile.Unbreakable Lamp Blocks
        LevelGenBase.setBlockAndMetadata(world, baseX + 1, baseY + 5, baseZ + 9, SokobanMod.BlockUnbreakableLamps.blockID, 0); //tile.Unbreakable Lamp Blocks
        LevelGenBase.setBlockAndMetadata(world, baseX + 1, baseY + 5, baseZ + 10, SokobanMod.BlockUnbreakableLamps.blockID, 0); //tile.Unbreakable Lamp Blocks
        LevelGenBase.setBlockAndMetadata(world, baseX + 1, baseY + 5, baseZ + 11, SokobanMod.BlockUnbreakableLamps.blockID, 0); //tile.Unbreakable Lamp Blocks
        LevelGenBase.setBlockAndMetadata(world, baseX + 1, baseY + 5, baseZ + 12, SokobanMod.BlockUnbreakableLamps.blockID, 0); //tile.Unbreakable Lamp Blocks
        LevelGenBase.setBlockAndMetadata(world, baseX + 1, baseY + 5, baseZ + 13, SokobanMod.BlockUnbreakableLamps.blockID, 0); //tile.Unbreakable Lamp Blocks
        LevelGenBase.setBlockAndMetadata(world, baseX + 1, baseY + 6, baseZ + 0, SokobanMod.BlockUnbreakableSolids.blockID, 0); //tile.Unbreakable Solid Blocks
        LevelGenBase.setBlockAndMetadata(world, baseX + 1, baseY + 6, baseZ + 13, SokobanMod.BlockUnbreakableSolids.blockID, 0); //tile.Unbreakable Solid Blocks
        LevelGenBase.setBlockAndMetadata(world, baseX + 1, baseY + 7, baseZ + 0, SokobanMod.BlockUnbreakableGlasses.blockID, 0); //tile.Unbreakable Glass Blocks
        LevelGenBase.setBlockAndMetadata(world, baseX + 1, baseY + 7, baseZ + 13, SokobanMod.BlockUnbreakableGlasses.blockID, 0); //tile.Unbreakable Glass Blocks
        LevelGenBase.setBlockAndMetadata(world, baseX + 1, baseY + 8, baseZ + 0, SokobanMod.BlockUnbreakableSolids.blockID, 0); //tile.Unbreakable Solid Blocks
        LevelGenBase.setBlockAndMetadata(world, baseX + 1, baseY + 8, baseZ + 13, SokobanMod.BlockUnbreakableSolids.blockID, 0); //tile.Unbreakable Solid Blocks
        LevelGenBase.setBlockAndMetadata(world, baseX + 1, baseY + 9, baseZ + 0, SokobanMod.BlockUnbreakableSolids.blockID, 0); //tile.Unbreakable Solid Blocks
        LevelGenBase.setBlockAndMetadata(world, baseX + 1, baseY + 9, baseZ + 1, SokobanMod.BlockUnbreakableSolids.blockID, 0); //tile.Unbreakable Solid Blocks
        LevelGenBase.setBlockAndMetadata(world, baseX + 1, baseY + 9, baseZ + 2, SokobanMod.BlockUnbreakableSolids.blockID, 0); //tile.Unbreakable Solid Blocks
        LevelGenBase.setBlockAndMetadata(world, baseX + 1, baseY + 9, baseZ + 3, SokobanMod.BlockUnbreakableSolids.blockID, 0); //tile.Unbreakable Solid Blocks
        LevelGenBase.setBlockAndMetadata(world, baseX + 1, baseY + 9, baseZ + 4, SokobanMod.BlockUnbreakableSolids.blockID, 0); //tile.Unbreakable Solid Blocks
        LevelGenBase.setBlockAndMetadata(world, baseX + 1, baseY + 9, baseZ + 5, SokobanMod.BlockUnbreakableSolids.blockID, 0); //tile.Unbreakable Solid Blocks
        LevelGenBase.setBlockAndMetadata(world, baseX + 1, baseY + 9, baseZ + 6, SokobanMod.BlockUnbreakableSolids.blockID, 0); //tile.Unbreakable Solid Blocks
        LevelGenBase.setBlockAndMetadata(world, baseX + 1, baseY + 9, baseZ + 7, SokobanMod.BlockUnbreakableSolids.blockID, 0); //tile.Unbreakable Solid Blocks
        LevelGenBase.setBlockAndMetadata(world, baseX + 1, baseY + 9, baseZ + 8, SokobanMod.BlockUnbreakableSolids.blockID, 0); //tile.Unbreakable Solid Blocks
        LevelGenBase.setBlockAndMetadata(world, baseX + 1, baseY + 9, baseZ + 9, SokobanMod.BlockUnbreakableSolids.blockID, 0); //tile.Unbreakable Solid Blocks
        LevelGenBase.setBlockAndMetadata(world, baseX + 1, baseY + 9, baseZ + 10, SokobanMod.BlockUnbreakableSolids.blockID, 0); //tile.Unbreakable Solid Blocks
        LevelGenBase.setBlockAndMetadata(world, baseX + 1, baseY + 9, baseZ + 11, SokobanMod.BlockUnbreakableSolids.blockID, 0); //tile.Unbreakable Solid Blocks
        LevelGenBase.setBlockAndMetadata(world, baseX + 1, baseY + 9, baseZ + 12, SokobanMod.BlockUnbreakableSolids.blockID, 0); //tile.Unbreakable Solid Blocks
        LevelGenBase.setBlockAndMetadata(world, baseX + 1, baseY + 9, baseZ + 13, SokobanMod.BlockUnbreakableSolids.blockID, 0); //tile.Unbreakable Solid Blocks
        LevelGenBase.setBlockAndMetadata(world, baseX + 2, baseY + 0, baseZ + 0, SokobanMod.BlockUnbreakableSolids.blockID, 0); //tile.Unbreakable Solid Blocks
        LevelGenBase.setBlockAndMetadata(world, baseX + 2, baseY + 0, baseZ + 1, SokobanMod.BlockUnbreakableSolids.blockID, 0); //tile.Unbreakable Solid Blocks
        LevelGenBase.setBlockAndMetadata(world, baseX + 2, baseY + 0, baseZ + 2, SokobanMod.BlockUnbreakableSolids.blockID, 0); //tile.Unbreakable Solid Blocks
        LevelGenBase.setBlockAndMetadata(world, baseX + 2, baseY + 0, baseZ + 3, SokobanMod.BlockUnbreakableSolids.blockID, 0); //tile.Unbreakable Solid Blocks
        LevelGenBase.setBlockAndMetadata(world, baseX + 2, baseY + 0, baseZ + 4, SokobanMod.BlockUnbreakableSolids.blockID, 0); //tile.Unbreakable Solid Blocks
        LevelGenBase.setBlockAndMetadata(world, baseX + 2, baseY + 0, baseZ + 5, SokobanMod.BlockUnbreakableSolids.blockID, 0); //tile.Unbreakable Solid Blocks
        LevelGenBase.setBlockAndMetadata(world, baseX + 2, baseY + 0, baseZ + 6, SokobanMod.BlockUnbreakableSolids.blockID, 0); //tile.Unbreakable Solid Blocks
        LevelGenBase.setBlockAndMetadata(world, baseX + 2, baseY + 0, baseZ + 7, SokobanMod.BlockUnbreakableSolids.blockID, 0); //tile.Unbreakable Solid Blocks
        LevelGenBase.setBlockAndMetadata(world, baseX + 2, baseY + 0, baseZ + 8, SokobanMod.BlockUnbreakableSolids.blockID, 0); //tile.Unbreakable Solid Blocks
        LevelGenBase.setBlockAndMetadata(world, baseX + 2, baseY + 0, baseZ + 9, SokobanMod.BlockUnbreakableSolids.blockID, 0); //tile.Unbreakable Solid Blocks
        LevelGenBase.setBlockAndMetadata(world, baseX + 2, baseY + 0, baseZ + 10, SokobanMod.BlockUnbreakableSolids.blockID, 0); //tile.Unbreakable Solid Blocks
        LevelGenBase.setBlockAndMetadata(world, baseX + 2, baseY + 0, baseZ + 11, SokobanMod.BlockUnbreakableSolids.blockID, 0); //tile.Unbreakable Solid Blocks
        LevelGenBase.setBlockAndMetadata(world, baseX + 2, baseY + 0, baseZ + 12, SokobanMod.BlockUnbreakableSolids.blockID, 0); //tile.Unbreakable Solid Blocks
        LevelGenBase.setBlockAndMetadata(world, baseX + 2, baseY + 0, baseZ + 13, SokobanMod.BlockUnbreakableSolids.blockID, 0); //tile.Unbreakable Solid Blocks
        LevelGenBase.setBlockAndMetadata(world, baseX + 2, baseY + 1, baseZ + 0, SokobanMod.BlockUnbreakableSolids.blockID, 0); //tile.Unbreakable Solid Blocks
        LevelGenBase.setBlockAndMetadata(world, baseX + 2, baseY + 1, baseZ + 1, SokobanMod.BlockUnbreakableSolids.blockID, 0); //tile.Unbreakable Solid Blocks
        LevelGenBase.setBlockAndMetadata(world, baseX + 2, baseY + 1, baseZ + 2, SokobanMod.BlockUnbreakableSolids.blockID, 0); //tile.Unbreakable Solid Blocks
        LevelGenBase.setBlockAndMetadata(world, baseX + 2, baseY + 1, baseZ + 3, SokobanMod.BlockUnbreakableSolids.blockID, 0); //tile.Unbreakable Solid Blocks
        LevelGenBase.setBlockAndMetadata(world, baseX + 2, baseY + 1, baseZ + 4, SokobanMod.BlockUnbreakableSolids.blockID, 0); //tile.Unbreakable Solid Blocks
        LevelGenBase.setBlockAndMetadata(world, baseX + 2, baseY + 1, baseZ + 5, SokobanMod.BlockUnbreakableSolids.blockID, 0); //tile.Unbreakable Solid Blocks
        LevelGenBase.setBlockAndMetadata(world, baseX + 2, baseY + 1, baseZ + 6, SokobanMod.BlockUnbreakableSolids.blockID, 0); //tile.Unbreakable Solid Blocks
        LevelGenBase.setBlockAndMetadata(world, baseX + 2, baseY + 1, baseZ + 7, Block.bedrock.blockID, 0); //tile.bedrock
        LevelGenBase.setBlockAndMetadata(world, baseX + 2, baseY + 1, baseZ + 8, Block.bedrock.blockID, 0); //tile.bedrock
        LevelGenBase.setBlockAndMetadata(world, baseX + 2, baseY + 1, baseZ + 9, SokobanMod.BlockUnbreakableSolids.blockID, 0); //tile.Unbreakable Solid Blocks
        LevelGenBase.setBlockAndMetadata(world, baseX + 2, baseY + 1, baseZ + 10, SokobanMod.BlockUnbreakableSolids.blockID, 0); //tile.Unbreakable Solid Blocks
        LevelGenBase.setBlockAndMetadata(world, baseX + 2, baseY + 1, baseZ + 11, SokobanMod.BlockUnbreakableSolids.blockID, 0); //tile.Unbreakable Solid Blocks
        LevelGenBase.setBlockAndMetadata(world, baseX + 2, baseY + 1, baseZ + 12, SokobanMod.BlockUnbreakableSolids.blockID, 0); //tile.Unbreakable Solid Blocks
        LevelGenBase.setBlockAndMetadata(world, baseX + 2, baseY + 1, baseZ + 13, SokobanMod.BlockUnbreakableSolids.blockID, 0); //tile.Unbreakable Solid Blocks
        LevelGenBase.setBlockAndMetadata(world, baseX + 2, baseY + 2, baseZ + 0, SokobanMod.BlockUnbreakableSolids.blockID, 0); //tile.Unbreakable Solid Blocks
        LevelGenBase.setBlockAndMetadata(world, baseX + 2, baseY + 2, baseZ + 1, SokobanMod.BlockUnbreakableSolids.blockID, 0); //tile.Unbreakable Solid Blocks
        LevelGenBase.setBlockAndMetadata(world, baseX + 2, baseY + 2, baseZ + 2, SokobanMod.BlockUnbreakableSolids.blockID, 0); //tile.Unbreakable Solid Blocks
        LevelGenBase.setBlockAndMetadata(world, baseX + 2, baseY + 2, baseZ + 3, SokobanMod.BlockUnbreakableSolids.blockID, 0); //tile.Unbreakable Solid Blocks
        LevelGenBase.setBlockAndMetadata(world, baseX + 2, baseY + 2, baseZ + 4, SokobanMod.BlockUnbreakableSolids.blockID, 0); //tile.Unbreakable Solid Blocks
        LevelGenBase.setBlockAndMetadata(world, baseX + 2, baseY + 2, baseZ + 5, SokobanMod.BlockUnbreakableSolids.blockID, 0); //tile.Unbreakable Solid Blocks
        LevelGenBase.setBlockAndMetadata(world, baseX + 2, baseY + 2, baseZ + 6, SokobanMod.BlockUnbreakableSolids.blockID, 0); //tile.Unbreakable Solid Blocks
        LevelGenBase.setBlockAndMetadata(world, baseX + 2, baseY + 2, baseZ + 9, Block.bedrock.blockID, 0); //tile.bedrock
        LevelGenBase.setBlockAndMetadata(world, baseX + 2, baseY + 2, baseZ + 10, SokobanMod.BlockUnbreakableSolids.blockID, 0); //tile.Unbreakable Solid Blocks
        LevelGenBase.setBlockAndMetadata(world, baseX + 2, baseY + 2, baseZ + 11, SokobanMod.BlockUnbreakableSolids.blockID, 0); //tile.Unbreakable Solid Blocks
        LevelGenBase.setBlockAndMetadata(world, baseX + 2, baseY + 2, baseZ + 12, SokobanMod.BlockUnbreakableSolids.blockID, 0); //tile.Unbreakable Solid Blocks
        LevelGenBase.setBlockAndMetadata(world, baseX + 2, baseY + 2, baseZ + 13, SokobanMod.BlockUnbreakableSolids.blockID, 0); //tile.Unbreakable Solid Blocks
        LevelGenBase.setBlockAndMetadata(world, baseX + 2, baseY + 3, baseZ + 0, SokobanMod.BlockUnbreakableSolids.blockID, 0); //tile.Unbreakable Solid Blocks
        LevelGenBase.setBlockAndMetadata(world, baseX + 2, baseY + 3, baseZ + 1, Block.bedrock.blockID, 0); //tile.bedrock
        LevelGenBase.setBlockAndMetadata(world, baseX + 2, baseY + 3, baseZ + 2, SokobanMod.BlockUnbreakableSolids.blockID, 0); //tile.Unbreakable Solid Blocks
        LevelGenBase.setBlockAndMetadata(world, baseX + 2, baseY + 3, baseZ + 7, SokobanMod.BlockUnbreakableSolids.blockID, 0); //tile.Unbreakable Solid Blocks
        LevelGenBase.setBlockAndMetadata(world, baseX + 2, baseY + 3, baseZ + 8, SokobanMod.BlockUnbreakableSolids.blockID, 0); //tile.Unbreakable Solid Blocks
        LevelGenBase.setBlockAndMetadata(world, baseX + 2, baseY + 3, baseZ + 9, SokobanMod.BlockVaporizingBlock.blockID, 0); //tile.Vaporizing Block
        LevelGenBase.setBlockAndMetadata(world, baseX + 2, baseY + 3, baseZ + 13, SokobanMod.BlockUnbreakableSolids.blockID, 0); //tile.Unbreakable Solid Blocks
        LevelGenBase.setBlockAndMetadata(world, baseX + 2, baseY + 4, baseZ + 0, SokobanMod.BlockUnbreakableSolids.blockID, 0); //tile.Unbreakable Solid Blocks
        LevelGenBase.setBlockAndMetadata(world, baseX + 2, baseY + 4, baseZ + 1, SokobanMod.BlockVaporizingBlock.blockID, 0); //tile.Vaporizing Block
        LevelGenBase.setBlockAndMetadata(world, baseX + 2, baseY + 4, baseZ + 2, SokobanMod.BlockUnbreakableSolids.blockID, 0); //tile.Unbreakable Solid Blocks
        LevelGenBase.setBlockAndMetadata(world, baseX + 2, baseY + 4, baseZ + 7, SokobanMod.BlockUnbreakableSolids.blockID, 0); //tile.Unbreakable Solid Blocks
        LevelGenBase.setBlockAndMetadata(world, baseX + 2, baseY + 4, baseZ + 8, SokobanMod.BlockUnbreakableSolids.blockID, 0); //tile.Unbreakable Solid Blocks
        LevelGenBase.setBlockAndMetadata(world, baseX + 2, baseY + 4, baseZ + 9, SokobanMod.BlockVaporizingBlock.blockID, 0); //tile.Vaporizing Block
        LevelGenBase.setBlockAndMetadata(world, baseX + 2, baseY + 4, baseZ + 13, SokobanMod.BlockUnbreakableSolids.blockID, 0); //tile.Unbreakable Solid Blocks
        LevelGenBase.setBlockAndMetadata(world, baseX + 2, baseY + 5, baseZ + 0, SokobanMod.BlockUnbreakableLamps.blockID, 0); //tile.Unbreakable Lamp Blocks
        LevelGenBase.setBlockAndMetadata(world, baseX + 2, baseY + 5, baseZ + 1, SokobanMod.BlockVaporizingBlock.blockID, 0); //tile.Vaporizing Block
        LevelGenBase.setBlockAndMetadata(world, baseX + 2, baseY + 5, baseZ + 2, SokobanMod.BlockUnbreakableLamps.blockID, 0); //tile.Unbreakable Lamp Blocks
        LevelGenBase.setBlockAndMetadata(world, baseX + 2, baseY + 5, baseZ + 3, SokobanMod.BlockUnbreakableLamps.blockID, 0); //tile.Unbreakable Lamp Blocks
        LevelGenBase.setBlockAndMetadata(world, baseX + 2, baseY + 5, baseZ + 4, SokobanMod.BlockUnbreakableLamps.blockID, 0); //tile.Unbreakable Lamp Blocks
        LevelGenBase.setBlockAndMetadata(world, baseX + 2, baseY + 5, baseZ + 5, SokobanMod.BlockUnbreakableLamps.blockID, 0); //tile.Unbreakable Lamp Blocks
        LevelGenBase.setBlockAndMetadata(world, baseX + 2, baseY + 5, baseZ + 6, SokobanMod.BlockUnbreakableLamps.blockID, 0); //tile.Unbreakable Lamp Blocks
        LevelGenBase.setBlockAndMetadata(world, baseX + 2, baseY + 5, baseZ + 7, SokobanMod.BlockUnbreakableLamps.blockID, 0); //tile.Unbreakable Lamp Blocks
        LevelGenBase.setBlockAndMetadata(world, baseX + 2, baseY + 5, baseZ + 8, SokobanMod.BlockUnbreakableLamps.blockID, 0); //tile.Unbreakable Lamp Blocks
        LevelGenBase.setBlockAndMetadata(world, baseX + 2, baseY + 5, baseZ + 9, SokobanMod.BlockUnbreakableLamps.blockID, 0); //tile.Unbreakable Lamp Blocks
        LevelGenBase.setBlockAndMetadata(world, baseX + 2, baseY + 5, baseZ + 10, SokobanMod.BlockUnbreakableLamps.blockID, 0); //tile.Unbreakable Lamp Blocks
        LevelGenBase.setBlockAndMetadata(world, baseX + 2, baseY + 5, baseZ + 11, SokobanMod.BlockUnbreakableLamps.blockID, 0); //tile.Unbreakable Lamp Blocks
        LevelGenBase.setBlockAndMetadata(world, baseX + 2, baseY + 5, baseZ + 12, SokobanMod.BlockUnbreakableLamps.blockID, 0); //tile.Unbreakable Lamp Blocks
        LevelGenBase.setBlockAndMetadata(world, baseX + 2, baseY + 5, baseZ + 13, SokobanMod.BlockUnbreakableLamps.blockID, 0); //tile.Unbreakable Lamp Blocks
        LevelGenBase.setBlockAndMetadata(world, baseX + 2, baseY + 6, baseZ + 0, SokobanMod.BlockUnbreakableSolids.blockID, 0); //tile.Unbreakable Solid Blocks
        LevelGenBase.setBlockAndMetadata(world, baseX + 2, baseY + 6, baseZ + 13, SokobanMod.BlockUnbreakableSolids.blockID, 0); //tile.Unbreakable Solid Blocks
        LevelGenBase.setBlockAndMetadata(world, baseX + 2, baseY + 7, baseZ + 0, SokobanMod.BlockUnbreakableGlasses.blockID, 0); //tile.Unbreakable Glass Blocks
        LevelGenBase.setBlockAndMetadata(world, baseX + 2, baseY + 7, baseZ + 13, SokobanMod.BlockUnbreakableGlasses.blockID, 0); //tile.Unbreakable Glass Blocks
        LevelGenBase.setBlockAndMetadata(world, baseX + 2, baseY + 8, baseZ + 0, SokobanMod.BlockUnbreakableSolids.blockID, 0); //tile.Unbreakable Solid Blocks
        LevelGenBase.setBlockAndMetadata(world, baseX + 2, baseY + 8, baseZ + 13, SokobanMod.BlockUnbreakableSolids.blockID, 0); //tile.Unbreakable Solid Blocks
        LevelGenBase.setBlockAndMetadata(world, baseX + 2, baseY + 9, baseZ + 0, SokobanMod.BlockUnbreakableSolids.blockID, 0); //tile.Unbreakable Solid Blocks
        LevelGenBase.setBlockAndMetadata(world, baseX + 2, baseY + 9, baseZ + 1, SokobanMod.BlockUnbreakableSolids.blockID, 0); //tile.Unbreakable Solid Blocks
        LevelGenBase.setBlockAndMetadata(world, baseX + 2, baseY + 9, baseZ + 2, SokobanMod.BlockUnbreakableSolids.blockID, 0); //tile.Unbreakable Solid Blocks
        LevelGenBase.setBlockAndMetadata(world, baseX + 2, baseY + 9, baseZ + 3, SokobanMod.BlockUnbreakableSolids.blockID, 0); //tile.Unbreakable Solid Blocks
        LevelGenBase.setBlockAndMetadata(world, baseX + 2, baseY + 9, baseZ + 4, SokobanMod.BlockUnbreakableSolids.blockID, 0); //tile.Unbreakable Solid Blocks
        LevelGenBase.setBlockAndMetadata(world, baseX + 2, baseY + 9, baseZ + 5, SokobanMod.BlockUnbreakableSolids.blockID, 0); //tile.Unbreakable Solid Blocks
        LevelGenBase.setBlockAndMetadata(world, baseX + 2, baseY + 9, baseZ + 6, SokobanMod.BlockUnbreakableSolids.blockID, 0); //tile.Unbreakable Solid Blocks
        LevelGenBase.setBlockAndMetadata(world, baseX + 2, baseY + 9, baseZ + 7, SokobanMod.BlockUnbreakableSolids.blockID, 0); //tile.Unbreakable Solid Blocks
        LevelGenBase.setBlockAndMetadata(world, baseX + 2, baseY + 9, baseZ + 8, SokobanMod.BlockUnbreakableSolids.blockID, 0); //tile.Unbreakable Solid Blocks
        LevelGenBase.setBlockAndMetadata(world, baseX + 2, baseY + 9, baseZ + 9, SokobanMod.BlockUnbreakableSolids.blockID, 0); //tile.Unbreakable Solid Blocks
        LevelGenBase.setBlockAndMetadata(world, baseX + 2, baseY + 9, baseZ + 10, SokobanMod.BlockUnbreakableSolids.blockID, 0); //tile.Unbreakable Solid Blocks
        LevelGenBase.setBlockAndMetadata(world, baseX + 2, baseY + 9, baseZ + 11, SokobanMod.BlockUnbreakableSolids.blockID, 0); //tile.Unbreakable Solid Blocks
        LevelGenBase.setBlockAndMetadata(world, baseX + 2, baseY + 9, baseZ + 12, SokobanMod.BlockUnbreakableSolids.blockID, 0); //tile.Unbreakable Solid Blocks
        LevelGenBase.setBlockAndMetadata(world, baseX + 2, baseY + 9, baseZ + 13, SokobanMod.BlockUnbreakableSolids.blockID, 0); //tile.Unbreakable Solid Blocks
        LevelGenBase.setBlockAndMetadata(world, baseX + 3, baseY + 0, baseZ + 0, SokobanMod.BlockUnbreakableSolids.blockID, 0); //tile.Unbreakable Solid Blocks
        LevelGenBase.setBlockAndMetadata(world, baseX + 3, baseY + 0, baseZ + 1, SokobanMod.BlockUnbreakableSolids.blockID, 0); //tile.Unbreakable Solid Blocks
        LevelGenBase.setBlockAndMetadata(world, baseX + 3, baseY + 0, baseZ + 2, SokobanMod.BlockUnbreakableSolids.blockID, 0); //tile.Unbreakable Solid Blocks
        LevelGenBase.setBlockAndMetadata(world, baseX + 3, baseY + 0, baseZ + 3, SokobanMod.BlockUnbreakableSolids.blockID, 0); //tile.Unbreakable Solid Blocks
        LevelGenBase.setBlockAndMetadata(world, baseX + 3, baseY + 0, baseZ + 4, Block.bedrock.blockID, 0); //tile.bedrock
        LevelGenBase.setBlockAndMetadata(world, baseX + 3, baseY + 0, baseZ + 5, Block.bedrock.blockID, 0); //tile.bedrock
        LevelGenBase.setBlockAndMetadata(world, baseX + 3, baseY + 0, baseZ + 6, Block.bedrock.blockID, 0); //tile.bedrock
        LevelGenBase.setBlockAndMetadata(world, baseX + 3, baseY + 0, baseZ + 7, SokobanMod.BlockUnbreakableSolids.blockID, 0); //tile.Unbreakable Solid Blocks
        LevelGenBase.setBlockAndMetadata(world, baseX + 3, baseY + 0, baseZ + 8, Block.bedrock.blockID, 0); //tile.bedrock
        LevelGenBase.setBlockAndMetadata(world, baseX + 3, baseY + 0, baseZ + 9, SokobanMod.BlockUnbreakableSolids.blockID, 0); //tile.Unbreakable Solid Blocks
        LevelGenBase.setBlockAndMetadata(world, baseX + 3, baseY + 0, baseZ + 10, SokobanMod.BlockUnbreakableSolids.blockID, 0); //tile.Unbreakable Solid Blocks
        LevelGenBase.setBlockAndMetadata(world, baseX + 3, baseY + 0, baseZ + 11, SokobanMod.BlockUnbreakableSolids.blockID, 0); //tile.Unbreakable Solid Blocks
        LevelGenBase.setBlockAndMetadata(world, baseX + 3, baseY + 0, baseZ + 12, SokobanMod.BlockUnbreakableSolids.blockID, 0); //tile.Unbreakable Solid Blocks
        LevelGenBase.setBlockAndMetadata(world, baseX + 3, baseY + 0, baseZ + 13, SokobanMod.BlockUnbreakableSolids.blockID, 0); //tile.Unbreakable Solid Blocks
        LevelGenBase.setBlockAndMetadata(world, baseX + 3, baseY + 1, baseZ + 0, SokobanMod.BlockUnbreakableSolids.blockID, 0); //tile.Unbreakable Solid Blocks
        LevelGenBase.setBlockAndMetadata(world, baseX + 3, baseY + 1, baseZ + 1, SokobanMod.BlockUnbreakableSolids.blockID, 0); //tile.Unbreakable Solid Blocks
        LevelGenBase.setBlockAndMetadata(world, baseX + 3, baseY + 1, baseZ + 2, SokobanMod.BlockUnbreakableSolids.blockID, 0); //tile.Unbreakable Solid Blocks
        LevelGenBase.setBlockAndMetadata(world, baseX + 3, baseY + 1, baseZ + 3, Block.bedrock.blockID, 0); //tile.bedrock
        LevelGenBase.setBlockAndMetadata(world, baseX + 3, baseY + 1, baseZ + 7, Block.bedrock.blockID, 0); //tile.bedrock
        LevelGenBase.setBlockAndMetadata(world, baseX + 3, baseY + 1, baseZ + 9, SokobanMod.BlockUnbreakableSolids.blockID, 0); //tile.Unbreakable Solid Blocks
        LevelGenBase.setBlockAndMetadata(world, baseX + 3, baseY + 1, baseZ + 10, SokobanMod.BlockUnbreakableSolids.blockID, 0); //tile.Unbreakable Solid Blocks
        LevelGenBase.setBlockAndMetadata(world, baseX + 3, baseY + 1, baseZ + 11, SokobanMod.BlockUnbreakableSolids.blockID, 0); //tile.Unbreakable Solid Blocks
        LevelGenBase.setBlockAndMetadata(world, baseX + 3, baseY + 1, baseZ + 12, SokobanMod.BlockUnbreakableSolids.blockID, 0); //tile.Unbreakable Solid Blocks
        LevelGenBase.setBlockAndMetadata(world, baseX + 3, baseY + 1, baseZ + 13, SokobanMod.BlockUnbreakableSolids.blockID, 0); //tile.Unbreakable Solid Blocks
        LevelGenBase.setBlockAndMetadata(world, baseX + 3, baseY + 2, baseZ + 0, SokobanMod.BlockUnbreakableSolids.blockID, 0); //tile.Unbreakable Solid Blocks
        LevelGenBase.setBlockAndMetadata(world, baseX + 3, baseY + 2, baseZ + 1, Block.bedrock.blockID, 0); //tile.bedrock
        LevelGenBase.setBlockAndMetadata(world, baseX + 3, baseY + 2, baseZ + 2, SokobanMod.BlockUnbreakableSolids.blockID, 0); //tile.Unbreakable Solid Blocks
        LevelGenBase.setBlockAndMetadata(world, baseX + 3, baseY + 2, baseZ + 3, SokobanMod.BlockVaporizingBlock.blockID, 0); //tile.Vaporizing Block
        LevelGenBase.setBlockAndMetadata(world, baseX + 3, baseY + 2, baseZ + 4, SokobanMod.BlockUnbreakableSolids.blockID, 0); //tile.Unbreakable Solid Blocks
        LevelGenBase.setBlockAndMetadata(world, baseX + 3, baseY + 2, baseZ + 5, SokobanMod.BlockUnbreakableSolids.blockID, 0); //tile.Unbreakable Solid Blocks
        LevelGenBase.setBlockAndMetadata(world, baseX + 3, baseY + 2, baseZ + 6, SokobanMod.BlockUnbreakableSolids.blockID, 0); //tile.Unbreakable Solid Blocks
        LevelGenBase.setBlockAndMetadata(world, baseX + 3, baseY + 2, baseZ + 9, SokobanMod.BlockUnbreakableSolids.blockID, 0); //tile.Unbreakable Solid Blocks
        LevelGenBase.setBlockAndMetadata(world, baseX + 3, baseY + 2, baseZ + 10, SokobanMod.BlockUnbreakableSolids.blockID, 0); //tile.Unbreakable Solid Blocks
        LevelGenBase.setBlockAndMetadata(world, baseX + 3, baseY + 2, baseZ + 11, SokobanMod.BlockUnbreakableSolids.blockID, 0); //tile.Unbreakable Solid Blocks
        LevelGenBase.setBlockAndMetadata(world, baseX + 3, baseY + 2, baseZ + 12, SokobanMod.BlockUnbreakableSolids.blockID, 0); //tile.Unbreakable Solid Blocks
        LevelGenBase.setBlockAndMetadata(world, baseX + 3, baseY + 2, baseZ + 13, SokobanMod.BlockUnbreakableSolids.blockID, 0); //tile.Unbreakable Solid Blocks
        LevelGenBase.setBlockAndMetadata(world, baseX + 3, baseY + 3, baseZ + 0, SokobanMod.BlockUnbreakableSolids.blockID, 0); //tile.Unbreakable Solid Blocks
        LevelGenBase.setBlockAndMetadata(world, baseX + 3, baseY + 3, baseZ + 1, SokobanMod.BlockVaporizingBlock.blockID, 0); //tile.Vaporizing Block
        LevelGenBase.setBlockAndMetadata(world, baseX + 3, baseY + 3, baseZ + 2, SokobanMod.BlockUnbreakableSolids.blockID, 0); //tile.Unbreakable Solid Blocks
        LevelGenBase.setBlockAndMetadata(world, baseX + 3, baseY + 3, baseZ + 3, SokobanMod.BlockVaporizingBlock.blockID, 0); //tile.Vaporizing Block
        LevelGenBase.setBlockAndMetadata(world, baseX + 3, baseY + 3, baseZ + 7, SokobanMod.BlockUnbreakableSolids.blockID, 0); //tile.Unbreakable Solid Blocks
        LevelGenBase.setBlockAndMetadata(world, baseX + 3, baseY + 3, baseZ + 8, SokobanMod.BlockUnbreakableSolids.blockID, 0); //tile.Unbreakable Solid Blocks
        LevelGenBase.setBlockAndMetadata(world, baseX + 3, baseY + 3, baseZ + 9, SokobanMod.BlockUnbreakableSolids.blockID, 0); //tile.Unbreakable Solid Blocks
        LevelGenBase.setBlockAndMetadata(world, baseX + 3, baseY + 3, baseZ + 10, SokobanMod.BlockUnbreakableSolids.blockID, 0); //tile.Unbreakable Solid Blocks
        LevelGenBase.setBlockAndMetadata(world, baseX + 3, baseY + 3, baseZ + 11, SokobanMod.BlockUnbreakableSolids.blockID, 0); //tile.Unbreakable Solid Blocks
        LevelGenBase.setBlockAndMetadata(world, baseX + 3, baseY + 3, baseZ + 12, SokobanMod.BlockUnbreakableSolids.blockID, 0); //tile.Unbreakable Solid Blocks
        LevelGenBase.setBlockAndMetadata(world, baseX + 3, baseY + 3, baseZ + 13, SokobanMod.BlockUnbreakableSolids.blockID, 0); //tile.Unbreakable Solid Blocks
        LevelGenBase.setBlockAndMetadata(world, baseX + 3, baseY + 4, baseZ + 0, SokobanMod.BlockUnbreakableSolids.blockID, 0); //tile.Unbreakable Solid Blocks
        LevelGenBase.setBlockAndMetadata(world, baseX + 3, baseY + 4, baseZ + 1, SokobanMod.BlockVaporizingBlock.blockID, 0); //tile.Vaporizing Block
        LevelGenBase.setBlockAndMetadata(world, baseX + 3, baseY + 4, baseZ + 2, SokobanMod.BlockVaporizingBlock.blockID, 0); //tile.Vaporizing Block
        LevelGenBase.setBlockAndMetadata(world, baseX + 3, baseY + 4, baseZ + 3, SokobanMod.BlockVaporizingBlock.blockID, 0); //tile.Vaporizing Block
        LevelGenBase.setBlockAndMetadata(world, baseX + 3, baseY + 4, baseZ + 7, SokobanMod.BlockUnbreakableSolids.blockID, 0); //tile.Unbreakable Solid Blocks
        LevelGenBase.setBlockAndMetadata(world, baseX + 3, baseY + 4, baseZ + 8, SokobanMod.BlockUnbreakableSolids.blockID, 0); //tile.Unbreakable Solid Blocks
        LevelGenBase.setBlockAndMetadata(world, baseX + 3, baseY + 4, baseZ + 9, SokobanMod.BlockUnbreakableSolids.blockID, 0); //tile.Unbreakable Solid Blocks
        LevelGenBase.setBlockAndMetadata(world, baseX + 3, baseY + 4, baseZ + 10, SokobanMod.BlockUnbreakableSolids.blockID, 0); //tile.Unbreakable Solid Blocks
        LevelGenBase.setBlockAndMetadata(world, baseX + 3, baseY + 4, baseZ + 11, SokobanMod.BlockUnbreakableSolids.blockID, 0); //tile.Unbreakable Solid Blocks
        LevelGenBase.setBlockAndMetadata(world, baseX + 3, baseY + 4, baseZ + 12, SokobanMod.BlockUnbreakableSolids.blockID, 0); //tile.Unbreakable Solid Blocks
        LevelGenBase.setBlockAndMetadata(world, baseX + 3, baseY + 4, baseZ + 13, SokobanMod.BlockUnbreakableSolids.blockID, 0); //tile.Unbreakable Solid Blocks
        LevelGenBase.setBlockAndMetadata(world, baseX + 3, baseY + 5, baseZ + 0, SokobanMod.BlockUnbreakableLamps.blockID, 0); //tile.Unbreakable Lamp Blocks
        LevelGenBase.setBlockAndMetadata(world, baseX + 3, baseY + 5, baseZ + 1, SokobanMod.BlockVaporizingBlock.blockID, 0); //tile.Vaporizing Block
        LevelGenBase.setBlockAndMetadata(world, baseX + 3, baseY + 5, baseZ + 2, SokobanMod.BlockUnbreakableLamps.blockID, 0); //tile.Unbreakable Lamp Blocks
        LevelGenBase.setBlockAndMetadata(world, baseX + 3, baseY + 5, baseZ + 3, SokobanMod.BlockUnbreakableLamps.blockID, 0); //tile.Unbreakable Lamp Blocks
        LevelGenBase.setBlockAndMetadata(world, baseX + 3, baseY + 5, baseZ + 4, SokobanMod.BlockUnbreakableLamps.blockID, 0); //tile.Unbreakable Lamp Blocks
        LevelGenBase.setBlockAndMetadata(world, baseX + 3, baseY + 5, baseZ + 5, SokobanMod.BlockUnbreakableLamps.blockID, 0); //tile.Unbreakable Lamp Blocks
        LevelGenBase.setBlockAndMetadata(world, baseX + 3, baseY + 5, baseZ + 6, SokobanMod.BlockUnbreakableLamps.blockID, 0); //tile.Unbreakable Lamp Blocks
        LevelGenBase.setBlockAndMetadata(world, baseX + 3, baseY + 5, baseZ + 7, SokobanMod.BlockUnbreakableLamps.blockID, 0); //tile.Unbreakable Lamp Blocks
        LevelGenBase.setBlockAndMetadata(world, baseX + 3, baseY + 5, baseZ + 8, SokobanMod.BlockUnbreakableLamps.blockID, 0); //tile.Unbreakable Lamp Blocks
        LevelGenBase.setBlockAndMetadata(world, baseX + 3, baseY + 5, baseZ + 9, SokobanMod.BlockUnbreakableLamps.blockID, 0); //tile.Unbreakable Lamp Blocks
        LevelGenBase.setBlockAndMetadata(world, baseX + 3, baseY + 5, baseZ + 10, SokobanMod.BlockUnbreakableLamps.blockID, 0); //tile.Unbreakable Lamp Blocks
        LevelGenBase.setBlockAndMetadata(world, baseX + 3, baseY + 5, baseZ + 11, SokobanMod.BlockUnbreakableLamps.blockID, 0); //tile.Unbreakable Lamp Blocks
        LevelGenBase.setBlockAndMetadata(world, baseX + 3, baseY + 5, baseZ + 12, SokobanMod.BlockUnbreakableLamps.blockID, 0); //tile.Unbreakable Lamp Blocks
        LevelGenBase.setBlockAndMetadata(world, baseX + 3, baseY + 5, baseZ + 13, SokobanMod.BlockUnbreakableLamps.blockID, 0); //tile.Unbreakable Lamp Blocks
        LevelGenBase.setBlockAndMetadata(world, baseX + 3, baseY + 6, baseZ + 0, SokobanMod.BlockUnbreakableSolids.blockID, 0); //tile.Unbreakable Solid Blocks
        LevelGenBase.setBlockAndMetadata(world, baseX + 3, baseY + 6, baseZ + 13, SokobanMod.BlockUnbreakableSolids.blockID, 0); //tile.Unbreakable Solid Blocks
        LevelGenBase.setBlockAndMetadata(world, baseX + 3, baseY + 7, baseZ + 0, SokobanMod.BlockUnbreakableGlasses.blockID, 0); //tile.Unbreakable Glass Blocks
        LevelGenBase.setBlockAndMetadata(world, baseX + 3, baseY + 7, baseZ + 13, SokobanMod.BlockUnbreakableGlasses.blockID, 0); //tile.Unbreakable Glass Blocks
        LevelGenBase.setBlockAndMetadata(world, baseX + 3, baseY + 8, baseZ + 0, SokobanMod.BlockUnbreakableSolids.blockID, 0); //tile.Unbreakable Solid Blocks
        LevelGenBase.setBlockAndMetadata(world, baseX + 3, baseY + 8, baseZ + 13, SokobanMod.BlockUnbreakableSolids.blockID, 0); //tile.Unbreakable Solid Blocks
        LevelGenBase.setBlockAndMetadata(world, baseX + 3, baseY + 9, baseZ + 0, SokobanMod.BlockUnbreakableSolids.blockID, 0); //tile.Unbreakable Solid Blocks
        LevelGenBase.setBlockAndMetadata(world, baseX + 3, baseY + 9, baseZ + 1, SokobanMod.BlockUnbreakableSolids.blockID, 0); //tile.Unbreakable Solid Blocks
        LevelGenBase.setBlockAndMetadata(world, baseX + 3, baseY + 9, baseZ + 2, SokobanMod.BlockUnbreakableSolids.blockID, 0); //tile.Unbreakable Solid Blocks
        LevelGenBase.setBlockAndMetadata(world, baseX + 3, baseY + 9, baseZ + 3, SokobanMod.BlockUnbreakableSolids.blockID, 0); //tile.Unbreakable Solid Blocks
        LevelGenBase.setBlockAndMetadata(world, baseX + 3, baseY + 9, baseZ + 4, SokobanMod.BlockUnbreakableSolids.blockID, 0); //tile.Unbreakable Solid Blocks
        LevelGenBase.setBlockAndMetadata(world, baseX + 3, baseY + 9, baseZ + 5, SokobanMod.BlockUnbreakableSolids.blockID, 0); //tile.Unbreakable Solid Blocks
        LevelGenBase.setBlockAndMetadata(world, baseX + 3, baseY + 9, baseZ + 6, SokobanMod.BlockUnbreakableSolids.blockID, 0); //tile.Unbreakable Solid Blocks
        LevelGenBase.setBlockAndMetadata(world, baseX + 3, baseY + 9, baseZ + 7, SokobanMod.BlockUnbreakableSolids.blockID, 0); //tile.Unbreakable Solid Blocks
        LevelGenBase.setBlockAndMetadata(world, baseX + 3, baseY + 9, baseZ + 8, SokobanMod.BlockUnbreakableSolids.blockID, 0); //tile.Unbreakable Solid Blocks
        LevelGenBase.setBlockAndMetadata(world, baseX + 3, baseY + 9, baseZ + 9, SokobanMod.BlockUnbreakableSolids.blockID, 0); //tile.Unbreakable Solid Blocks
        LevelGenBase.setBlockAndMetadata(world, baseX + 3, baseY + 9, baseZ + 10, SokobanMod.BlockUnbreakableSolids.blockID, 0); //tile.Unbreakable Solid Blocks
        LevelGenBase.setBlockAndMetadata(world, baseX + 3, baseY + 9, baseZ + 11, SokobanMod.BlockUnbreakableSolids.blockID, 0); //tile.Unbreakable Solid Blocks
        LevelGenBase.setBlockAndMetadata(world, baseX + 3, baseY + 9, baseZ + 12, SokobanMod.BlockUnbreakableSolids.blockID, 0); //tile.Unbreakable Solid Blocks
        LevelGenBase.setBlockAndMetadata(world, baseX + 3, baseY + 9, baseZ + 13, SokobanMod.BlockUnbreakableSolids.blockID, 0); //tile.Unbreakable Solid Blocks
        LevelGenBase.setBlockAndMetadata(world, baseX + 4, baseY + 0, baseZ + 0, SokobanMod.BlockUnbreakableSolids.blockID, 0); //tile.Unbreakable Solid Blocks
        LevelGenBase.setBlockAndMetadata(world, baseX + 4, baseY + 0, baseZ + 1, SokobanMod.BlockUnbreakableSolids.blockID, 0); //tile.Unbreakable Solid Blocks
        LevelGenBase.setBlockAndMetadata(world, baseX + 4, baseY + 0, baseZ + 2, SokobanMod.BlockUnbreakableSolids.blockID, 0); //tile.Unbreakable Solid Blocks
        LevelGenBase.setBlockAndMetadata(world, baseX + 4, baseY + 0, baseZ + 3, SokobanMod.BlockUnbreakableSolids.blockID, 0); //tile.Unbreakable Solid Blocks
        LevelGenBase.setBlockAndMetadata(world, baseX + 4, baseY + 0, baseZ + 4, SokobanMod.BlockUnbreakableSolids.blockID, 0); //tile.Unbreakable Solid Blocks
        LevelGenBase.setBlockAndMetadata(world, baseX + 4, baseY + 0, baseZ + 5, SokobanMod.BlockUnbreakableSolids.blockID, 0); //tile.Unbreakable Solid Blocks
        LevelGenBase.setBlockAndMetadata(world, baseX + 4, baseY + 0, baseZ + 6, Block.bedrock.blockID, 0); //tile.bedrock
        LevelGenBase.setBlockAndMetadata(world, baseX + 4, baseY + 0, baseZ + 7, Block.bedrock.blockID, 0); //tile.bedrock
        LevelGenBase.setBlockAndMetadata(world, baseX + 4, baseY + 0, baseZ + 8, Block.bedrock.blockID, 0); //tile.bedrock
        LevelGenBase.setBlockAndMetadata(world, baseX + 4, baseY + 0, baseZ + 9, SokobanMod.BlockUnbreakableSolids.blockID, 0); //tile.Unbreakable Solid Blocks
        LevelGenBase.setBlockAndMetadata(world, baseX + 4, baseY + 0, baseZ + 10, SokobanMod.BlockUnbreakableSolids.blockID, 0); //tile.Unbreakable Solid Blocks
        LevelGenBase.setBlockAndMetadata(world, baseX + 4, baseY + 0, baseZ + 11, SokobanMod.BlockUnbreakableSolids.blockID, 0); //tile.Unbreakable Solid Blocks
        LevelGenBase.setBlockAndMetadata(world, baseX + 4, baseY + 0, baseZ + 12, SokobanMod.BlockUnbreakableSolids.blockID, 0); //tile.Unbreakable Solid Blocks
        LevelGenBase.setBlockAndMetadata(world, baseX + 4, baseY + 0, baseZ + 13, SokobanMod.BlockUnbreakableSolids.blockID, 0); //tile.Unbreakable Solid Blocks
        LevelGenBase.setBlockAndMetadata(world, baseX + 4, baseY + 1, baseZ + 0, SokobanMod.BlockUnbreakableSolids.blockID, 0); //tile.Unbreakable Solid Blocks
        LevelGenBase.setBlockAndMetadata(world, baseX + 4, baseY + 1, baseZ + 1, SokobanMod.BlockUnbreakableSolids.blockID, 0); //tile.Unbreakable Solid Blocks
        LevelGenBase.setBlockAndMetadata(world, baseX + 4, baseY + 1, baseZ + 2, SokobanMod.BlockUnbreakableSolids.blockID, 0); //tile.Unbreakable Solid Blocks
        LevelGenBase.setBlockAndMetadata(world, baseX + 4, baseY + 1, baseZ + 3, SokobanMod.BlockUnbreakableSolids.blockID, 0); //tile.Unbreakable Solid Blocks
        LevelGenBase.setBlockAndMetadata(world, baseX + 4, baseY + 1, baseZ + 4, SokobanMod.BlockUnbreakableSolids.blockID, 0); //tile.Unbreakable Solid Blocks
        LevelGenBase.setBlockAndMetadata(world, baseX + 4, baseY + 1, baseZ + 5, SokobanMod.BlockUnbreakableSolids.blockID, 0); //tile.Unbreakable Solid Blocks
        LevelGenBase.setBlockAndMetadata(world, baseX + 4, baseY + 1, baseZ + 9, SokobanMod.BlockUnbreakableSolids.blockID, 0); //tile.Unbreakable Solid Blocks
        LevelGenBase.setBlockAndMetadata(world, baseX + 4, baseY + 1, baseZ + 10, SokobanMod.BlockUnbreakableSolids.blockID, 0); //tile.Unbreakable Solid Blocks
        LevelGenBase.setBlockAndMetadata(world, baseX + 4, baseY + 1, baseZ + 11, SokobanMod.BlockUnbreakableSolids.blockID, 0); //tile.Unbreakable Solid Blocks
        LevelGenBase.setBlockAndMetadata(world, baseX + 4, baseY + 1, baseZ + 12, SokobanMod.BlockUnbreakableSolids.blockID, 0); //tile.Unbreakable Solid Blocks
        LevelGenBase.setBlockAndMetadata(world, baseX + 4, baseY + 1, baseZ + 13, SokobanMod.BlockUnbreakableSolids.blockID, 0); //tile.Unbreakable Solid Blocks
        LevelGenBase.setBlockAndMetadata(world, baseX + 4, baseY + 2, baseZ + 0, SokobanMod.BlockUnbreakableSolids.blockID, 0); //tile.Unbreakable Solid Blocks
        LevelGenBase.setBlockAndMetadata(world, baseX + 4, baseY + 2, baseZ + 2, SokobanMod.BlockUnbreakableSolids.blockID, 0); //tile.Unbreakable Solid Blocks
        LevelGenBase.setBlockAndMetadata(world, baseX + 4, baseY + 2, baseZ + 3, SokobanMod.BlockUnbreakableSolids.blockID, 0); //tile.Unbreakable Solid Blocks
        LevelGenBase.setBlockAndMetadata(world, baseX + 4, baseY + 2, baseZ + 4, SokobanMod.BlockUnbreakableSolids.blockID, 0); //tile.Unbreakable Solid Blocks
        LevelGenBase.setBlockAndMetadata(world, baseX + 4, baseY + 2, baseZ + 5, SokobanMod.BlockUnbreakableSolids.blockID, 0); //tile.Unbreakable Solid Blocks
        LevelGenBase.setBlockAndMetadata(world, baseX + 4, baseY + 2, baseZ + 6, SokobanMod.BlockTarget.blockID, 0); //tile.Target
        LevelGenBase.setBlockAndMetadata(world, baseX + 4, baseY + 2, baseZ + 7, SokobanMod.BlockUnbreakableSolids.blockID, 0); //tile.Unbreakable Solid Blocks
        LevelGenBase.setBlockAndMetadata(world, baseX + 4, baseY + 2, baseZ + 8, SokobanMod.BlockUnbreakableSolids.blockID, 0); //tile.Unbreakable Solid Blocks
        LevelGenBase.setBlockAndMetadata(world, baseX + 4, baseY + 2, baseZ + 9, SokobanMod.BlockUnbreakableSolids.blockID, 0); //tile.Unbreakable Solid Blocks
        LevelGenBase.setBlockAndMetadata(world, baseX + 4, baseY + 2, baseZ + 13, SokobanMod.BlockUnbreakableSolids.blockID, 0); //tile.Unbreakable Solid Blocks
        LevelGenBase.setBlockAndMetadata(world, baseX + 4, baseY + 3, baseZ + 0, SokobanMod.BlockUnbreakableSolids.blockID, 0); //tile.Unbreakable Solid Blocks
        LevelGenBase.setBlockAndMetadata(world, baseX + 4, baseY + 3, baseZ + 2, SokobanMod.BlockUnbreakableSolids.blockID, 0); //tile.Unbreakable Solid Blocks
        LevelGenBase.setBlockAndMetadata(world, baseX + 4, baseY + 3, baseZ + 9, SokobanMod.BlockUnbreakableSolids.blockID, 0); //tile.Unbreakable Solid Blocks
        LevelGenBase.setBlockAndMetadata(world, baseX + 4, baseY + 3, baseZ + 13, SokobanMod.BlockUnbreakableSolids.blockID, 0); //tile.Unbreakable Solid Blocks
        LevelGenBase.setBlockAndMetadata(world, baseX + 4, baseY + 4, baseZ + 0, SokobanMod.BlockUnbreakableSolids.blockID, 0); //tile.Unbreakable Solid Blocks
        LevelGenBase.setBlockAndMetadata(world, baseX + 4, baseY + 4, baseZ + 2, SokobanMod.BlockUnbreakableSolids.blockID, 0); //tile.Unbreakable Solid Blocks
        LevelGenBase.setBlockAndMetadata(world, baseX + 4, baseY + 4, baseZ + 9, SokobanMod.BlockUnbreakableSolids.blockID, 0); //tile.Unbreakable Solid Blocks
        LevelGenBase.setBlockAndMetadata(world, baseX + 4, baseY + 4, baseZ + 13, SokobanMod.BlockUnbreakableSolids.blockID, 0); //tile.Unbreakable Solid Blocks
        LevelGenBase.setBlockAndMetadata(world, baseX + 4, baseY + 5, baseZ + 0, SokobanMod.BlockUnbreakableLamps.blockID, 0); //tile.Unbreakable Lamp Blocks
        LevelGenBase.setBlockAndMetadata(world, baseX + 4, baseY + 5, baseZ + 2, SokobanMod.BlockUnbreakableLamps.blockID, 0); //tile.Unbreakable Lamp Blocks
        LevelGenBase.setBlockAndMetadata(world, baseX + 4, baseY + 5, baseZ + 3, SokobanMod.BlockUnbreakableLamps.blockID, 0); //tile.Unbreakable Lamp Blocks
        LevelGenBase.setBlockAndMetadata(world, baseX + 4, baseY + 5, baseZ + 4, SokobanMod.BlockUnbreakableLamps.blockID, 0); //tile.Unbreakable Lamp Blocks
        LevelGenBase.setBlockAndMetadata(world, baseX + 4, baseY + 5, baseZ + 5, SokobanMod.BlockUnbreakableLamps.blockID, 0); //tile.Unbreakable Lamp Blocks
        LevelGenBase.setBlockAndMetadata(world, baseX + 4, baseY + 5, baseZ + 6, SokobanMod.BlockUnbreakableLamps.blockID, 0); //tile.Unbreakable Lamp Blocks
        LevelGenBase.setBlockAndMetadata(world, baseX + 4, baseY + 5, baseZ + 7, SokobanMod.BlockUnbreakableLamps.blockID, 0); //tile.Unbreakable Lamp Blocks
        LevelGenBase.setBlockAndMetadata(world, baseX + 4, baseY + 5, baseZ + 8, SokobanMod.BlockUnbreakableLamps.blockID, 0); //tile.Unbreakable Lamp Blocks
        LevelGenBase.setBlockAndMetadata(world, baseX + 4, baseY + 5, baseZ + 9, SokobanMod.BlockUnbreakableLamps.blockID, 0); //tile.Unbreakable Lamp Blocks
        LevelGenBase.setBlockAndMetadata(world, baseX + 4, baseY + 5, baseZ + 10, SokobanMod.BlockUnbreakableLamps.blockID, 0); //tile.Unbreakable Lamp Blocks
        LevelGenBase.setBlockAndMetadata(world, baseX + 4, baseY + 5, baseZ + 11, SokobanMod.BlockUnbreakableLamps.blockID, 0); //tile.Unbreakable Lamp Blocks
        LevelGenBase.setBlockAndMetadata(world, baseX + 4, baseY + 5, baseZ + 12, SokobanMod.BlockUnbreakableLamps.blockID, 0); //tile.Unbreakable Lamp Blocks
        LevelGenBase.setBlockAndMetadata(world, baseX + 4, baseY + 5, baseZ + 13, SokobanMod.BlockUnbreakableLamps.blockID, 0); //tile.Unbreakable Lamp Blocks
        LevelGenBase.setBlockAndMetadata(world, baseX + 4, baseY + 6, baseZ + 0, SokobanMod.BlockUnbreakableSolids.blockID, 0); //tile.Unbreakable Solid Blocks
        LevelGenBase.setBlockAndMetadata(world, baseX + 4, baseY + 6, baseZ + 13, SokobanMod.BlockUnbreakableSolids.blockID, 0); //tile.Unbreakable Solid Blocks
        LevelGenBase.setBlockAndMetadata(world, baseX + 4, baseY + 7, baseZ + 0, SokobanMod.BlockUnbreakableGlasses.blockID, 0); //tile.Unbreakable Glass Blocks
        LevelGenBase.setBlockAndMetadata(world, baseX + 4, baseY + 7, baseZ + 13, SokobanMod.BlockUnbreakableGlasses.blockID, 0); //tile.Unbreakable Glass Blocks
        LevelGenBase.setBlockAndMetadata(world, baseX + 4, baseY + 8, baseZ + 0, SokobanMod.BlockUnbreakableSolids.blockID, 0); //tile.Unbreakable Solid Blocks
        LevelGenBase.setBlockAndMetadata(world, baseX + 4, baseY + 8, baseZ + 13, SokobanMod.BlockUnbreakableSolids.blockID, 0); //tile.Unbreakable Solid Blocks
        LevelGenBase.setBlockAndMetadata(world, baseX + 4, baseY + 9, baseZ + 0, SokobanMod.BlockUnbreakableSolids.blockID, 0); //tile.Unbreakable Solid Blocks
        LevelGenBase.setBlockAndMetadata(world, baseX + 4, baseY + 9, baseZ + 1, SokobanMod.BlockUnbreakableSolids.blockID, 0); //tile.Unbreakable Solid Blocks
        LevelGenBase.setBlockAndMetadata(world, baseX + 4, baseY + 9, baseZ + 2, SokobanMod.BlockUnbreakableSolids.blockID, 0); //tile.Unbreakable Solid Blocks
        LevelGenBase.setBlockAndMetadata(world, baseX + 4, baseY + 9, baseZ + 3, SokobanMod.BlockUnbreakableSolids.blockID, 0); //tile.Unbreakable Solid Blocks
        LevelGenBase.setBlockAndMetadata(world, baseX + 4, baseY + 9, baseZ + 4, SokobanMod.BlockUnbreakableSolids.blockID, 0); //tile.Unbreakable Solid Blocks
        LevelGenBase.setBlockAndMetadata(world, baseX + 4, baseY + 9, baseZ + 5, SokobanMod.BlockUnbreakableSolids.blockID, 0); //tile.Unbreakable Solid Blocks
        LevelGenBase.setBlockAndMetadata(world, baseX + 4, baseY + 9, baseZ + 6, SokobanMod.BlockUnbreakableSolids.blockID, 0); //tile.Unbreakable Solid Blocks
        LevelGenBase.setBlockAndMetadata(world, baseX + 4, baseY + 9, baseZ + 7, SokobanMod.BlockUnbreakableSolids.blockID, 0); //tile.Unbreakable Solid Blocks
        LevelGenBase.setBlockAndMetadata(world, baseX + 4, baseY + 9, baseZ + 8, SokobanMod.BlockUnbreakableSolids.blockID, 0); //tile.Unbreakable Solid Blocks
        LevelGenBase.setBlockAndMetadata(world, baseX + 4, baseY + 9, baseZ + 9, SokobanMod.BlockUnbreakableSolids.blockID, 0); //tile.Unbreakable Solid Blocks
        LevelGenBase.setBlockAndMetadata(world, baseX + 4, baseY + 9, baseZ + 10, SokobanMod.BlockUnbreakableSolids.blockID, 0); //tile.Unbreakable Solid Blocks
        LevelGenBase.setBlockAndMetadata(world, baseX + 4, baseY + 9, baseZ + 11, SokobanMod.BlockUnbreakableSolids.blockID, 0); //tile.Unbreakable Solid Blocks
        LevelGenBase.setBlockAndMetadata(world, baseX + 4, baseY + 9, baseZ + 12, SokobanMod.BlockUnbreakableSolids.blockID, 0); //tile.Unbreakable Solid Blocks
        LevelGenBase.setBlockAndMetadata(world, baseX + 4, baseY + 9, baseZ + 13, SokobanMod.BlockUnbreakableSolids.blockID, 0); //tile.Unbreakable Solid Blocks
        LevelGenBase.setBlockAndMetadata(world, baseX + 5, baseY + 0, baseZ + 0, SokobanMod.BlockUnbreakableSolids.blockID, 0); //tile.Unbreakable Solid Blocks
        LevelGenBase.setBlockAndMetadata(world, baseX + 5, baseY + 0, baseZ + 1, SokobanMod.BlockUnbreakableSolids.blockID, 0); //tile.Unbreakable Solid Blocks
        LevelGenBase.setBlockAndMetadata(world, baseX + 5, baseY + 0, baseZ + 2, SokobanMod.BlockUnbreakableSolids.blockID, 0); //tile.Unbreakable Solid Blocks
        LevelGenBase.setBlockAndMetadata(world, baseX + 5, baseY + 0, baseZ + 3, SokobanMod.BlockUnbreakableSolids.blockID, 0); //tile.Unbreakable Solid Blocks
        LevelGenBase.setBlockAndMetadata(world, baseX + 5, baseY + 0, baseZ + 4, SokobanMod.BlockUnbreakableSolids.blockID, 0); //tile.Unbreakable Solid Blocks
        LevelGenBase.setBlockAndMetadata(world, baseX + 5, baseY + 0, baseZ + 5, SokobanMod.BlockUnbreakableSolids.blockID, 0); //tile.Unbreakable Solid Blocks
        LevelGenBase.setBlockAndMetadata(world, baseX + 5, baseY + 0, baseZ + 6, SokobanMod.BlockUnbreakableSolids.blockID, 0); //tile.Unbreakable Solid Blocks
        LevelGenBase.setBlockAndMetadata(world, baseX + 5, baseY + 0, baseZ + 7, SokobanMod.BlockUnbreakableSolids.blockID, 0); //tile.Unbreakable Solid Blocks
        LevelGenBase.setBlockAndMetadata(world, baseX + 5, baseY + 0, baseZ + 8, SokobanMod.BlockUnbreakableSolids.blockID, 0); //tile.Unbreakable Solid Blocks
        LevelGenBase.setBlockAndMetadata(world, baseX + 5, baseY + 0, baseZ + 9, SokobanMod.BlockUnbreakableSolids.blockID, 0); //tile.Unbreakable Solid Blocks
        LevelGenBase.setBlockAndMetadata(world, baseX + 5, baseY + 0, baseZ + 10, SokobanMod.BlockUnbreakableSolids.blockID, 0); //tile.Unbreakable Solid Blocks
        LevelGenBase.setBlockAndMetadata(world, baseX + 5, baseY + 0, baseZ + 11, SokobanMod.BlockUnbreakableSolids.blockID, 0); //tile.Unbreakable Solid Blocks
        LevelGenBase.setBlockAndMetadata(world, baseX + 5, baseY + 0, baseZ + 12, SokobanMod.BlockUnbreakableSolids.blockID, 0); //tile.Unbreakable Solid Blocks
        LevelGenBase.setBlockAndMetadata(world, baseX + 5, baseY + 0, baseZ + 13, SokobanMod.BlockUnbreakableSolids.blockID, 0); //tile.Unbreakable Solid Blocks
        LevelGenBase.setBlockAndMetadata(world, baseX + 5, baseY + 1, baseZ + 0, SokobanMod.BlockUnbreakableSolids.blockID, 0); //tile.Unbreakable Solid Blocks
        LevelGenBase.setBlockAndMetadata(world, baseX + 5, baseY + 1, baseZ + 1, SokobanMod.BlockUnbreakableSolids.blockID, 0); //tile.Unbreakable Solid Blocks
        LevelGenBase.setBlockAndMetadata(world, baseX + 5, baseY + 1, baseZ + 2, SokobanMod.BlockUnbreakableSolids.blockID, 0); //tile.Unbreakable Solid Blocks
        LevelGenBase.setBlockAndMetadata(world, baseX + 5, baseY + 1, baseZ + 3, SokobanMod.BlockUnbreakableSolids.blockID, 0); //tile.Unbreakable Solid Blocks
        LevelGenBase.setBlockAndMetadata(world, baseX + 5, baseY + 1, baseZ + 4, SokobanMod.BlockUnbreakableSolids.blockID, 0); //tile.Unbreakable Solid Blocks
        LevelGenBase.setBlockAndMetadata(world, baseX + 5, baseY + 1, baseZ + 5, SokobanMod.BlockUnbreakableSolids.blockID, 0); //tile.Unbreakable Solid Blocks
        LevelGenBase.setBlockAndMetadata(world, baseX + 5, baseY + 1, baseZ + 6, SokobanMod.BlockUnbreakableSolids.blockID, 0); //tile.Unbreakable Solid Blocks
        LevelGenBase.setBlockAndMetadata(world, baseX + 5, baseY + 1, baseZ + 7, SokobanMod.BlockUnbreakableSolids.blockID, 0); //tile.Unbreakable Solid Blocks
        LevelGenBase.setBlockAndMetadata(world, baseX + 5, baseY + 1, baseZ + 8, SokobanMod.BlockUnbreakableSolids.blockID, 0); //tile.Unbreakable Solid Blocks
        LevelGenBase.setBlockAndMetadata(world, baseX + 5, baseY + 1, baseZ + 9, SokobanMod.BlockUnbreakableSolids.blockID, 0); //tile.Unbreakable Solid Blocks
        LevelGenBase.setBlockAndMetadata(world, baseX + 5, baseY + 1, baseZ + 10, SokobanMod.BlockUnbreakableSolids.blockID, 0); //tile.Unbreakable Solid Blocks
        LevelGenBase.setBlockAndMetadata(world, baseX + 5, baseY + 1, baseZ + 11, SokobanMod.BlockUnbreakableSolids.blockID, 0); //tile.Unbreakable Solid Blocks
        LevelGenBase.setBlockAndMetadata(world, baseX + 5, baseY + 1, baseZ + 12, SokobanMod.BlockUnbreakableSolids.blockID, 0); //tile.Unbreakable Solid Blocks
        LevelGenBase.setBlockAndMetadata(world, baseX + 5, baseY + 1, baseZ + 13, SokobanMod.BlockUnbreakableSolids.blockID, 0); //tile.Unbreakable Solid Blocks
        LevelGenBase.setBlockAndMetadata(world, baseX + 5, baseY + 2, baseZ + 2, SokobanMod.BlockUnbreakableSolids.blockID, 0); //tile.Unbreakable Solid Blocks
        LevelGenBase.setBlockAndMetadata(world, baseX + 5, baseY + 2, baseZ + 3, SokobanMod.BlockUnbreakableSolids.blockID, 0); //tile.Unbreakable Solid Blocks
        LevelGenBase.setBlockAndMetadata(world, baseX + 5, baseY + 2, baseZ + 4, SokobanMod.BlockUnbreakableSolids.blockID, 0); //tile.Unbreakable Solid Blocks
        LevelGenBase.setBlockAndMetadata(world, baseX + 5, baseY + 2, baseZ + 5, SokobanMod.BlockUnbreakableSolids.blockID, 0); //tile.Unbreakable Solid Blocks
        LevelGenBase.setBlockAndMetadata(world, baseX + 5, baseY + 2, baseZ + 6, SokobanMod.BlockUnbreakableSolids.blockID, 0); //tile.Unbreakable Solid Blocks
        LevelGenBase.setBlockAndMetadata(world, baseX + 5, baseY + 2, baseZ + 7, SokobanMod.BlockUnbreakableSolids.blockID, 0); //tile.Unbreakable Solid Blocks
        LevelGenBase.setBlockAndMetadata(world, baseX + 5, baseY + 2, baseZ + 8, SokobanMod.BlockUnbreakableSolids.blockID, 0); //tile.Unbreakable Solid Blocks
        LevelGenBase.setBlockAndMetadata(world, baseX + 5, baseY + 2, baseZ + 9, SokobanMod.BlockUnbreakableSolids.blockID, 0); //tile.Unbreakable Solid Blocks
        LevelGenBase.setBlockAndMetadata(world, baseX + 5, baseY + 2, baseZ + 11, SokobanMod.BlockUnbreakableSolids.blockID, 0); //tile.Unbreakable Solid Blocks
        LevelGenBase.setBlockAndMetadata(world, baseX + 5, baseY + 3, baseZ + 2, SokobanMod.BlockUnbreakableSolids.blockID, 0); //tile.Unbreakable Solid Blocks
        LevelGenBase.setBlockAndMetadata(world, baseX + 5, baseY + 3, baseZ + 9, SokobanMod.BlockUnbreakableSolids.blockID, 0); //tile.Unbreakable Solid Blocks
        LevelGenBase.setBlockAndMetadata(world, baseX + 5, baseY + 3, baseZ + 11, SokobanMod.BlockUnbreakableSolids.blockID, 0); //tile.Unbreakable Solid Blocks
        LevelGenBase.setBlockAndMetadata(world, baseX + 5, baseY + 4, baseZ + 2, SokobanMod.BlockUnbreakableSolids.blockID, 0); //tile.Unbreakable Solid Blocks
        LevelGenBase.setBlockAndMetadata(world, baseX + 5, baseY + 4, baseZ + 9, SokobanMod.BlockUnbreakableSolids.blockID, 0); //tile.Unbreakable Solid Blocks
        LevelGenBase.setBlockAndMetadata(world, baseX + 5, baseY + 4, baseZ + 11, SokobanMod.BlockUnbreakableSolids.blockID, 0); //tile.Unbreakable Solid Blocks
        LevelGenBase.setBlockAndMetadata(world, baseX + 5, baseY + 5, baseZ + 0, SokobanMod.BlockUnbreakableLamps.blockID, 0); //tile.Unbreakable Lamp Blocks
        LevelGenBase.setBlockAndMetadata(world, baseX + 5, baseY + 5, baseZ + 1, SokobanMod.BlockUnbreakableLamps.blockID, 0); //tile.Unbreakable Lamp Blocks
        LevelGenBase.setBlockAndMetadata(world, baseX + 5, baseY + 5, baseZ + 2, SokobanMod.BlockUnbreakableLamps.blockID, 0); //tile.Unbreakable Lamp Blocks
        LevelGenBase.setBlockAndMetadata(world, baseX + 5, baseY + 5, baseZ + 3, SokobanMod.BlockUnbreakableLamps.blockID, 0); //tile.Unbreakable Lamp Blocks
        LevelGenBase.setBlockAndMetadata(world, baseX + 5, baseY + 5, baseZ + 4, SokobanMod.BlockUnbreakableLamps.blockID, 0); //tile.Unbreakable Lamp Blocks
        LevelGenBase.setBlockAndMetadata(world, baseX + 5, baseY + 5, baseZ + 5, SokobanMod.BlockUnbreakableLamps.blockID, 0); //tile.Unbreakable Lamp Blocks
        LevelGenBase.setBlockAndMetadata(world, baseX + 5, baseY + 5, baseZ + 6, SokobanMod.BlockUnbreakableLamps.blockID, 0); //tile.Unbreakable Lamp Blocks
        LevelGenBase.setBlockAndMetadata(world, baseX + 5, baseY + 5, baseZ + 7, SokobanMod.BlockUnbreakableLamps.blockID, 0); //tile.Unbreakable Lamp Blocks
        LevelGenBase.setBlockAndMetadata(world, baseX + 5, baseY + 5, baseZ + 8, SokobanMod.BlockUnbreakableLamps.blockID, 0); //tile.Unbreakable Lamp Blocks
        LevelGenBase.setBlockAndMetadata(world, baseX + 5, baseY + 5, baseZ + 9, SokobanMod.BlockUnbreakableLamps.blockID, 0); //tile.Unbreakable Lamp Blocks
        LevelGenBase.setBlockAndMetadata(world, baseX + 5, baseY + 5, baseZ + 10, SokobanMod.BlockUnbreakableLamps.blockID, 0); //tile.Unbreakable Lamp Blocks
        LevelGenBase.setBlockAndMetadata(world, baseX + 5, baseY + 5, baseZ + 11, SokobanMod.BlockUnbreakableLamps.blockID, 0); //tile.Unbreakable Lamp Blocks
        LevelGenBase.setBlockAndMetadata(world, baseX + 5, baseY + 5, baseZ + 12, SokobanMod.BlockUnbreakableLamps.blockID, 0); //tile.Unbreakable Lamp Blocks
        LevelGenBase.setBlockAndMetadata(world, baseX + 5, baseY + 5, baseZ + 13, SokobanMod.BlockUnbreakableLamps.blockID, 0); //tile.Unbreakable Lamp Blocks
        LevelGenBase.setBlockAndMetadata(world, baseX + 5, baseY + 6, baseZ + 0, SokobanMod.BlockUnbreakableSolids.blockID, 0); //tile.Unbreakable Solid Blocks
        LevelGenBase.setBlockAndMetadata(world, baseX + 5, baseY + 6, baseZ + 13, SokobanMod.BlockUnbreakableSolids.blockID, 0); //tile.Unbreakable Solid Blocks
        LevelGenBase.setBlockAndMetadata(world, baseX + 5, baseY + 7, baseZ + 0, SokobanMod.BlockUnbreakableGlasses.blockID, 0); //tile.Unbreakable Glass Blocks
        LevelGenBase.setBlockAndMetadata(world, baseX + 5, baseY + 7, baseZ + 13, SokobanMod.BlockUnbreakableGlasses.blockID, 0); //tile.Unbreakable Glass Blocks
        LevelGenBase.setBlockAndMetadata(world, baseX + 5, baseY + 8, baseZ + 0, SokobanMod.BlockUnbreakableSolids.blockID, 0); //tile.Unbreakable Solid Blocks
        LevelGenBase.setBlockAndMetadata(world, baseX + 5, baseY + 8, baseZ + 13, SokobanMod.BlockUnbreakableSolids.blockID, 0); //tile.Unbreakable Solid Blocks
        LevelGenBase.setBlockAndMetadata(world, baseX + 5, baseY + 9, baseZ + 0, SokobanMod.BlockUnbreakableSolids.blockID, 0); //tile.Unbreakable Solid Blocks
        LevelGenBase.setBlockAndMetadata(world, baseX + 5, baseY + 9, baseZ + 1, SokobanMod.BlockUnbreakableSolids.blockID, 0); //tile.Unbreakable Solid Blocks
        LevelGenBase.setBlockAndMetadata(world, baseX + 5, baseY + 9, baseZ + 2, SokobanMod.BlockUnbreakableSolids.blockID, 0); //tile.Unbreakable Solid Blocks
        LevelGenBase.setBlockAndMetadata(world, baseX + 5, baseY + 9, baseZ + 3, SokobanMod.BlockUnbreakableSolids.blockID, 0); //tile.Unbreakable Solid Blocks
        LevelGenBase.setBlockAndMetadata(world, baseX + 5, baseY + 9, baseZ + 4, SokobanMod.BlockUnbreakableSolids.blockID, 0); //tile.Unbreakable Solid Blocks
        LevelGenBase.setBlockAndMetadata(world, baseX + 5, baseY + 9, baseZ + 5, SokobanMod.BlockUnbreakableSolids.blockID, 0); //tile.Unbreakable Solid Blocks
        LevelGenBase.setBlockAndMetadata(world, baseX + 5, baseY + 9, baseZ + 6, SokobanMod.BlockUnbreakableSolids.blockID, 0); //tile.Unbreakable Solid Blocks
        LevelGenBase.setBlockAndMetadata(world, baseX + 5, baseY + 9, baseZ + 7, SokobanMod.BlockUnbreakableSolids.blockID, 0); //tile.Unbreakable Solid Blocks
        LevelGenBase.setBlockAndMetadata(world, baseX + 5, baseY + 9, baseZ + 8, SokobanMod.BlockUnbreakableSolids.blockID, 0); //tile.Unbreakable Solid Blocks
        LevelGenBase.setBlockAndMetadata(world, baseX + 5, baseY + 9, baseZ + 9, SokobanMod.BlockUnbreakableSolids.blockID, 0); //tile.Unbreakable Solid Blocks
        LevelGenBase.setBlockAndMetadata(world, baseX + 5, baseY + 9, baseZ + 10, SokobanMod.BlockUnbreakableSolids.blockID, 0); //tile.Unbreakable Solid Blocks
        LevelGenBase.setBlockAndMetadata(world, baseX + 5, baseY + 9, baseZ + 11, SokobanMod.BlockUnbreakableSolids.blockID, 0); //tile.Unbreakable Solid Blocks
        LevelGenBase.setBlockAndMetadata(world, baseX + 5, baseY + 9, baseZ + 12, SokobanMod.BlockUnbreakableSolids.blockID, 0); //tile.Unbreakable Solid Blocks
        LevelGenBase.setBlockAndMetadata(world, baseX + 5, baseY + 9, baseZ + 13, SokobanMod.BlockUnbreakableSolids.blockID, 0); //tile.Unbreakable Solid Blocks
        LevelGenBase.setBlockAndMetadata(world, baseX + 6, baseY + 0, baseZ + 0, SokobanMod.BlockUnbreakableSolids.blockID, 0); //tile.Unbreakable Solid Blocks
        LevelGenBase.setBlockAndMetadata(world, baseX + 6, baseY + 0, baseZ + 1, SokobanMod.BlockUnbreakableSolids.blockID, 0); //tile.Unbreakable Solid Blocks
        LevelGenBase.setBlockAndMetadata(world, baseX + 6, baseY + 0, baseZ + 2, SokobanMod.BlockUnbreakableSolids.blockID, 0); //tile.Unbreakable Solid Blocks
        LevelGenBase.setBlockAndMetadata(world, baseX + 6, baseY + 0, baseZ + 3, SokobanMod.BlockUnbreakableSolids.blockID, 0); //tile.Unbreakable Solid Blocks
        LevelGenBase.setBlockAndMetadata(world, baseX + 6, baseY + 0, baseZ + 4, SokobanMod.BlockUnbreakableSolids.blockID, 0); //tile.Unbreakable Solid Blocks
        LevelGenBase.setBlockAndMetadata(world, baseX + 6, baseY + 0, baseZ + 5, SokobanMod.BlockUnbreakableSolids.blockID, 0); //tile.Unbreakable Solid Blocks
        LevelGenBase.setBlockAndMetadata(world, baseX + 6, baseY + 0, baseZ + 6, SokobanMod.BlockUnbreakableSolids.blockID, 0); //tile.Unbreakable Solid Blocks
        LevelGenBase.setBlockAndMetadata(world, baseX + 6, baseY + 0, baseZ + 7, SokobanMod.BlockUnbreakableSolids.blockID, 0); //tile.Unbreakable Solid Blocks
        LevelGenBase.setBlockAndMetadata(world, baseX + 6, baseY + 0, baseZ + 8, SokobanMod.BlockUnbreakableSolids.blockID, 0); //tile.Unbreakable Solid Blocks
        LevelGenBase.setBlockAndMetadata(world, baseX + 6, baseY + 0, baseZ + 9, SokobanMod.BlockUnbreakableSolids.blockID, 0); //tile.Unbreakable Solid Blocks
        LevelGenBase.setBlockAndMetadata(world, baseX + 6, baseY + 0, baseZ + 10, SokobanMod.BlockUnbreakableSolids.blockID, 0); //tile.Unbreakable Solid Blocks
        LevelGenBase.setBlockAndMetadata(world, baseX + 6, baseY + 0, baseZ + 11, SokobanMod.BlockUnbreakableSolids.blockID, 0); //tile.Unbreakable Solid Blocks
        LevelGenBase.setBlockAndMetadata(world, baseX + 6, baseY + 0, baseZ + 12, SokobanMod.BlockUnbreakableSolids.blockID, 0); //tile.Unbreakable Solid Blocks
        LevelGenBase.setBlockAndMetadata(world, baseX + 6, baseY + 0, baseZ + 13, SokobanMod.BlockUnbreakableSolids.blockID, 0); //tile.Unbreakable Solid Blocks
        LevelGenBase.setBlockAndMetadata(world, baseX + 6, baseY + 1, baseZ + 0, SokobanMod.BlockUnbreakableSolids.blockID, 0); //tile.Unbreakable Solid Blocks
        LevelGenBase.setBlockAndMetadata(world, baseX + 6, baseY + 1, baseZ + 1, SokobanMod.BlockUnbreakableSolids.blockID, 0); //tile.Unbreakable Solid Blocks
        LevelGenBase.setBlockAndMetadata(world, baseX + 6, baseY + 1, baseZ + 2, SokobanMod.BlockUnbreakableSolids.blockID, 0); //tile.Unbreakable Solid Blocks
        LevelGenBase.setBlockAndMetadata(world, baseX + 6, baseY + 1, baseZ + 3, SokobanMod.BlockUnbreakableSolids.blockID, 0); //tile.Unbreakable Solid Blocks
        LevelGenBase.setBlockAndMetadata(world, baseX + 6, baseY + 1, baseZ + 4, SokobanMod.BlockUnbreakableSolids.blockID, 0); //tile.Unbreakable Solid Blocks
        LevelGenBase.setBlockAndMetadata(world, baseX + 6, baseY + 1, baseZ + 5, SokobanMod.BlockUnbreakableSolids.blockID, 0); //tile.Unbreakable Solid Blocks
        LevelGenBase.setBlockAndMetadata(world, baseX + 6, baseY + 1, baseZ + 6, SokobanMod.BlockUnbreakableSolids.blockID, 0); //tile.Unbreakable Solid Blocks
        LevelGenBase.setBlockAndMetadata(world, baseX + 6, baseY + 1, baseZ + 7, SokobanMod.BlockUnbreakableSolids.blockID, 0); //tile.Unbreakable Solid Blocks
        LevelGenBase.setBlockAndMetadata(world, baseX + 6, baseY + 1, baseZ + 8, SokobanMod.BlockUnbreakableSolids.blockID, 0); //tile.Unbreakable Solid Blocks
        LevelGenBase.setBlockAndMetadata(world, baseX + 6, baseY + 1, baseZ + 9, SokobanMod.BlockUnbreakableSolids.blockID, 0); //tile.Unbreakable Solid Blocks
        LevelGenBase.setBlockAndMetadata(world, baseX + 6, baseY + 1, baseZ + 10, SokobanMod.BlockUnbreakableSolids.blockID, 0); //tile.Unbreakable Solid Blocks
        LevelGenBase.setBlockAndMetadata(world, baseX + 6, baseY + 1, baseZ + 11, SokobanMod.BlockUnbreakableSolids.blockID, 0); //tile.Unbreakable Solid Blocks
        LevelGenBase.setBlockAndMetadata(world, baseX + 6, baseY + 1, baseZ + 12, SokobanMod.BlockUnbreakableSolids.blockID, 0); //tile.Unbreakable Solid Blocks
        LevelGenBase.setBlockAndMetadata(world, baseX + 6, baseY + 1, baseZ + 13, SokobanMod.BlockUnbreakableSolids.blockID, 0); //tile.Unbreakable Solid Blocks
        LevelGenBase.setBlockAndMetadata(world, baseX + 6, baseY + 2, baseZ + 0, SokobanMod.BlockUnbreakableSolids.blockID, 0); //tile.Unbreakable Solid Blocks
        LevelGenBase.setBlockAndMetadata(world, baseX + 6, baseY + 2, baseZ + 2, SokobanMod.BlockUnbreakableSolids.blockID, 0); //tile.Unbreakable Solid Blocks
        LevelGenBase.setBlockAndMetadata(world, baseX + 6, baseY + 2, baseZ + 3, SokobanMod.BlockUnbreakableSolids.blockID, 0); //tile.Unbreakable Solid Blocks
        LevelGenBase.setBlockAndMetadata(world, baseX + 6, baseY + 2, baseZ + 4, SokobanMod.BlockUnbreakableSolids.blockID, 0); //tile.Unbreakable Solid Blocks
        LevelGenBase.setBlockAndMetadata(world, baseX + 6, baseY + 2, baseZ + 5, SokobanMod.BlockUnbreakableSolids.blockID, 0); //tile.Unbreakable Solid Blocks
        LevelGenBase.setBlockAndMetadata(world, baseX + 6, baseY + 2, baseZ + 6, SokobanMod.BlockUnbreakableSolids.blockID, 0); //tile.Unbreakable Solid Blocks
        LevelGenBase.setBlockAndMetadata(world, baseX + 6, baseY + 2, baseZ + 7, SokobanMod.BlockUnbreakableSolids.blockID, 0); //tile.Unbreakable Solid Blocks
        LevelGenBase.setBlockAndMetadata(world, baseX + 6, baseY + 2, baseZ + 8, SokobanMod.BlockUnbreakableSolids.blockID, 0); //tile.Unbreakable Solid Blocks
        LevelGenBase.setBlockAndMetadata(world, baseX + 6, baseY + 2, baseZ + 9, SokobanMod.BlockUnbreakableSolids.blockID, 0); //tile.Unbreakable Solid Blocks
        LevelGenBase.setBlockAndMetadata(world, baseX + 6, baseY + 2, baseZ + 11, SokobanMod.BlockUnbreakableSolids.blockID, 0); //tile.Unbreakable Solid Blocks
        LevelGenBase.setBlockAndMetadata(world, baseX + 6, baseY + 2, baseZ + 13, SokobanMod.BlockUnbreakableSolids.blockID, 0); //tile.Unbreakable Solid Blocks
        LevelGenBase.setBlockAndMetadata(world, baseX + 6, baseY + 3, baseZ + 0, SokobanMod.BlockUnbreakableSolids.blockID, 0); //tile.Unbreakable Solid Blocks
        LevelGenBase.setBlockAndMetadata(world, baseX + 6, baseY + 3, baseZ + 2, SokobanMod.BlockUnbreakableSolids.blockID, 0); //tile.Unbreakable Solid Blocks
        LevelGenBase.setBlockAndMetadata(world, baseX + 6, baseY + 3, baseZ + 9, SokobanMod.BlockUnbreakableSolids.blockID, 0); //tile.Unbreakable Solid Blocks
        LevelGenBase.setBlockAndMetadata(world, baseX + 6, baseY + 3, baseZ + 11, SokobanMod.BlockUnbreakableSolids.blockID, 0); //tile.Unbreakable Solid Blocks
        LevelGenBase.setBlockAndMetadata(world, baseX + 6, baseY + 3, baseZ + 13, SokobanMod.BlockUnbreakableSolids.blockID, 0); //tile.Unbreakable Solid Blocks
        LevelGenBase.setBlockAndMetadata(world, baseX + 6, baseY + 4, baseZ + 0, SokobanMod.BlockUnbreakableSolids.blockID, 0); //tile.Unbreakable Solid Blocks
        LevelGenBase.setBlockAndMetadata(world, baseX + 6, baseY + 4, baseZ + 2, SokobanMod.BlockUnbreakableSolids.blockID, 0); //tile.Unbreakable Solid Blocks
        LevelGenBase.setBlockAndMetadata(world, baseX + 6, baseY + 4, baseZ + 9, SokobanMod.BlockUnbreakableSolids.blockID, 0); //tile.Unbreakable Solid Blocks
        LevelGenBase.setBlockAndMetadata(world, baseX + 6, baseY + 4, baseZ + 11, SokobanMod.BlockUnbreakableSolids.blockID, 0); //tile.Unbreakable Solid Blocks
        LevelGenBase.setBlockAndMetadata(world, baseX + 6, baseY + 4, baseZ + 13, SokobanMod.BlockUnbreakableSolids.blockID, 0); //tile.Unbreakable Solid Blocks
        LevelGenBase.setBlockAndMetadata(world, baseX + 6, baseY + 5, baseZ + 0, SokobanMod.BlockUnbreakableLamps.blockID, 0); //tile.Unbreakable Lamp Blocks
        LevelGenBase.setBlockAndMetadata(world, baseX + 6, baseY + 5, baseZ + 1, SokobanMod.BlockUnbreakableLamps.blockID, 0); //tile.Unbreakable Lamp Blocks
        LevelGenBase.setBlockAndMetadata(world, baseX + 6, baseY + 5, baseZ + 2, SokobanMod.BlockUnbreakableLamps.blockID, 0); //tile.Unbreakable Lamp Blocks
        LevelGenBase.setBlockAndMetadata(world, baseX + 6, baseY + 5, baseZ + 3, SokobanMod.BlockUnbreakableLamps.blockID, 0); //tile.Unbreakable Lamp Blocks
