package sokobanMod.common.gen.hard;

import net.minecraft.block.Block;
import net.minecraft.item.Item;
import net.minecraft.item.ItemStack;
import net.minecraft.tileentity.TileEntitySign;
import net.minecraft.util.WeightedRandomChestContent;
import net.minecraft.world.World;
import sokobanMod.common.SokobanMod;
import sokobanMod.common.TileEntityLootGenerator;
import sokobanMod.common.TileEntityTargetBox;
import sokobanMod.common.gen.ISokobanLevel;
import sokobanMod.common.gen.LevelGenBase;

/**
 * Sokoban Mod
 * @author MineMaarten, level designed by Emiiitje
 * www.minemaarten.com
 * @license Lesser GNU Public License v3 (http://www.gnu.org/licenses/lgpl.html)
 */

public class HardLevel1Gen implements ISokobanLevel{
    private static final int[] levelBounds = {19, 12, 15};
    private static final int[] entranceCoords = {10, 10, 15, 10, 11, 15, 11, 10, 15, 11, 11, 15, 16, 1, 15, 16, 2, 15, 16, 3, 15, 17, 1, 15, 17, 2, 15, 17, 3, 15, 0, 10, 5, 19, 10, 5, 0, 10, 6, 19, 10, 6, 0, 11, 5, 19, 11, 5, 0, 11, 6, 19, 11, 6};
    public static final ItemStack[] staticInventoryContents_5_6_12 = new ItemStack[]{new ItemStack(264, 2, 0), //
    new ItemStack(266, 1, 0), //
    new ItemStack(400, 1, 0), //
    new ItemStack(367, 4, 0), //
    new ItemStack(352, 4, 0)};
    public static final WeightedRandomChestContent[] randomInventoryContents_5_6_12;

    static {
        randomInventoryContents_5_6_12 = new WeightedRandomChestContent[16];
        for(int i = 0; i < 16; i++) {
            randomInventoryContents_5_6_12[i] = new WeightedRandomChestContent(Item.dyePowder.itemID, i, 5, 15, 10);
        }
    }

    @Override
    public int getLevelNumber(){
        return 3000;
    }

    @Override
    public int[] getLevelBounds(){
        return levelBounds;
    }

    @Override
    public int[] getEntranceCoords(){
        return entranceCoords;
    }

    @Override
    public String getLevelName(){
        return "Colours";
    }

    @Override
    public String getAuthorName(){
        return "Emiiitje";
    }

    @Override
    public boolean canGenerateOnSurface(){
        return true;
    }

    @Override
    public boolean canGenerateUnderground(){
        return true;
    }

    @Override
    public boolean generate(World world, ISokobanLevel.EnumGenerationMethod generationMethod, int baseX, int baseY, int baseZ){

        //base blocks
        LevelGenBase.setBlockAndMetadata(world, baseX + 0, baseY + 0, baseZ + 0, SokobanMod.BlockUnbreakableSolids.blockID, 0); //tile.Unbreakable Solid Blocks
        LevelGenBase.setBlockAndMetadata(world, baseX + 0, baseY + 0, baseZ + 1, SokobanMod.BlockUnbreakableSolids.blockID, 0); //tile.Unbreakable Solid Blocks
        LevelGenBase.setBlockAndMetadata(world, baseX + 0, baseY + 0, baseZ + 2, SokobanMod.BlockUnbreakableSolids.blockID, 0); //tile.Unbreakable Solid Blocks
        LevelGenBase.setBlockAndMetadata(world, baseX + 0, baseY + 0, baseZ + 3, SokobanMod.BlockUnbreakableSolids.blockID, 0); //tile.Unbreakable Solid Blocks
        LevelGenBase.setBlockAndMetadata(world, baseX + 0, baseY + 0, baseZ + 4, SokobanMod.BlockUnbreakableSolids.blockID, 0); //tile.Unbreakable Solid Blocks
        LevelGenBase.setBlockAndMetadata(world, baseX + 0, baseY + 0, baseZ + 5, SokobanMod.BlockUnbreakableSolids.blockID, 0); //tile.Unbreakable Solid Blocks
        LevelGenBase.setBlockAndMetadata(world, baseX + 0, baseY + 0, baseZ + 6, SokobanMod.BlockUnbreakableSolids.blockID, 0); //tile.Unbreakable Solid Blocks
        LevelGenBase.setBlockAndMetadata(world, baseX + 0, baseY + 0, baseZ + 7, SokobanMod.BlockUnbreakableSolids.blockID, 0); //tile.Unbreakable Solid Blocks
        LevelGenBase.setBlockAndMetadata(world, baseX + 0, baseY + 0, baseZ + 8, SokobanMod.BlockUnbreakableSolids.blockID, 0); //tile.Unbreakable Solid Blocks
        LevelGenBase.setBlockAndMetadata(world, baseX + 0, baseY + 0, baseZ + 9, SokobanMod.BlockUnbreakableSolids.blockID, 0); //tile.Unbreakable Solid Blocks
        LevelGenBase.setBlockAndMetadata(world, baseX + 0, baseY + 0, baseZ + 10, SokobanMod.BlockUnbreakableSolids.blockID, 0); //tile.Unbreakable Solid Blocks
        LevelGenBase.setBlockAndMetadata(world, baseX + 0, baseY + 0, baseZ + 11, SokobanMod.BlockUnbreakableSolids.blockID, 0); //tile.Unbreakable Solid Blocks
        LevelGenBase.setBlockAndMetadata(world, baseX + 0, baseY + 0, baseZ + 12, SokobanMod.BlockUnbreakableSolids.blockID, 0); //tile.Unbreakable Solid Blocks
        LevelGenBase.setBlockAndMetadata(world, baseX + 0, baseY + 0, baseZ + 13, SokobanMod.BlockUnbreakableSolids.blockID, 0); //tile.Unbreakable Solid Blocks
        LevelGenBase.setBlockAndMetadata(world, baseX + 0, baseY + 0, baseZ + 14, SokobanMod.BlockUnbreakableSolids.blockID, 0); //tile.Unbreakable Solid Blocks
        LevelGenBase.setBlockAndMetadata(world, baseX + 0, baseY + 0, baseZ + 15, SokobanMod.BlockUnbreakableSolids.blockID, 0); //tile.Unbreakable Solid Blocks
        LevelGenBase.setBlockAndMetadata(world, baseX + 0, baseY + 1, baseZ + 0, SokobanMod.BlockUnbreakableSolids.blockID, 0); //tile.Unbreakable Solid Blocks
        LevelGenBase.setBlockAndMetadata(world, baseX + 0, baseY + 1, baseZ + 1, SokobanMod.BlockUnbreakableSolids.blockID, 0); //tile.Unbreakable Solid Blocks
        LevelGenBase.setBlockAndMetadata(world, baseX + 0, baseY + 1, baseZ + 2, SokobanMod.BlockUnbreakableSolids.blockID, 0); //tile.Unbreakable Solid Blocks
        LevelGenBase.setBlockAndMetadata(world, baseX + 0, baseY + 1, baseZ + 3, SokobanMod.BlockUnbreakableSolids.blockID, 0); //tile.Unbreakable Solid Blocks
        LevelGenBase.setBlockAndMetadata(world, baseX + 0, baseY + 1, baseZ + 4, SokobanMod.BlockUnbreakableSolids.blockID, 0); //tile.Unbreakable Solid Blocks
        LevelGenBase.setBlockAndMetadata(world, baseX + 0, baseY + 1, baseZ + 5, SokobanMod.BlockUnbreakableSolids.blockID, 0); //tile.Unbreakable Solid Blocks
        LevelGenBase.setBlockAndMetadata(world, baseX + 0, baseY + 1, baseZ + 6, SokobanMod.BlockUnbreakableSolids.blockID, 0); //tile.Unbreakable Solid Blocks
        LevelGenBase.setBlockAndMetadata(world, baseX + 0, baseY + 1, baseZ + 7, SokobanMod.BlockUnbreakableSolids.blockID, 0); //tile.Unbreakable Solid Blocks
        LevelGenBase.setBlockAndMetadata(world, baseX + 0, baseY + 1, baseZ + 8, SokobanMod.BlockUnbreakableSolids.blockID, 0); //tile.Unbreakable Solid Blocks
        LevelGenBase.setBlockAndMetadata(world, baseX + 0, baseY + 1, baseZ + 9, SokobanMod.BlockUnbreakableSolids.blockID, 0); //tile.Unbreakable Solid Blocks
        LevelGenBase.setBlockAndMetadata(world, baseX + 0, baseY + 1, baseZ + 10, SokobanMod.BlockUnbreakableSolids.blockID, 0); //tile.Unbreakable Solid Blocks
        LevelGenBase.setBlockAndMetadata(world, baseX + 0, baseY + 1, baseZ + 11, SokobanMod.BlockUnbreakableSolids.blockID, 0); //tile.Unbreakable Solid Blocks
        LevelGenBase.setBlockAndMetadata(world, baseX + 0, baseY + 1, baseZ + 12, SokobanMod.BlockUnbreakableSolids.blockID, 0); //tile.Unbreakable Solid Blocks
        LevelGenBase.setBlockAndMetadata(world, baseX + 0, baseY + 1, baseZ + 13, SokobanMod.BlockUnbreakableSolids.blockID, 0); //tile.Unbreakable Solid Blocks
        LevelGenBase.setBlockAndMetadata(world, baseX + 0, baseY + 1, baseZ + 14, SokobanMod.BlockUnbreakableSolids.blockID, 0); //tile.Unbreakable Solid Blocks
        LevelGenBase.setBlockAndMetadata(world, baseX + 0, baseY + 1, baseZ + 15, SokobanMod.BlockUnbreakableSolids.blockID, 0); //tile.Unbreakable Solid Blocks
        LevelGenBase.setBlockAndMetadata(world, baseX + 0, baseY + 2, baseZ + 0, SokobanMod.BlockUnbreakableSolids.blockID, 0); //tile.Unbreakable Solid Blocks
        LevelGenBase.setBlockAndMetadata(world, baseX + 0, baseY + 2, baseZ + 1, SokobanMod.BlockUnbreakableSolids.blockID, 0); //tile.Unbreakable Solid Blocks
        LevelGenBase.setBlockAndMetadata(world, baseX + 0, baseY + 2, baseZ + 2, SokobanMod.BlockUnbreakableSolids.blockID, 0); //tile.Unbreakable Solid Blocks
        LevelGenBase.setBlockAndMetadata(world, baseX + 0, baseY + 2, baseZ + 3, SokobanMod.BlockUnbreakableSolids.blockID, 0); //tile.Unbreakable Solid Blocks
        LevelGenBase.setBlockAndMetadata(world, baseX + 0, baseY + 2, baseZ + 4, SokobanMod.BlockUnbreakableSolids.blockID, 0); //tile.Unbreakable Solid Blocks
        LevelGenBase.setBlockAndMetadata(world, baseX + 0, baseY + 2, baseZ + 5, SokobanMod.BlockUnbreakableSolids.blockID, 0); //tile.Unbreakable Solid Blocks
        LevelGenBase.setBlockAndMetadata(world, baseX + 0, baseY + 2, baseZ + 6, SokobanMod.BlockUnbreakableSolids.blockID, 0); //tile.Unbreakable Solid Blocks
        LevelGenBase.setBlockAndMetadata(world, baseX + 0, baseY + 2, baseZ + 7, SokobanMod.BlockUnbreakableSolids.blockID, 0); //tile.Unbreakable Solid Blocks
        LevelGenBase.setBlockAndMetadata(world, baseX + 0, baseY + 2, baseZ + 8, SokobanMod.BlockUnbreakableSolids.blockID, 0); //tile.Unbreakable Solid Blocks
        LevelGenBase.setBlockAndMetadata(world, baseX + 0, baseY + 2, baseZ + 9, SokobanMod.BlockUnbreakableSolids.blockID, 0); //tile.Unbreakable Solid Blocks
        LevelGenBase.setBlockAndMetadata(world, baseX + 0, baseY + 2, baseZ + 10, SokobanMod.BlockUnbreakableSolids.blockID, 0); //tile.Unbreakable Solid Blocks
        LevelGenBase.setBlockAndMetadata(world, baseX + 0, baseY + 2, baseZ + 11, SokobanMod.BlockUnbreakableSolids.blockID, 0); //tile.Unbreakable Solid Blocks
        LevelGenBase.setBlockAndMetadata(world, baseX + 0, baseY + 2, baseZ + 12, SokobanMod.BlockUnbreakableSolids.blockID, 0); //tile.Unbreakable Solid Blocks
        LevelGenBase.setBlockAndMetadata(world, baseX + 0, baseY + 2, baseZ + 13, SokobanMod.BlockUnbreakableSolids.blockID, 0); //tile.Unbreakable Solid Blocks
        LevelGenBase.setBlockAndMetadata(world, baseX + 0, baseY + 2, baseZ + 14, SokobanMod.BlockUnbreakableSolids.blockID, 0); //tile.Unbreakable Solid Blocks
        LevelGenBase.setBlockAndMetadata(world, baseX + 0, baseY + 2, baseZ + 15, SokobanMod.BlockUnbreakableSolids.blockID, 0); //tile.Unbreakable Solid Blocks
        LevelGenBase.setBlockAndMetadata(world, baseX + 0, baseY + 3, baseZ + 0, SokobanMod.BlockUnbreakableSolids.blockID, 0); //tile.Unbreakable Solid Blocks
        LevelGenBase.setBlockAndMetadata(world, baseX + 0, baseY + 3, baseZ + 1, SokobanMod.BlockUnbreakableSolids.blockID, 0); //tile.Unbreakable Solid Blocks
        LevelGenBase.setBlockAndMetadata(world, baseX + 0, baseY + 3, baseZ + 2, SokobanMod.BlockUnbreakableSolids.blockID, 0); //tile.Unbreakable Solid Blocks
        LevelGenBase.setBlockAndMetadata(world, baseX + 0, baseY + 3, baseZ + 3, SokobanMod.BlockUnbreakableSolids.blockID, 0); //tile.Unbreakable Solid Blocks
        LevelGenBase.setBlockAndMetadata(world, baseX + 0, baseY + 3, baseZ + 4, SokobanMod.BlockUnbreakableSolids.blockID, 0); //tile.Unbreakable Solid Blocks
        LevelGenBase.setBlockAndMetadata(world, baseX + 0, baseY + 3, baseZ + 5, SokobanMod.BlockUnbreakableSolids.blockID, 0); //tile.Unbreakable Solid Blocks
        LevelGenBase.setBlockAndMetadata(world, baseX + 0, baseY + 3, baseZ + 6, SokobanMod.BlockUnbreakableSolids.blockID, 0); //tile.Unbreakable Solid Blocks
        LevelGenBase.setBlockAndMetadata(world, baseX + 0, baseY + 3, baseZ + 7, SokobanMod.BlockUnbreakableSolids.blockID, 0); //tile.Unbreakable Solid Blocks
        LevelGenBase.setBlockAndMetadata(world, baseX + 0, baseY + 3, baseZ + 8, SokobanMod.BlockUnbreakableSolids.blockID, 0); //tile.Unbreakable Solid Blocks
        LevelGenBase.setBlockAndMetadata(world, baseX + 0, baseY + 3, baseZ + 9, SokobanMod.BlockUnbreakableSolids.blockID, 0); //tile.Unbreakable Solid Blocks
        LevelGenBase.setBlockAndMetadata(world, baseX + 0, baseY + 3, baseZ + 10, SokobanMod.BlockUnbreakableSolids.blockID, 0); //tile.Unbreakable Solid Blocks
        LevelGenBase.setBlockAndMetadata(world, baseX + 0, baseY + 3, baseZ + 11, SokobanMod.BlockUnbreakableSolids.blockID, 0); //tile.Unbreakable Solid Blocks
        LevelGenBase.setBlockAndMetadata(world, baseX + 0, baseY + 3, baseZ + 12, SokobanMod.BlockUnbreakableSolids.blockID, 0); //tile.Unbreakable Solid Blocks
        LevelGenBase.setBlockAndMetadata(world, baseX + 0, baseY + 3, baseZ + 13, SokobanMod.BlockUnbreakableSolids.blockID, 0); //tile.Unbreakable Solid Blocks
        LevelGenBase.setBlockAndMetadata(world, baseX + 0, baseY + 3, baseZ + 14, SokobanMod.BlockUnbreakableSolids.blockID, 0); //tile.Unbreakable Solid Blocks
        LevelGenBase.setBlockAndMetadata(world, baseX + 0, baseY + 3, baseZ + 15, SokobanMod.BlockUnbreakableSolids.blockID, 0); //tile.Unbreakable Solid Blocks
        LevelGenBase.setBlockAndMetadata(world, baseX + 0, baseY + 4, baseZ + 0, SokobanMod.BlockUnbreakableSolids.blockID, 0); //tile.Unbreakable Solid Blocks
        LevelGenBase.setBlockAndMetadata(world, baseX + 0, baseY + 4, baseZ + 1, SokobanMod.BlockUnbreakableSolids.blockID, 0); //tile.Unbreakable Solid Blocks
        LevelGenBase.setBlockAndMetadata(world, baseX + 0, baseY + 4, baseZ + 2, SokobanMod.BlockUnbreakableSolids.blockID, 0); //tile.Unbreakable Solid Blocks
        LevelGenBase.setBlockAndMetadata(world, baseX + 0, baseY + 4, baseZ + 3, SokobanMod.BlockUnbreakableSolids.blockID, 0); //tile.Unbreakable Solid Blocks
        LevelGenBase.setBlockAndMetadata(world, baseX + 0, baseY + 4, baseZ + 4, SokobanMod.BlockUnbreakableSolids.blockID, 0); //tile.Unbreakable Solid Blocks
        LevelGenBase.setBlockAndMetadata(world, baseX + 0, baseY + 4, baseZ + 5, SokobanMod.BlockUnbreakableSolids.blockID, 0); //tile.Unbreakable Solid Blocks
        LevelGenBase.setBlockAndMetadata(world, baseX + 0, baseY + 4, baseZ + 6, SokobanMod.BlockUnbreakableSolids.blockID, 0); //tile.Unbreakable Solid Blocks
        LevelGenBase.setBlockAndMetadata(world, baseX + 0, baseY + 4, baseZ + 7, SokobanMod.BlockUnbreakableSolids.blockID, 0); //tile.Unbreakable Solid Blocks
        LevelGenBase.setBlockAndMetadata(world, baseX + 0, baseY + 4, baseZ + 8, SokobanMod.BlockUnbreakableSolids.blockID, 0); //tile.Unbreakable Solid Blocks
        LevelGenBase.setBlockAndMetadata(world, baseX + 0, baseY + 4, baseZ + 9, SokobanMod.BlockUnbreakableSolids.blockID, 0); //tile.Unbreakable Solid Blocks
        LevelGenBase.setBlockAndMetadata(world, baseX + 0, baseY + 4, baseZ + 10, SokobanMod.BlockUnbreakableSolids.blockID, 0); //tile.Unbreakable Solid Blocks
        LevelGenBase.setBlockAndMetadata(world, baseX + 0, baseY + 4, baseZ + 11, SokobanMod.BlockUnbreakableSolids.blockID, 0); //tile.Unbreakable Solid Blocks
        LevelGenBase.setBlockAndMetadata(world, baseX + 0, baseY + 4, baseZ + 12, SokobanMod.BlockUnbreakableSolids.blockID, 0); //tile.Unbreakable Solid Blocks
        LevelGenBase.setBlockAndMetadata(world, baseX + 0, baseY + 4, baseZ + 13, SokobanMod.BlockUnbreakableSolids.blockID, 0); //tile.Unbreakable Solid Blocks
        LevelGenBase.setBlockAndMetadata(world, baseX + 0, baseY + 4, baseZ + 14, SokobanMod.BlockUnbreakableSolids.blockID, 0); //tile.Unbreakable Solid Blocks
        LevelGenBase.setBlockAndMetadata(world, baseX + 0, baseY + 4, baseZ + 15, SokobanMod.BlockUnbreakableSolids.blockID, 0); //tile.Unbreakable Solid Blocks
        LevelGenBase.setBlockAndMetadata(world, baseX + 0, baseY + 5, baseZ + 0, SokobanMod.BlockUnbreakableSolids.blockID, 0); //tile.Unbreakable Solid Blocks
        LevelGenBase.setBlockAndMetadata(world, baseX + 0, baseY + 5, baseZ + 1, SokobanMod.BlockUnbreakableSolids.blockID, 0); //tile.Unbreakable Solid Blocks
        LevelGenBase.setBlockAndMetadata(world, baseX + 0, baseY + 5, baseZ + 2, SokobanMod.BlockUnbreakableSolids.blockID, 0); //tile.Unbreakable Solid Blocks
        LevelGenBase.setBlockAndMetadata(world, baseX + 0, baseY + 5, baseZ + 3, SokobanMod.BlockUnbreakableSolids.blockID, 0); //tile.Unbreakable Solid Blocks
        LevelGenBase.setBlockAndMetadata(world, baseX + 0, baseY + 5, baseZ + 4, SokobanMod.BlockUnbreakableSolids.blockID, 0); //tile.Unbreakable Solid Blocks
        LevelGenBase.setBlockAndMetadata(world, baseX + 0, baseY + 5, baseZ + 5, SokobanMod.BlockUnbreakableSolids.blockID, 0); //tile.Unbreakable Solid Blocks
        LevelGenBase.setBlockAndMetadata(world, baseX + 0, baseY + 5, baseZ + 6, SokobanMod.BlockUnbreakableSolids.blockID, 0); //tile.Unbreakable Solid Blocks
        LevelGenBase.setBlockAndMetadata(world, baseX + 0, baseY + 5, baseZ + 7, SokobanMod.BlockUnbreakableSolids.blockID, 0); //tile.Unbreakable Solid Blocks
        LevelGenBase.setBlockAndMetadata(world, baseX + 0, baseY + 5, baseZ + 8, SokobanMod.BlockUnbreakableSolids.blockID, 0); //tile.Unbreakable Solid Blocks
        LevelGenBase.setBlockAndMetadata(world, baseX + 0, baseY + 5, baseZ + 9, SokobanMod.BlockUnbreakableSolids.blockID, 0); //tile.Unbreakable Solid Blocks
        LevelGenBase.setBlockAndMetadata(world, baseX + 0, baseY + 5, baseZ + 10, SokobanMod.BlockUnbreakableSolids.blockID, 0); //tile.Unbreakable Solid Blocks
        LevelGenBase.setBlockAndMetadata(world, baseX + 0, baseY + 5, baseZ + 11, SokobanMod.BlockUnbreakableSolids.blockID, 0); //tile.Unbreakable Solid Blocks
        LevelGenBase.setBlockAndMetadata(world, baseX + 0, baseY + 5, baseZ + 12, SokobanMod.BlockUnbreakableSolids.blockID, 0); //tile.Unbreakable Solid Blocks
        LevelGenBase.setBlockAndMetadata(world, baseX + 0, baseY + 5, baseZ + 13, SokobanMod.BlockUnbreakableSolids.blockID, 0); //tile.Unbreakable Solid Blocks
        LevelGenBase.setBlockAndMetadata(world, baseX + 0, baseY + 5, baseZ + 14, SokobanMod.BlockUnbreakableSolids.blockID, 0); //tile.Unbreakable Solid Blocks
        LevelGenBase.setBlockAndMetadata(world, baseX + 0, baseY + 5, baseZ + 15, SokobanMod.BlockUnbreakableSolids.blockID, 0); //tile.Unbreakable Solid Blocks
        LevelGenBase.setBlockAndMetadata(world, baseX + 0, baseY + 6, baseZ + 0, SokobanMod.BlockUnbreakableSolids.blockID, 0); //tile.Unbreakable Solid Blocks
        LevelGenBase.setBlockAndMetadata(world, baseX + 0, baseY + 6, baseZ + 1, SokobanMod.BlockUnbreakableSolids.blockID, 0); //tile.Unbreakable Solid Blocks
        LevelGenBase.setBlockAndMetadata(world, baseX + 0, baseY + 6, baseZ + 2, SokobanMod.BlockUnbreakableSolids.blockID, 0); //tile.Unbreakable Solid Blocks
        LevelGenBase.setBlockAndMetadata(world, baseX + 0, baseY + 6, baseZ + 3, SokobanMod.BlockUnbreakableSolids.blockID, 0); //tile.Unbreakable Solid Blocks
        LevelGenBase.setBlockAndMetadata(world, baseX + 0, baseY + 6, baseZ + 4, SokobanMod.BlockUnbreakableSolids.blockID, 0); //tile.Unbreakable Solid Blocks
        LevelGenBase.setBlockAndMetadata(world, baseX + 0, baseY + 6, baseZ + 5, SokobanMod.BlockUnbreakableSolids.blockID, 0); //tile.Unbreakable Solid Blocks
        LevelGenBase.setBlockAndMetadata(world, baseX + 0, baseY + 6, baseZ + 6, SokobanMod.BlockUnbreakableSolids.blockID, 0); //tile.Unbreakable Solid Blocks
        LevelGenBase.setBlockAndMetadata(world, baseX + 0, baseY + 6, baseZ + 7, SokobanMod.BlockUnbreakableSolids.blockID, 0); //tile.Unbreakable Solid Blocks
        LevelGenBase.setBlockAndMetadata(world, baseX + 0, baseY + 6, baseZ + 8, SokobanMod.BlockUnbreakableSolids.blockID, 0); //tile.Unbreakable Solid Blocks
        LevelGenBase.setBlockAndMetadata(world, baseX + 0, baseY + 6, baseZ + 9, SokobanMod.BlockUnbreakableSolids.blockID, 0); //tile.Unbreakable Solid Blocks
        LevelGenBase.setBlockAndMetadata(world, baseX + 0, baseY + 6, baseZ + 10, SokobanMod.BlockUnbreakableSolids.blockID, 0); //tile.Unbreakable Solid Blocks
        LevelGenBase.setBlockAndMetadata(world, baseX + 0, baseY + 6, baseZ + 11, SokobanMod.BlockUnbreakableSolids.blockID, 0); //tile.Unbreakable Solid Blocks
        LevelGenBase.setBlockAndMetadata(world, baseX + 0, baseY + 6, baseZ + 12, SokobanMod.BlockUnbreakableSolids.blockID, 0); //tile.Unbreakable Solid Blocks
        LevelGenBase.setBlockAndMetadata(world, baseX + 0, baseY + 6, baseZ + 13, SokobanMod.BlockUnbreakableSolids.blockID, 0); //tile.Unbreakable Solid Blocks
        LevelGenBase.setBlockAndMetadata(world, baseX + 0, baseY + 6, baseZ + 14, SokobanMod.BlockUnbreakableSolids.blockID, 0); //tile.Unbreakable Solid Blocks
        LevelGenBase.setBlockAndMetadata(world, baseX + 0, baseY + 6, baseZ + 15, SokobanMod.BlockUnbreakableSolids.blockID, 0); //tile.Unbreakable Solid Blocks
        LevelGenBase.setBlockAndMetadata(world, baseX + 0, baseY + 7, baseZ + 0, SokobanMod.BlockUnbreakableSolids.blockID, 0); //tile.Unbreakable Solid Blocks
        LevelGenBase.setBlockAndMetadata(world, baseX + 0, baseY + 7, baseZ + 1, SokobanMod.BlockUnbreakableSolids.blockID, 0); //tile.Unbreakable Solid Blocks
        LevelGenBase.setBlockAndMetadata(world, baseX + 0, baseY + 7, baseZ + 2, SokobanMod.BlockUnbreakableSolids.blockID, 0); //tile.Unbreakable Solid Blocks
        LevelGenBase.setBlockAndMetadata(world, baseX + 0, baseY + 7, baseZ + 3, SokobanMod.BlockUnbreakableSolids.blockID, 0); //tile.Unbreakable Solid Blocks
        LevelGenBase.setBlockAndMetadata(world, baseX + 0, baseY + 7, baseZ + 4, SokobanMod.BlockUnbreakableSolids.blockID, 0); //tile.Unbreakable Solid Blocks
        LevelGenBase.setBlockAndMetadata(world, baseX + 0, baseY + 7, baseZ + 5, SokobanMod.BlockUnbreakableSolids.blockID, 0); //tile.Unbreakable Solid Blocks
        LevelGenBase.setBlockAndMetadata(world, baseX + 0, baseY + 7, baseZ + 6, SokobanMod.BlockUnbreakableSolids.blockID, 0); //tile.Unbreakable Solid Blocks
        LevelGenBase.setBlockAndMetadata(world, baseX + 0, baseY + 7, baseZ + 7, SokobanMod.BlockUnbreakableSolids.blockID, 0); //tile.Unbreakable Solid Blocks
        LevelGenBase.setBlockAndMetadata(world, baseX + 0, baseY + 7, baseZ + 8, SokobanMod.BlockUnbreakableSolids.blockID, 0); //tile.Unbreakable Solid Blocks
        LevelGenBase.setBlockAndMetadata(world, baseX + 0, baseY + 7, baseZ + 9, SokobanMod.BlockUnbreakableSolids.blockID, 0); //tile.Unbreakable Solid Blocks
        LevelGenBase.setBlockAndMetadata(world, baseX + 0, baseY + 7, baseZ + 10, SokobanMod.BlockUnbreakableSolids.blockID, 0); //tile.Unbreakable Solid Blocks
        LevelGenBase.setBlockAndMetadata(world, baseX + 0, baseY + 7, baseZ + 11, SokobanMod.BlockUnbreakableSolids.blockID, 0); //tile.Unbreakable Solid Blocks
        LevelGenBase.setBlockAndMetadata(world, baseX + 0, baseY + 7, baseZ + 12, SokobanMod.BlockUnbreakableSolids.blockID, 0); //tile.Unbreakable Solid Blocks
        LevelGenBase.setBlockAndMetadata(world, baseX + 0, baseY + 7, baseZ + 13, SokobanMod.BlockUnbreakableSolids.blockID, 0); //tile.Unbreakable Solid Blocks
        LevelGenBase.setBlockAndMetadata(world, baseX + 0, baseY + 7, baseZ + 14, SokobanMod.BlockUnbreakableSolids.blockID, 0); //tile.Unbreakable Solid Blocks
        LevelGenBase.setBlockAndMetadata(world, baseX + 0, baseY + 7, baseZ + 15, SokobanMod.BlockUnbreakableSolids.blockID, 0); //tile.Unbreakable Solid Blocks
        LevelGenBase.setBlockAndMetadata(world, baseX + 0, baseY + 8, baseZ + 0, SokobanMod.BlockUnbreakableSolids.blockID, 0); //tile.Unbreakable Solid Blocks
        LevelGenBase.setBlockAndMetadata(world, baseX + 0, baseY + 8, baseZ + 1, SokobanMod.BlockUnbreakableSolids.blockID, 0); //tile.Unbreakable Solid Blocks
        LevelGenBase.setBlockAndMetadata(world, baseX + 0, baseY + 8, baseZ + 2, SokobanMod.BlockUnbreakableSolids.blockID, 0); //tile.Unbreakable Solid Blocks
        LevelGenBase.setBlockAndMetadata(world, baseX + 0, baseY + 8, baseZ + 3, SokobanMod.BlockUnbreakableSolids.blockID, 0); //tile.Unbreakable Solid Blocks
        LevelGenBase.setBlockAndMetadata(world, baseX + 0, baseY + 8, baseZ + 4, SokobanMod.BlockUnbreakableSolids.blockID, 0); //tile.Unbreakable Solid Blocks
        LevelGenBase.setBlockAndMetadata(world, baseX + 0, baseY + 8, baseZ + 5, SokobanMod.BlockUnbreakableSolids.blockID, 0); //tile.Unbreakable Solid Blocks
        LevelGenBase.setBlockAndMetadata(world, baseX + 0, baseY + 8, baseZ + 6, SokobanMod.BlockUnbreakableSolids.blockID, 0); //tile.Unbreakable Solid Blocks
        LevelGenBase.setBlockAndMetadata(world, baseX + 0, baseY + 8, baseZ + 7, SokobanMod.BlockUnbreakableSolids.blockID, 0); //tile.Unbreakable Solid Blocks
        LevelGenBase.setBlockAndMetadata(world, baseX + 0, baseY + 8, baseZ + 8, SokobanMod.BlockUnbreakableSolids.blockID, 0); //tile.Unbreakable Solid Blocks
        LevelGenBase.setBlockAndMetadata(world, baseX + 0, baseY + 8, baseZ + 9, SokobanMod.BlockUnbreakableSolids.blockID, 0); //tile.Unbreakable Solid Blocks
        LevelGenBase.setBlockAndMetadata(world, baseX + 0, baseY + 8, baseZ + 10, SokobanMod.BlockUnbreakableSolids.blockID, 0); //tile.Unbreakable Solid Blocks
        LevelGenBase.setBlockAndMetadata(world, baseX + 0, baseY + 8, baseZ + 11, SokobanMod.BlockUnbreakableSolids.blockID, 0); //tile.Unbreakable Solid Blocks
        LevelGenBase.setBlockAndMetadata(world, baseX + 0, baseY + 8, baseZ + 12, SokobanMod.BlockUnbreakableSolids.blockID, 0); //tile.Unbreakable Solid Blocks
        LevelGenBase.setBlockAndMetadata(world, baseX + 0, baseY + 8, baseZ + 13, SokobanMod.BlockUnbreakableSolids.blockID, 0); //tile.Unbreakable Solid Blocks
        LevelGenBase.setBlockAndMetadata(world, baseX + 0, baseY + 8, baseZ + 14, SokobanMod.BlockUnbreakableSolids.blockID, 0); //tile.Unbreakable Solid Blocks
        LevelGenBase.setBlockAndMetadata(world, baseX + 0, baseY + 8, baseZ + 15, SokobanMod.BlockUnbreakableSolids.blockID, 0); //tile.Unbreakable Solid Blocks
        LevelGenBase.setBlockAndMetadata(world, baseX + 0, baseY + 9, baseZ + 0, SokobanMod.BlockUnbreakableSolids.blockID, 0); //tile.Unbreakable Solid Blocks
        LevelGenBase.setBlockAndMetadata(world, baseX + 0, baseY + 9, baseZ + 1, SokobanMod.BlockUnbreakableSolids.blockID, 0); //tile.Unbreakable Solid Blocks
        LevelGenBase.setBlockAndMetadata(world, baseX + 0, baseY + 9, baseZ + 2, SokobanMod.BlockUnbreakableSolids.blockID, 0); //tile.Unbreakable Solid Blocks
        LevelGenBase.setBlockAndMetadata(world, baseX + 0, baseY + 9, baseZ + 3, SokobanMod.BlockUnbreakableSolids.blockID, 0); //tile.Unbreakable Solid Blocks
        LevelGenBase.setBlockAndMetadata(world, baseX + 0, baseY + 9, baseZ + 4, SokobanMod.BlockUnbreakableSolids.blockID, 0); //tile.Unbreakable Solid Blocks
        LevelGenBase.setBlockAndMetadata(world, baseX + 0, baseY + 9, baseZ + 5, SokobanMod.BlockUnbreakableSolids.blockID, 0); //tile.Unbreakable Solid Blocks
        LevelGenBase.setBlockAndMetadata(world, baseX + 0, baseY + 9, baseZ + 6, SokobanMod.BlockUnbreakableSolids.blockID, 0); //tile.Unbreakable Solid Blocks
        LevelGenBase.setBlockAndMetadata(world, baseX + 0, baseY + 9, baseZ + 7, SokobanMod.BlockUnbreakableSolids.blockID, 0); //tile.Unbreakable Solid Blocks
        LevelGenBase.setBlockAndMetadata(world, baseX + 0, baseY + 9, baseZ + 8, SokobanMod.BlockUnbreakableSolids.blockID, 0); //tile.Unbreakable Solid Blocks
        LevelGenBase.setBlockAndMetadata(world, baseX + 0, baseY + 9, baseZ + 9, SokobanMod.BlockUnbreakableSolids.blockID, 0); //tile.Unbreakable Solid Blocks
        LevelGenBase.setBlockAndMetadata(world, baseX + 0, baseY + 9, baseZ + 10, SokobanMod.BlockUnbreakableSolids.blockID, 0); //tile.Unbreakable Solid Blocks
        LevelGenBase.setBlockAndMetadata(world, baseX + 0, baseY + 9, baseZ + 11, SokobanMod.BlockUnbreakableSolids.blockID, 0); //tile.Unbreakable Solid Blocks
        LevelGenBase.setBlockAndMetadata(world, baseX + 0, baseY + 9, baseZ + 12, SokobanMod.BlockUnbreakableSolids.blockID, 0); //tile.Unbreakable Solid Blocks
        LevelGenBase.setBlockAndMetadata(world, baseX + 0, baseY + 9, baseZ + 13, SokobanMod.BlockUnbreakableSolids.blockID, 0); //tile.Unbreakable Solid Blocks
        LevelGenBase.setBlockAndMetadata(world, baseX + 0, baseY + 9, baseZ + 14, SokobanMod.BlockUnbreakableSolids.blockID, 0); //tile.Unbreakable Solid Blocks
        LevelGenBase.setBlockAndMetadata(world, baseX + 0, baseY + 9, baseZ + 15, SokobanMod.BlockUnbreakableSolids.blockID, 0); //tile.Unbreakable Solid Blocks
        LevelGenBase.setBlockAndMetadata(world, baseX + 0, baseY + 10, baseZ + 0, SokobanMod.BlockUnbreakableSolids.blockID, 0); //tile.Unbreakable Solid Blocks
        LevelGenBase.setBlockAndMetadata(world, baseX + 0, baseY + 10, baseZ + 1, SokobanMod.BlockUnbreakableSolids.blockID, 0); //tile.Unbreakable Solid Blocks
        LevelGenBase.setBlockAndMetadata(world, baseX + 0, baseY + 10, baseZ + 2, SokobanMod.BlockUnbreakableSolids.blockID, 0); //tile.Unbreakable Solid Blocks
        LevelGenBase.setBlockAndMetadata(world, baseX + 0, baseY + 10, baseZ + 3, SokobanMod.BlockUnbreakableSolids.blockID, 0); //tile.Unbreakable Solid Blocks
        LevelGenBase.setBlockAndMetadata(world, baseX + 0, baseY + 10, baseZ + 4, SokobanMod.BlockUnbreakableSolids.blockID, 0); //tile.Unbreakable Solid Blocks
        LevelGenBase.setBlockAndMetadata(world, baseX + 0, baseY + 10, baseZ + 7, SokobanMod.BlockUnbreakableSolids.blockID, 0); //tile.Unbreakable Solid Blocks
        LevelGenBase.setBlockAndMetadata(world, baseX + 0, baseY + 10, baseZ + 8, SokobanMod.BlockUnbreakableSolids.blockID, 0); //tile.Unbreakable Solid Blocks
        LevelGenBase.setBlockAndMetadata(world, baseX + 0, baseY + 10, baseZ + 9, SokobanMod.BlockUnbreakableSolids.blockID, 0); //tile.Unbreakable Solid Blocks
        LevelGenBase.setBlockAndMetadata(world, baseX + 0, baseY + 10, baseZ + 10, SokobanMod.BlockUnbreakableSolids.blockID, 0); //tile.Unbreakable Solid Blocks
        LevelGenBase.setBlockAndMetadata(world, baseX + 0, baseY + 10, baseZ + 11, SokobanMod.BlockUnbreakableSolids.blockID, 0); //tile.Unbreakable Solid Blocks
        LevelGenBase.setBlockAndMetadata(world, baseX + 0, baseY + 10, baseZ + 12, SokobanMod.BlockUnbreakableSolids.blockID, 0); //tile.Unbreakable Solid Blocks
        LevelGenBase.setBlockAndMetadata(world, baseX + 0, baseY + 10, baseZ + 13, SokobanMod.BlockUnbreakableSolids.blockID, 0); //tile.Unbreakable Solid Blocks
        LevelGenBase.setBlockAndMetadata(world, baseX + 0, baseY + 10, baseZ + 14, SokobanMod.BlockUnbreakableSolids.blockID, 0); //tile.Unbreakable Solid Blocks
        LevelGenBase.setBlockAndMetadata(world, baseX + 0, baseY + 10, baseZ + 15, SokobanMod.BlockUnbreakableSolids.blockID, 0); //tile.Unbreakable Solid Blocks
        LevelGenBase.setBlockAndMetadata(world, baseX + 0, baseY + 11, baseZ + 0, SokobanMod.BlockUnbreakableSolids.blockID, 0); //tile.Unbreakable Solid Blocks
        LevelGenBase.setBlockAndMetadata(world, baseX + 0, baseY + 11, baseZ + 1, SokobanMod.BlockUnbreakableSolids.blockID, 0); //tile.Unbreakable Solid Blocks
        LevelGenBase.setBlockAndMetadata(world, baseX + 0, baseY + 11, baseZ + 2, SokobanMod.BlockUnbreakableSolids.blockID, 0); //tile.Unbreakable Solid Blocks
        LevelGenBase.setBlockAndMetadata(world, baseX + 0, baseY + 11, baseZ + 3, SokobanMod.BlockUnbreakableSolids.blockID, 0); //tile.Unbreakable Solid Blocks
        LevelGenBase.setBlockAndMetadata(world, baseX + 0, baseY + 11, baseZ + 4, SokobanMod.BlockUnbreakableSolids.blockID, 0); //tile.Unbreakable Solid Blocks
        LevelGenBase.setBlockAndMetadata(world, baseX + 0, baseY + 11, baseZ + 7, SokobanMod.BlockUnbreakableSolids.blockID, 0); //tile.Unbreakable Solid Blocks
        LevelGenBase.setBlockAndMetadata(world, baseX + 0, baseY + 11, baseZ + 8, SokobanMod.BlockUnbreakableSolids.blockID, 0); //tile.Unbreakable Solid Blocks
        LevelGenBase.setBlockAndMetadata(world, baseX + 0, baseY + 11, baseZ + 9, SokobanMod.BlockUnbreakableSolids.blockID, 0); //tile.Unbreakable Solid Blocks
        LevelGenBase.setBlockAndMetadata(world, baseX + 0, baseY + 11, baseZ + 10, SokobanMod.BlockUnbreakableSolids.blockID, 0); //tile.Unbreakable Solid Blocks
        LevelGenBase.setBlockAndMetadata(world, baseX + 0, baseY + 11, baseZ + 11, SokobanMod.BlockUnbreakableSolids.blockID, 0); //tile.Unbreakable Solid Blocks
        LevelGenBase.setBlockAndMetadata(world, baseX + 0, baseY + 11, baseZ + 12, SokobanMod.BlockUnbreakableSolids.blockID, 0); //tile.Unbreakable Solid Blocks
        LevelGenBase.setBlockAndMetadata(world, baseX + 0, baseY + 11, baseZ + 13, SokobanMod.BlockUnbreakableSolids.blockID, 0); //tile.Unbreakable Solid Blocks
        LevelGenBase.setBlockAndMetadata(world, baseX + 0, baseY + 11, baseZ + 14, SokobanMod.BlockUnbreakableSolids.blockID, 0); //tile.Unbreakable Solid Blocks
        LevelGenBase.setBlockAndMetadata(world, baseX + 0, baseY + 11, baseZ + 15, SokobanMod.BlockUnbreakableSolids.blockID, 0); //tile.Unbreakable Solid Blocks
        LevelGenBase.setBlockAndMetadata(world, baseX + 0, baseY + 12, baseZ + 0, SokobanMod.BlockUnbreakableSolids.blockID, 0); //tile.Unbreakable Solid Blocks
        LevelGenBase.setBlockAndMetadata(world, baseX + 0, baseY + 12, baseZ + 1, SokobanMod.BlockUnbreakableSolids.blockID, 0); //tile.Unbreakable Solid Blocks
        LevelGenBase.setBlockAndMetadata(world, baseX + 0, baseY + 12, baseZ + 2, SokobanMod.BlockUnbreakableSolids.blockID, 0); //tile.Unbreakable Solid Blocks
        LevelGenBase.setBlockAndMetadata(world, baseX + 0, baseY + 12, baseZ + 3, SokobanMod.BlockUnbreakableSolids.blockID, 0); //tile.Unbreakable Solid Blocks
        LevelGenBase.setBlockAndMetadata(world, baseX + 0, baseY + 12, baseZ + 4, SokobanMod.BlockUnbreakableSolids.blockID, 0); //tile.Unbreakable Solid Blocks
        LevelGenBase.setBlockAndMetadata(world, baseX + 0, baseY + 12, baseZ + 5, SokobanMod.BlockUnbreakableSolids.blockID, 0); //tile.Unbreakable Solid Blocks
        LevelGenBase.setBlockAndMetadata(world, baseX + 0, baseY + 12, baseZ + 6, SokobanMod.BlockUnbreakableSolids.blockID, 0); //tile.Unbreakable Solid Blocks
        LevelGenBase.setBlockAndMetadata(world, baseX + 0, baseY + 12, baseZ + 7, SokobanMod.BlockUnbreakableSolids.blockID, 0); //tile.Unbreakable Solid Blocks
        LevelGenBase.setBlockAndMetadata(world, baseX + 0, baseY + 12, baseZ + 8, SokobanMod.BlockUnbreakableSolids.blockID, 0); //tile.Unbreakable Solid Blocks
        LevelGenBase.setBlockAndMetadata(world, baseX + 0, baseY + 12, baseZ + 9, SokobanMod.BlockUnbreakableSolids.blockID, 0); //tile.Unbreakable Solid Blocks
        LevelGenBase.setBlockAndMetadata(world, baseX + 0, baseY + 12, baseZ + 10, SokobanMod.BlockUnbreakableSolids.blockID, 0); //tile.Unbreakable Solid Blocks
        LevelGenBase.setBlockAndMetadata(world, baseX + 0, baseY + 12, baseZ + 11, SokobanMod.BlockUnbreakableSolids.blockID, 0); //tile.Unbreakable Solid Blocks
        LevelGenBase.setBlockAndMetadata(world, baseX + 0, baseY + 12, baseZ + 12, SokobanMod.BlockUnbreakableSolids.blockID, 0); //tile.Unbreakable Solid Blocks
        LevelGenBase.setBlockAndMetadata(world, baseX + 0, baseY + 12, baseZ + 13, SokobanMod.BlockUnbreakableSolids.blockID, 0); //tile.Unbreakable Solid Blocks
        LevelGenBase.setBlockAndMetadata(world, baseX + 0, baseY + 12, baseZ + 14, SokobanMod.BlockUnbreakableSolids.blockID, 0); //tile.Unbreakable Solid Blocks
        LevelGenBase.setBlockAndMetadata(world, baseX + 0, baseY + 12, baseZ + 15, SokobanMod.BlockUnbreakableSolids.blockID, 0); //tile.Unbreakable Solid Blocks
        LevelGenBase.setBlockAndMetadata(world, baseX + 1, baseY + 0, baseZ + 0, SokobanMod.BlockUnbreakableSolids.blockID, 0); //tile.Unbreakable Solid Blocks
        LevelGenBase.setBlockAndMetadata(world, baseX + 1, baseY + 0, baseZ + 1, SokobanMod.BlockUnbreakableSolids.blockID, 0); //tile.Unbreakable Solid Blocks
        LevelGenBase.setBlockAndMetadata(world, baseX + 1, baseY + 0, baseZ + 2, SokobanMod.BlockUnbreakableSolids.blockID, 0); //tile.Unbreakable Solid Blocks
        LevelGenBase.setBlockAndMetadata(world, baseX + 1, baseY + 0, baseZ + 3, SokobanMod.BlockUnbreakableSolids.blockID, 0); //tile.Unbreakable Solid Blocks
        LevelGenBase.setBlockAndMetadata(world, baseX + 1, baseY + 0, baseZ + 4, SokobanMod.BlockUnbreakableSolids.blockID, 0); //tile.Unbreakable Solid Blocks
        LevelGenBase.setBlockAndMetadata(world, baseX + 1, baseY + 0, baseZ + 5, SokobanMod.BlockUnbreakableSolids.blockID, 0); //tile.Unbreakable Solid Blocks
        LevelGenBase.setBlockAndMetadata(world, baseX + 1, baseY + 0, baseZ + 6, SokobanMod.BlockUnbreakableSolids.blockID, 0); //tile.Unbreakable Solid Blocks
        LevelGenBase.setBlockAndMetadata(world, baseX + 1, baseY + 0, baseZ + 7, SokobanMod.BlockUnbreakableSolids.blockID, 0); //tile.Unbreakable Solid Blocks
        LevelGenBase.setBlockAndMetadata(world, baseX + 1, baseY + 0, baseZ + 8, SokobanMod.BlockUnbreakableSolids.blockID, 0); //tile.Unbreakable Solid Blocks
        LevelGenBase.setBlockAndMetadata(world, baseX + 1, baseY + 0, baseZ + 9, SokobanMod.BlockUnbreakableSolids.blockID, 0); //tile.Unbreakable Solid Blocks
        LevelGenBase.setBlockAndMetadata(world, baseX + 1, baseY + 0, baseZ + 10, SokobanMod.BlockUnbreakableSolids.blockID, 0); //tile.Unbreakable Solid Blocks
        LevelGenBase.setBlockAndMetadata(world, baseX + 1, baseY + 0, baseZ + 11, SokobanMod.BlockUnbreakableSolids.blockID, 0); //tile.Unbreakable Solid Blocks
        LevelGenBase.setBlockAndMetadata(world, baseX + 1, baseY + 0, baseZ + 12, SokobanMod.BlockUnbreakableSolids.blockID, 0); //tile.Unbreakable Solid Blocks
        LevelGenBase.setBlockAndMetadata(world, baseX + 1, baseY + 0, baseZ + 13, SokobanMod.BlockUnbreakableSolids.blockID, 0); //tile.Unbreakable Solid Blocks
        LevelGenBase.setBlockAndMetadata(world, baseX + 1, baseY + 0, baseZ + 14, SokobanMod.BlockUnbreakableSolids.blockID, 0); //tile.Unbreakable Solid Blocks
        LevelGenBase.setBlockAndMetadata(world, baseX + 1, baseY + 0, baseZ + 15, SokobanMod.BlockUnbreakableSolids.blockID, 0); //tile.Unbreakable Solid Blocks
        LevelGenBase.setBlockAndMetadata(world, baseX + 1, baseY + 1, baseZ + 0, SokobanMod.BlockUnbreakableSolids.blockID, 0); //tile.Unbreakable Solid Blocks
        LevelGenBase.setBlockAndMetadata(world, baseX + 1, baseY + 1, baseZ + 4, SokobanMod.BlockUnbreakableLamps.blockID, 7); //tile.Unbreakable Lamp Blocks
        LevelGenBase.setBlockAndMetadata(world, baseX + 1, baseY + 1, baseZ + 9, SokobanMod.BlockUnbreakableLamps.blockID, 7); //tile.Unbreakable Lamp Blocks
        LevelGenBase.setBlockAndMetadata(world, baseX + 1, baseY + 1, baseZ + 15, SokobanMod.BlockUnbreakableSolids.blockID, 0); //tile.Unbreakable Solid Blocks
        LevelGenBase.setBlockAndMetadata(world, baseX + 1, baseY + 2, baseZ + 0, SokobanMod.BlockUnbreakableSolids.blockID, 0); //tile.Unbreakable Solid Blocks
        LevelGenBase.setBlockAndMetadata(world, baseX + 1, baseY + 2, baseZ + 15, SokobanMod.BlockUnbreakableSolids.blockID, 0); //tile.Unbreakable Solid Blocks
        LevelGenBase.setBlockAndMetadata(world, baseX + 1, baseY + 3, baseZ + 0, SokobanMod.BlockUnbreakableSolids.blockID, 0); //tile.Unbreakable Solid Blocks
        LevelGenBase.setBlockAndMetadata(world, baseX + 1, baseY + 3, baseZ + 1, Block.bedrock.blockID, 0); //tile.bedrock
        LevelGenBase.setBlockAndMetadata(world, baseX + 1, baseY + 3, baseZ + 4, Block.bedrock.blockID, 0); //tile.bedrock
        LevelGenBase.setBlockAndMetadata(world, baseX + 1, baseY + 3, baseZ + 15, SokobanMod.BlockUnbreakableSolids.blockID, 0); //tile.Unbreakable Solid Blocks
        LevelGenBase.setBlockAndMetadata(world, baseX + 1, baseY + 4, baseZ + 0, SokobanMod.BlockUnbreakableSolids.blockID, 0); //tile.Unbreakable Solid Blocks
        LevelGenBase.setBlockAndMetadata(world, baseX + 1, baseY + 4, baseZ + 2, Block.bedrock.blockID, 0); //tile.bedrock
        LevelGenBase.setBlockAndMetadata(world, baseX + 1, baseY + 4, baseZ + 5, Block.bedrock.blockID, 0); //tile.bedrock
        LevelGenBase.setBlockAndMetadata(world, baseX + 1, baseY + 4, baseZ + 15, SokobanMod.BlockUnbreakableSolids.blockID, 0); //tile.Unbreakable Solid Blocks
        LevelGenBase.setBlockAndMetadata(world, baseX + 1, baseY + 5, baseZ + 0, SokobanMod.BlockUnbreakableSolids.blockID, 0); //tile.Unbreakable Solid Blocks
        LevelGenBase.setBlockAndMetadata(world, baseX + 1, baseY + 5, baseZ + 3, Block.bedrock.blockID, 0); //tile.bedrock
        LevelGenBase.setBlockAndMetadata(world, baseX + 1, baseY + 5, baseZ + 6, Block.bedrock.blockID, 0); //tile.bedrock
        LevelGenBase.setBlockAndMetadata(world, baseX + 1, baseY + 5, baseZ + 15, SokobanMod.BlockUnbreakableSolids.blockID, 0); //tile.Unbreakable Solid Blocks
        LevelGenBase.setBlockAndMetadata(world, baseX + 1, baseY + 6, baseZ + 0, SokobanMod.BlockUnbreakableSolids.blockID, 0); //tile.Unbreakable Solid Blocks
        LevelGenBase.setBlockAndMetadata(world, baseX + 1, baseY + 6, baseZ + 1, SokobanMod.BlockUnbreakableSolids.blockID, 0); //tile.Unbreakable Solid Blocks
        LevelGenBase.setBlockAndMetadata(world, baseX + 1, baseY + 6, baseZ + 2, SokobanMod.BlockUnbreakableSolids.blockID, 0); //tile.Unbreakable Solid Blocks
        LevelGenBase.setBlockAndMetadata(world, baseX + 1, baseY + 6, baseZ + 3, SokobanMod.BlockVaporizingBlock.blockID, 0); //tile.Vaporizing Block
        LevelGenBase.setBlockAndMetadata(world, baseX + 1, baseY + 6, baseZ + 4, SokobanMod.BlockUnbreakableSolids.blockID, 0); //tile.Unbreakable Solid Blocks
        LevelGenBase.setBlockAndMetadata(world, baseX + 1, baseY + 6, baseZ + 7, Block.bedrock.blockID, 0); //tile.bedrock
        LevelGenBase.setBlockAndMetadata(world, baseX + 1, baseY + 6, baseZ + 8, Block.bedrock.blockID, 0); //tile.bedrock
        LevelGenBase.setBlockAndMetadata(world, baseX + 1, baseY + 6, baseZ + 10, Block.bedrock.blockID, 0); //tile.bedrock
        LevelGenBase.setBlockAndMetadata(world, baseX + 1, baseY + 6, baseZ + 11, Block.bedrock.blockID, 0); //tile.bedrock
        LevelGenBase.setBlockAndMetadata(world, baseX + 1, baseY + 6, baseZ + 12, Block.bedrock.blockID, 0); //tile.bedrock
        LevelGenBase.setBlockAndMetadata(world, baseX + 1, baseY + 6, baseZ + 13, Block.bedrock.blockID, 0); //tile.bedrock
        LevelGenBase.setBlockAndMetadata(world, baseX + 1, baseY + 6, baseZ + 14, Block.bedrock.blockID, 0); //tile.bedrock
        LevelGenBase.setBlockAndMetadata(world, baseX + 1, baseY + 6, baseZ + 15, SokobanMod.BlockUnbreakableSolids.blockID, 0); //tile.Unbreakable Solid Blocks
        LevelGenBase.setBlockAndMetadata(world, baseX + 1, baseY + 7, baseZ + 0, SokobanMod.BlockUnbreakableSolids.blockID, 0); //tile.Unbreakable Solid Blocks
        LevelGenBase.setBlockAndMetadata(world, baseX + 1, baseY + 7, baseZ + 1, SokobanMod.BlockUnbreakableSolids.blockID, 0); //tile.Unbreakable Solid Blocks
        LevelGenBase.setBlockAndMetadata(world, baseX + 1, baseY + 7, baseZ + 2, SokobanMod.BlockUnbreakableSolids.blockID, 0); //tile.Unbreakable Solid Blocks
        LevelGenBase.setBlockAndMetadata(world, baseX + 1, baseY + 7, baseZ + 3, SokobanMod.BlockUnbreakableLamps.blockID, 7); //tile.Unbreakable Lamp Blocks
        LevelGenBase.setBlockAndMetadata(world, baseX + 1, baseY + 7, baseZ + 4, SokobanMod.BlockUnbreakableSolids.blockID, 0); //tile.Unbreakable Solid Blocks
        LevelGenBase.setBlockAndMetadata(world, baseX + 1, baseY + 7, baseZ + 9, Block.bedrock.blockID, 0); //tile.bedrock
        LevelGenBase.setBlockAndMetadata(world, baseX + 1, baseY + 7, baseZ + 15, SokobanMod.BlockUnbreakableSolids.blockID, 0); //tile.Unbreakable Solid Blocks
        LevelGenBase.setBlockAndMetadata(world, baseX + 1, baseY + 8, baseZ + 0, SokobanMod.BlockUnbreakableSolids.blockID, 0); //tile.Unbreakable Solid Blocks
        LevelGenBase.setBlockAndMetadata(world, baseX + 1, baseY + 8, baseZ + 1, SokobanMod.BlockUnbreakableSolids.blockID, 0); //tile.Unbreakable Solid Blocks
        LevelGenBase.setBlockAndMetadata(world, baseX + 1, baseY + 8, baseZ + 2, SokobanMod.BlockUnbreakableSolids.blockID, 0); //tile.Unbreakable Solid Blocks
        LevelGenBase.setBlockAndMetadata(world, baseX + 1, baseY + 8, baseZ + 3, SokobanMod.BlockUnbreakableSolids.blockID, 0); //tile.Unbreakable Solid Blocks
        LevelGenBase.setBlockAndMetadata(world, baseX + 1, baseY + 8, baseZ + 4, SokobanMod.BlockUnbreakableSolids.blockID, 0); //tile.Unbreakable Solid Blocks
        LevelGenBase.setBlockAndMetadata(world, baseX + 1, baseY + 8, baseZ + 8, Block.bedrock.blockID, 0); //tile.bedrock
        LevelGenBase.setBlockAndMetadata(world, baseX + 1, baseY + 8, baseZ + 15, SokobanMod.BlockUnbreakableSolids.blockID, 0); //tile.Unbreakable Solid Blocks
        LevelGenBase.setBlockAndMetadata(world, baseX + 1, baseY + 9, baseZ + 0, SokobanMod.BlockUnbreakableSolids.blockID, 0); //tile.Unbreakable Solid Blocks
        LevelGenBase.setBlockAndMetadata(world, baseX + 1, baseY + 9, baseZ + 1, SokobanMod.BlockUnbreakableSolids.blockID, 0); //tile.Unbreakable Solid Blocks
        LevelGenBase.setBlockAndMetadata(world, baseX + 1, baseY + 9, baseZ + 2, SokobanMod.BlockUnbreakableSolids.blockID, 0); //tile.Unbreakable Solid Blocks
        LevelGenBase.setBlockAndMetadata(world, baseX + 1, baseY + 9, baseZ + 3, SokobanMod.BlockUnbreakableSolids.blockID, 0); //tile.Unbreakable Solid Blocks
        LevelGenBase.setBlockAndMetadata(world, baseX + 1, baseY + 9, baseZ + 4, SokobanMod.BlockUnbreakableSolids.blockID, 0); //tile.Unbreakable Solid Blocks
        LevelGenBase.setBlockAndMetadata(world, baseX + 1, baseY + 9, baseZ + 5, SokobanMod.BlockUnbreakableSolids.blockID, 0); //tile.Unbreakable Solid Blocks
        LevelGenBase.setBlockAndMetadata(world, baseX + 1, baseY + 9, baseZ + 6, SokobanMod.BlockUnbreakableSolids.blockID, 0); //tile.Unbreakable Solid Blocks
        LevelGenBase.setBlockAndMetadata(world, baseX + 1, baseY + 9, baseZ + 7, Block.bedrock.blockID, 0); //tile.bedrock
        LevelGenBase.setBlockAndMetadata(world, baseX + 1, baseY + 9, baseZ + 15, SokobanMod.BlockUnbreakableSolids.blockID, 0); //tile.Unbreakable Solid Blocks
        LevelGenBase.setBlockAndMetadata(world, baseX + 1, baseY + 10, baseZ + 0, SokobanMod.BlockUnbreakableSolids.blockID, 0); //tile.Unbreakable Solid Blocks
        LevelGenBase.setBlockAndMetadata(world, baseX + 1, baseY + 10, baseZ + 4, SokobanMod.BlockUnbreakableSolids.blockID, 0); //tile.Unbreakable Solid Blocks
        LevelGenBase.setBlockAndMetadata(world, baseX + 1, baseY + 10, baseZ + 7, SokobanMod.BlockUnbreakableSolids.blockID, 0); //tile.Unbreakable Solid Blocks
        LevelGenBase.setBlockAndMetadata(world, baseX + 1, baseY + 10, baseZ + 15, SokobanMod.BlockUnbreakableSolids.blockID, 0); //tile.Unbreakable Solid Blocks
        LevelGenBase.setBlockAndMetadata(world, baseX + 1, baseY + 11, baseZ + 0, SokobanMod.BlockUnbreakableSolids.blockID, 0); //tile.Unbreakable Solid Blocks
        LevelGenBase.setBlockAndMetadata(world, baseX + 1, baseY + 11, baseZ + 4, SokobanMod.BlockUnbreakableLamps.blockID, 7); //tile.Unbreakable Lamp Blocks
        LevelGenBase.setBlockAndMetadata(world, baseX + 1, baseY + 11, baseZ + 7, SokobanMod.BlockUnbreakableLamps.blockID, 7); //tile.Unbreakable Lamp Blocks
        LevelGenBase.setBlockAndMetadata(world, baseX + 1, baseY + 11, baseZ + 15, SokobanMod.BlockUnbreakableSolids.blockID, 0); //tile.Unbreakable Solid Blocks
        LevelGenBase.setBlockAndMetadata(world, baseX + 1, baseY + 12, baseZ + 0, SokobanMod.BlockUnbreakableSolids.blockID, 0); //tile.Unbreakable Solid Blocks
        LevelGenBase.setBlockAndMetadata(world, baseX + 1, baseY + 12, baseZ + 1, SokobanMod.BlockUnbreakableSolids.blockID, 0); //tile.Unbreakable Solid Blocks
        LevelGenBase.setBlockAndMetadata(world, baseX + 1, baseY + 12, baseZ + 2, SokobanMod.BlockUnbreakableSolids.blockID, 0); //tile.Unbreakable Solid Blocks
        LevelGenBase.setBlockAndMetadata(world, baseX + 1, baseY + 12, baseZ + 3, SokobanMod.BlockUnbreakableSolids.blockID, 0); //tile.Unbreakable Solid Blocks
        LevelGenBase.setBlockAndMetadata(world, baseX + 1, baseY + 12, baseZ + 4, SokobanMod.BlockUnbreakableSolids.blockID, 0); //tile.Unbreakable Solid Blocks
        LevelGenBase.setBlockAndMetadata(world, baseX + 1, baseY + 12, baseZ + 5, SokobanMod.BlockUnbreakableSolids.blockID, 0); //tile.Unbreakable Solid Blocks
        LevelGenBase.setBlockAndMetadata(world, baseX + 1, baseY + 12, baseZ + 6, SokobanMod.BlockUnbreakableSolids.blockID, 0); //tile.Unbreakable Solid Blocks
        LevelGenBase.setBlockAndMetadata(world, baseX + 1, baseY + 12, baseZ + 7, SokobanMod.BlockUnbreakableSolids.blockID, 0); //tile.Unbreakable Solid Blocks
        LevelGenBase.setBlockAndMetadata(world, baseX + 1, baseY + 12, baseZ + 8, SokobanMod.BlockUnbreakableSolids.blockID, 0); //tile.Unbreakable Solid Blocks
        LevelGenBase.setBlockAndMetadata(world, baseX + 1, baseY + 12, baseZ + 9, SokobanMod.BlockUnbreakableSolids.blockID, 0); //tile.Unbreakable Solid Blocks
        LevelGenBase.setBlockAndMetadata(world, baseX + 1, baseY + 12, baseZ + 10, SokobanMod.BlockUnbreakableSolids.blockID, 0); //tile.Unbreakable Solid Blocks
        LevelGenBase.setBlockAndMetadata(world, baseX + 1, baseY + 12, baseZ + 11, SokobanMod.BlockUnbreakableSolids.blockID, 0); //tile.Unbreakable Solid Blocks
        LevelGenBase.setBlockAndMetadata(world, baseX + 1, baseY + 12, baseZ + 12, SokobanMod.BlockUnbreakableSolids.blockID, 0); //tile.Unbreakable Solid Blocks
        LevelGenBase.setBlockAndMetadata(world, baseX + 1, baseY + 12, baseZ + 13, SokobanMod.BlockUnbreakableSolids.blockID, 0); //tile.Unbreakable Solid Blocks
        LevelGenBase.setBlockAndMetadata(world, baseX + 1, baseY + 12, baseZ + 14, SokobanMod.BlockUnbreakableSolids.blockID, 0); //tile.Unbreakable Solid Blocks
        LevelGenBase.setBlockAndMetadata(world, baseX + 1, baseY + 12, baseZ + 15, SokobanMod.BlockUnbreakableSolids.blockID, 0); //tile.Unbreakable Solid Blocks
        LevelGenBase.setBlockAndMetadata(world, baseX + 2, baseY + 0, baseZ + 0, SokobanMod.BlockUnbreakableSolids.blockID, 0); //tile.Unbreakable Solid Blocks
        LevelGenBase.setBlockAndMetadata(world, baseX + 2, baseY + 0, baseZ + 1, SokobanMod.BlockUnbreakableSolids.blockID, 0); //tile.Unbreakable Solid Blocks
        LevelGenBase.setBlockAndMetadata(world, baseX + 2, baseY + 0, baseZ + 2, SokobanMod.BlockUnbreakableSolids.blockID, 0); //tile.Unbreakable Solid Blocks
        LevelGenBase.setBlockAndMetadata(world, baseX + 2, baseY + 0, baseZ + 3, SokobanMod.BlockUnbreakableSolids.blockID, 0); //tile.Unbreakable Solid Blocks
        LevelGenBase.setBlockAndMetadata(world, baseX + 2, baseY + 0, baseZ + 4, SokobanMod.BlockUnbreakableSolids.blockID, 0); //tile.Unbreakable Solid Blocks
        LevelGenBase.setBlockAndMetadata(world, baseX + 2, baseY + 0, baseZ + 5, SokobanMod.BlockUnbreakableSolids.blockID, 0); //tile.Unbreakable Solid Blocks
        LevelGenBase.setBlockAndMetadata(world, baseX + 2, baseY + 0, baseZ + 6, SokobanMod.BlockUnbreakableSolids.blockID, 0); //tile.Unbreakable Solid Blocks
        LevelGenBase.setBlockAndMetadata(world, baseX + 2, baseY + 0, baseZ + 7, SokobanMod.BlockUnbreakableSolids.blockID, 0); //tile.Unbreakable Solid Blocks
        LevelGenBase.setBlockAndMetadata(world, baseX + 2, baseY + 0, baseZ + 8, SokobanMod.BlockUnbreakableSolids.blockID, 0); //tile.Unbreakable Solid Blocks
        LevelGenBase.setBlockAndMetadata(world, baseX + 2, baseY + 0, baseZ + 9, SokobanMod.BlockUnbreakableSolids.blockID, 0); //tile.Unbreakable Solid Blocks
        LevelGenBase.setBlockAndMetadata(world, baseX + 2, baseY + 0, baseZ + 10, SokobanMod.BlockUnbreakableSolids.blockID, 0); //tile.Unbreakable Solid Blocks
        LevelGenBase.setBlockAndMetadata(world, baseX + 2, baseY + 0, baseZ + 11, SokobanMod.BlockUnbreakableSolids.blockID, 0); //tile.Unbreakable Solid Blocks
        LevelGenBase.setBlockAndMetadata(world, baseX + 2, baseY + 0, baseZ + 12, SokobanMod.BlockUnbreakableSolids.blockID, 0); //tile.Unbreakable Solid Blocks
        LevelGenBase.setBlockAndMetadata(world, baseX + 2, baseY + 0, baseZ + 13, SokobanMod.BlockUnbreakableSolids.blockID, 0); //tile.Unbreakable Solid Blocks
        LevelGenBase.setBlockAndMetadata(world, baseX + 2, baseY + 0, baseZ + 14, SokobanMod.BlockUnbreakableSolids.blockID, 0); //tile.Unbreakable Solid Blocks
        LevelGenBase.setBlockAndMetadata(world, baseX + 2, baseY + 0, baseZ + 15, SokobanMod.BlockUnbreakableSolids.blockID, 0); //tile.Unbreakable Solid Blocks
        LevelGenBase.setBlockAndMetadata(world, baseX + 2, baseY + 1, baseZ + 0, SokobanMod.BlockUnbreakableSolids.blockID, 0); //tile.Unbreakable Solid Blocks
        LevelGenBase.setBlockAndMetadata(world, baseX + 2, baseY + 1, baseZ + 15, SokobanMod.BlockUnbreakableSolids.blockID, 0); //tile.Unbreakable Solid Blocks
        LevelGenBase.setBlockAndMetadata(world, baseX + 2, baseY + 2, baseZ + 0, SokobanMod.BlockUnbreakableSolids.blockID, 0); //tile.Unbreakable Solid Blocks
        LevelGenBase.setBlockAndMetadata(world, baseX + 2, baseY + 2, baseZ + 15, SokobanMod.BlockUnbreakableSolids.blockID, 0); //tile.Unbreakable Solid Blocks
        LevelGenBase.setBlockAndMetadata(world, baseX + 2, baseY + 3, baseZ + 0, SokobanMod.BlockUnbreakableSolids.blockID, 0); //tile.Unbreakable Solid Blocks
        LevelGenBase.setBlockAndMetadata(world, baseX + 2, baseY + 3, baseZ + 1, Block.bedrock.blockID, 0); //tile.bedrock
        LevelGenBase.setBlockAndMetadata(world, baseX + 2, baseY + 3, baseZ + 3, Block.bedrock.blockID, 0); //tile.bedrock
        LevelGenBase.setBlockAndMetadata(world, baseX + 2, baseY + 3, baseZ + 4, Block.bedrock.blockID, 0); //tile.bedrock
        LevelGenBase.setBlockAndMetadata(world, baseX + 2, baseY + 3, baseZ + 15, SokobanMod.BlockUnbreakableSolids.blockID, 0); //tile.Unbreakable Solid Blocks
        LevelGenBase.setBlockAndMetadata(world, baseX + 2, baseY + 4, baseZ + 0, SokobanMod.BlockUnbreakableSolids.blockID, 0); //tile.Unbreakable Solid Blocks
        LevelGenBase.setBlockAndMetadata(world, baseX + 2, baseY + 4, baseZ + 8, SokobanMod.BlockUnbreakableSolids.blockID, 0); //tile.Unbreakable Solid Blocks
        LevelGenBase.setBlockAndMetadata(world, baseX + 2, baseY + 4, baseZ + 10, Block.bedrock.blockID, 0); //tile.bedrock
        LevelGenBase.setBlockAndMetadata(world, baseX + 2, baseY + 4, baseZ + 15, SokobanMod.BlockUnbreakableSolids.blockID, 0); //tile.Unbreakable Solid Blocks
        LevelGenBase.setBlockAndMetadata(world, baseX + 2, baseY + 5, baseZ + 0, SokobanMod.BlockUnbreakableSolids.blockID, 0); //tile.Unbreakable Solid Blocks
        LevelGenBase.setBlockAndMetadata(world, baseX + 2, baseY + 5, baseZ + 3, SokobanMod.BlockTarget.blockID, 2); //tile.Target
        LevelGenBase.setBlockAndMetadata(world, baseX + 2, baseY + 5, baseZ + 8, SokobanMod.BlockUnbreakableSolids.blockID, 0); //tile.Unbreakable Solid Blocks
        LevelGenBase.setBlockAndMetadata(world, baseX + 2, baseY + 5, baseZ + 9, SokobanMod.BlockRedstoneRemover.blockID, 5); //tile.Redstone Remover
        LevelGenBase.setBlockAndMetadata(world, baseX + 2, baseY + 5, baseZ + 11, Block.bedrock.blockID, 0); //tile.bedrock
        LevelGenBase.setBlockAndMetadata(world, baseX + 2, baseY + 5, baseZ + 15, SokobanMod.BlockUnbreakableSolids.blockID, 0); //tile.Unbreakable Solid Blocks
        LevelGenBase.setBlockAndMetadata(world, baseX + 2, baseY + 6, baseZ + 0, SokobanMod.BlockUnbreakableSolids.blockID, 0); //tile.Unbreakable Solid Blocks
        LevelGenBase.setBlockAndMetadata(world, baseX + 2, baseY + 6, baseZ + 1, SokobanMod.BlockUnbreakableSolids.blockID, 0); //tile.Unbreakable Solid Blocks
        LevelGenBase.setBlockAndMetadata(world, baseX + 2, baseY + 6, baseZ + 2, SokobanMod.BlockUnbreakableSolids.blockID, 0); //tile.Unbreakable Solid Blocks
        LevelGenBase.setBlockAndMetadata(world, baseX + 2, baseY + 6, baseZ + 3, SokobanMod.BlockVaporizingBlock.blockID, 0); //tile.Vaporizing Block
        LevelGenBase.setBlockAndMetadata(world, baseX + 2, baseY + 6, baseZ + 4, SokobanMod.BlockUnbreakableSolids.blockID, 0); //tile.Unbreakable Solid Blocks
        LevelGenBase.setBlockAndMetadata(world, baseX + 2, baseY + 6, baseZ + 5, SokobanMod.BlockUnbreakableSolids.blockID, 0); //tile.Unbreakable Solid Blocks
        LevelGenBase.setBlockAndMetadata(world, baseX + 2, baseY + 6, baseZ + 6, SokobanMod.BlockUnbreakableSolids.blockID, 0); //tile.Unbreakable Solid Blocks
        LevelGenBase.setBlockAndMetadata(world, baseX + 2, baseY + 6, baseZ + 7, SokobanMod.BlockUnbreakableSolids.blockID, 0); //tile.Unbreakable Solid Blocks
        LevelGenBase.setBlockAndMetadata(world, baseX + 2, baseY + 6, baseZ + 8, SokobanMod.BlockUnbreakableSolids.blockID, 0); //tile.Unbreakable Solid Blocks
        LevelGenBase.setBlockAndMetadata(world, baseX + 2, baseY + 6, baseZ + 9, SokobanMod.BlockUnbreakableSolids.blockID, 0); //tile.Unbreakable Solid Blocks
        LevelGenBase.setBlockAndMetadata(world, baseX + 2, baseY + 6, baseZ + 14, Block.bedrock.blockID, 0); //tile.bedrock
        LevelGenBase.setBlockAndMetadata(world, baseX + 2, baseY + 6, baseZ + 15, SokobanMod.BlockUnbreakableSolids.blockID, 0); //tile.Unbreakable Solid Blocks
        LevelGenBase.setBlockAndMetadata(world, baseX + 2, baseY + 7, baseZ + 0, SokobanMod.BlockUnbreakableSolids.blockID, 0); //tile.Unbreakable Solid Blocks
        LevelGenBase.setBlockAndMetadata(world, baseX + 2, baseY + 7, baseZ + 1, SokobanMod.BlockUnbreakableLamps.blockID, 7); //tile.Unbreakable Lamp Blocks
        LevelGenBase.setBlockAndMetadata(world, baseX + 2, baseY + 7, baseZ + 2, SokobanMod.BlockUnbreakableLamps.blockID, 7); //tile.Unbreakable Lamp Blocks
        LevelGenBase.setBlockAndMetadata(world, baseX + 2, baseY + 7, baseZ + 3, SokobanMod.BlockVaporizingBlock.blockID, 0); //tile.Vaporizing Block
        LevelGenBase.setBlockAndMetadata(world, baseX + 2, baseY + 7, baseZ + 4, SokobanMod.BlockUnbreakableLamps.blockID, 7); //tile.Unbreakable Lamp Blocks
        LevelGenBase.setBlockAndMetadata(world, baseX + 2, baseY + 7, baseZ + 5, SokobanMod.BlockUnbreakableLamps.blockID, 7); //tile.Unbreakable Lamp Blocks
        LevelGenBase.setBlockAndMetadata(world, baseX + 2, baseY + 7, baseZ + 6, SokobanMod.BlockUnbreakableLamps.blockID, 7); //tile.Unbreakable Lamp Blocks
        LevelGenBase.setBlockAndMetadata(world, baseX + 2, baseY + 7, baseZ + 7, SokobanMod.BlockUnbreakableLamps.blockID, 7); //tile.Unbreakable Lamp Blocks
        LevelGenBase.setBlockAndMetadata(world, baseX + 2, baseY + 7, baseZ + 8, SokobanMod.BlockUnbreakableLamps.blockID, 7); //tile.Unbreakable Lamp Blocks
        LevelGenBase.setBlockAndMetadata(world, baseX + 2, baseY + 7, baseZ + 9, SokobanMod.BlockUnbreakableLamps.blockID, 7); //tile.Unbreakable Lamp Blocks
        LevelGenBase.setBlockAndMetadata(world, baseX + 2, baseY + 7, baseZ + 15, SokobanMod.BlockUnbreakableSolids.blockID, 0); //tile.Unbreakable Solid Blocks
        LevelGenBase.setBlockAndMetadata(world, baseX + 2, baseY + 8, baseZ + 0, SokobanMod.BlockUnbreakableSolids.blockID, 0); //tile.Unbreakable Solid Blocks
        LevelGenBase.setBlockAndMetadata(world, baseX + 2, baseY + 8, baseZ + 1, SokobanMod.BlockUnbreakableSolids.blockID, 0); //tile.Unbreakable Solid Blocks
        LevelGenBase.setBlockAndMetadata(world, baseX + 2, baseY + 8, baseZ + 2, SokobanMod.BlockUnbreakableSolids.blockID, 0); //tile.Unbreakable Solid Blocks
        LevelGenBase.setBlockAndMetadata(world, baseX + 2, baseY + 8, baseZ + 3, SokobanMod.BlockVaporizingBlock.blockID, 0); //tile.Vaporizing Block
        LevelGenBase.setBlockAndMetadata(world, baseX + 2, baseY + 8, baseZ + 4, SokobanMod.BlockUnbreakableSolids.blockID, 0); //tile.Unbreakable Solid Blocks
        LevelGenBase.setBlockAndMetadata(world, baseX + 2, baseY + 8, baseZ + 5, SokobanMod.BlockUnbreakableSolids.blockID, 0); //tile.Unbreakable Solid Blocks
        LevelGenBase.setBlockAndMetadata(world, baseX + 2, baseY + 8, baseZ + 6, SokobanMod.BlockUnbreakableSolids.blockID, 0); //tile.Unbreakable Solid Blocks
        LevelGenBase.setBlockAndMetadata(world, baseX + 2, baseY + 8, baseZ + 7, SokobanMod.BlockUnbreakableSolids.blockID, 0); //tile.Unbreakable Solid Blocks
        LevelGenBase.setBlockAndMetadata(world, baseX + 2, baseY + 8, baseZ + 8, SokobanMod.BlockUnbreakableSolids.blockID, 0); //tile.Unbreakable Solid Blocks
        LevelGenBase.setBlockAndMetadata(world, baseX + 2, baseY + 8, baseZ + 9, SokobanMod.BlockUnbreakableSolids.blockID, 0); //tile.Unbreakable Solid Blocks
        LevelGenBase.setBlockAndMetadata(world, baseX + 2, baseY + 8, baseZ + 15, SokobanMod.BlockUnbreakableSolids.blockID, 0); //tile.Unbreakable Solid Blocks
        LevelGenBase.setBlockAndMetadata(world, baseX + 2, baseY + 9, baseZ + 0, SokobanMod.BlockUnbreakableSolids.blockID, 0); //tile.Unbreakable Solid Blocks
        LevelGenBase.setBlockAndMetadata(world, baseX + 2, baseY + 9, baseZ + 1, SokobanMod.BlockUnbreakableSolids.blockID, 0); //tile.Unbreakable Solid Blocks
        LevelGenBase.setBlockAndMetadata(world, baseX + 2, baseY + 9, baseZ + 2, SokobanMod.BlockUnbreakableSolids.blockID, 0); //tile.Unbreakable Solid Blocks
        LevelGenBase.setBlockAndMetadata(world, baseX + 2, baseY + 9, baseZ + 3, SokobanMod.BlockUnbreakableLamps.blockID, 5); //tile.Unbreakable Lamp Blocks
        LevelGenBase.setBlockAndMetadata(world, baseX + 2, baseY + 9, baseZ + 4, SokobanMod.BlockUnbreakableSolids.blockID, 0); //tile.Unbreakable Solid Blocks
        LevelGenBase.setBlockAndMetadata(world, baseX + 2, baseY + 9, baseZ + 5, SokobanMod.BlockUnbreakableSolids.blockID, 0); //tile.Unbreakable Solid Blocks
        LevelGenBase.setBlockAndMetadata(world, baseX + 2, baseY + 9, baseZ + 6, SokobanMod.BlockUnbreakableSolids.blockID, 0); //tile.Unbreakable Solid Blocks
        LevelGenBase.setBlockAndMetadata(world, baseX + 2, baseY + 9, baseZ + 7, SokobanMod.BlockRedstoneRemover.blockID, 5); //tile.Redstone Remover
        LevelGenBase.setBlockAndMetadata(world, baseX + 2, baseY + 9, baseZ + 8, SokobanMod.BlockUnbreakableSolids.blockID, 0); //tile.Unbreakable Solid Blocks
        LevelGenBase.setBlockAndMetadata(world, baseX + 2, baseY + 9, baseZ + 9, SokobanMod.BlockUnbreakableSolids.blockID, 0); //tile.Unbreakable Solid Blocks
        LevelGenBase.setBlockAndMetadata(world, baseX + 2, baseY + 9, baseZ + 15, SokobanMod.BlockUnbreakableSolids.blockID, 0); //tile.Unbreakable Solid Blocks
        LevelGenBase.setBlockAndMetadata(world, baseX + 2, baseY + 10, baseZ + 0, SokobanMod.BlockUnbreakableSolids.blockID, 0); //tile.Unbreakable Solid Blocks
        LevelGenBase.setBlockAndMetadata(world, baseX + 2, baseY + 10, baseZ + 1, SokobanMod.BlockUnbreakableSolids.blockID, 0); //tile.Unbreakable Solid Blocks
        LevelGenBase.setBlockAndMetadata(world, baseX + 2, baseY + 10, baseZ + 2, SokobanMod.BlockUnbreakableSolids.blockID, 0); //tile.Unbreakable Solid Blocks
        LevelGenBase.setBlockAndMetadata(world, baseX + 2, baseY + 10, baseZ + 3, SokobanMod.BlockUnbreakableSolids.blockID, 0); //tile.Unbreakable Solid Blocks
        LevelGenBase.setBlockAndMetadata(world, baseX + 2, baseY + 10, baseZ + 4, SokobanMod.BlockUnbreakableSolids.blockID, 0); //tile.Unbreakable Solid Blocks
        LevelGenBase.setBlockAndMetadata(world, baseX + 2, baseY + 10, baseZ + 7, SokobanMod.BlockUnbreakableSolids.blockID, 0); //tile.Unbreakable Solid Blocks
        LevelGenBase.setBlockAndMetadata(world, baseX + 2, baseY + 10, baseZ + 8, SokobanMod.BlockUnbreakableSolids.blockID, 0); //tile.Unbreakable Solid Blocks
        LevelGenBase.setBlockAndMetadata(world, baseX + 2, baseY + 10, baseZ + 9, SokobanMod.BlockUnbreakableSolids.blockID, 0); //tile.Unbreakable Solid Blocks
        LevelGenBase.setBlockAndMetadata(world, baseX + 2, baseY + 10, baseZ + 10, SokobanMod.BlockUnbreakableSolids.blockID, 0); //tile.Unbreakable Solid Blocks
        LevelGenBase.setBlockAndMetadata(world, baseX + 2, baseY + 10, baseZ + 15, SokobanMod.BlockUnbreakableSolids.blockID, 0); //tile.Unbreakable Solid Blocks
        LevelGenBase.setBlockAndMetadata(world, baseX + 2, baseY + 11, baseZ + 0, SokobanMod.BlockUnbreakableSolids.blockID, 0); //tile.Unbreakable Solid Blocks
        LevelGenBase.setBlockAndMetadata(world, baseX + 2, baseY + 11, baseZ + 1, SokobanMod.BlockUnbreakableLamps.blockID, 7); //tile.Unbreakable Lamp Blocks
        LevelGenBase.setBlockAndMetadata(world, baseX + 2, baseY + 11, baseZ + 2, SokobanMod.BlockUnbreakableLamps.blockID, 7); //tile.Unbreakable Lamp Blocks
        LevelGenBase.setBlockAndMetadata(world, baseX + 2, baseY + 11, baseZ + 3, SokobanMod.BlockUnbreakableLamps.blockID, 7); //tile.Unbreakable Lamp Blocks
        LevelGenBase.setBlockAndMetadata(world, baseX + 2, baseY + 11, baseZ + 4, SokobanMod.BlockUnbreakableLamps.blockID, 7); //tile.Unbreakable Lamp Blocks
        LevelGenBase.setBlockAndMetadata(world, baseX + 2, baseY + 11, baseZ + 7, SokobanMod.BlockUnbreakableLamps.blockID, 7); //tile.Unbreakable Lamp Blocks
        LevelGenBase.setBlockAndMetadata(world, baseX + 2, baseY + 11, baseZ + 8, SokobanMod.BlockUnbreakableLamps.blockID, 7); //tile.Unbreakable Lamp Blocks
        LevelGenBase.setBlockAndMetadata(world, baseX + 2, baseY + 11, baseZ + 9, SokobanMod.BlockUnbreakableLamps.blockID, 7); //tile.Unbreakable Lamp Blocks
        LevelGenBase.setBlockAndMetadata(world, baseX + 2, baseY + 11, baseZ + 10, SokobanMod.BlockUnbreakableSolids.blockID, 0); //tile.Unbreakable Solid Blocks
        LevelGenBase.setBlockAndMetadata(world, baseX + 2, baseY + 11, baseZ + 15, SokobanMod.BlockUnbreakableSolids.blockID, 0); //tile.Unbreakable Solid Blocks
        LevelGenBase.setBlockAndMetadata(world, baseX + 2, baseY + 12, baseZ + 0, SokobanMod.BlockUnbreakableSolids.blockID, 0); //tile.Unbreakable Solid Blocks
        LevelGenBase.setBlockAndMetadata(world, baseX + 2, baseY + 12, baseZ + 1, SokobanMod.BlockUnbreakableSolids.blockID, 0); //tile.Unbreakable Solid Blocks
        LevelGenBase.setBlockAndMetadata(world, baseX + 2, baseY + 12, baseZ + 2, SokobanMod.BlockUnbreakableSolids.blockID, 0); //tile.Unbreakable Solid Blocks
        LevelGenBase.setBlockAndMetadata(world, baseX + 2, baseY + 12, baseZ + 3, SokobanMod.BlockUnbreakableSolids.blockID, 0); //tile.Unbreakable Solid Blocks
        LevelGenBase.setBlockAndMetadata(world, baseX + 2, baseY + 12, baseZ + 4, SokobanMod.BlockUnbreakableSolids.blockID, 0); //tile.Unbreakable Solid Blocks
        LevelGenBase.setBlockAndMetadata(world, baseX + 2, baseY + 12, baseZ + 5, SokobanMod.BlockUnbreakableSolids.blockID, 0); //tile.Unbreakable Solid Blocks
        LevelGenBase.setBlockAndMetadata(world, baseX + 2, baseY + 12, baseZ + 6, SokobanMod.BlockUnbreakableSolids.blockID, 0); //tile.Unbreakable Solid Blocks
        LevelGenBase.setBlockAndMetadata(world, baseX + 2, baseY + 12, baseZ + 7, SokobanMod.BlockUnbreakableSolids.blockID, 0); //tile.Unbreakable Solid Blocks
        LevelGenBase.setBlockAndMetadata(world, baseX + 2, baseY + 12, baseZ + 8, SokobanMod.BlockUnbreakableSolids.blockID, 0); //tile.Unbreakable Solid Blocks
        LevelGenBase.setBlockAndMetadata(world, baseX + 2, baseY + 12, baseZ + 9, SokobanMod.BlockUnbreakableSolids.blockID, 0); //tile.Unbreakable Solid Blocks
        LevelGenBase.setBlockAndMetadata(world, baseX + 2, baseY + 12, baseZ + 10, SokobanMod.BlockUnbreakableSolids.blockID, 0); //tile.Unbreakable Solid Blocks
        LevelGenBase.setBlockAndMetadata(world, baseX + 2, baseY + 12, baseZ + 11, SokobanMod.BlockUnbreakableSolids.blockID, 0); //tile.Unbreakable Solid Blocks
        LevelGenBase.setBlockAndMetadata(world, baseX + 2, baseY + 12, baseZ + 12, SokobanMod.BlockUnbreakableSolids.blockID, 0); //tile.Unbreakable Solid Blocks
        LevelGenBase.setBlockAndMetadata(world, baseX + 2, baseY + 12, baseZ + 13, SokobanMod.BlockUnbreakableSolids.blockID, 0); //tile.Unbreakable Solid Blocks
        LevelGenBase.setBlockAndMetadata(world, baseX + 2, baseY + 12, baseZ + 14, SokobanMod.BlockUnbreakableSolids.blockID, 0); //tile.Unbreakable Solid Blocks
        LevelGenBase.setBlockAndMetadata(world, baseX + 2, baseY + 12, baseZ + 15, SokobanMod.BlockUnbreakableSolids.blockID, 0); //tile.Unbreakable Solid Blocks
        LevelGenBase.setBlockAndMetadata(world, baseX + 3, baseY + 0, baseZ + 0, SokobanMod.BlockUnbreakableSolids.blockID, 0); //tile.Unbreakable Solid Blocks
        LevelGenBase.setBlockAndMetadata(world, baseX + 3, baseY + 0, baseZ + 1, SokobanMod.BlockUnbreakableSolids.blockID, 0); //tile.Unbreakable Solid Blocks
        LevelGenBase.setBlockAndMetadata(world, baseX + 3, baseY + 0, baseZ + 2, SokobanMod.BlockUnbreakableSolids.blockID, 0); //tile.Unbreakable Solid Blocks
        LevelGenBase.setBlockAndMetadata(world, baseX + 3, baseY + 0, baseZ + 3, SokobanMod.BlockUnbreakableSolids.blockID, 0); //tile.Unbreakable Solid Blocks
        LevelGenBase.setBlockAndMetadata(world, baseX + 3, baseY + 0, baseZ + 4, SokobanMod.BlockUnbreakableSolids.blockID, 0); //tile.Unbreakable Solid Blocks
        LevelGenBase.setBlockAndMetadata(world, baseX + 3, baseY + 0, baseZ + 5, SokobanMod.BlockUnbreakableSolids.blockID, 0); //tile.Unbreakable Solid Blocks
        LevelGenBase.setBlockAndMetadata(world, baseX + 3, baseY + 0, baseZ + 6, SokobanMod.BlockUnbreakableSolids.blockID, 0); //tile.Unbreakable Solid Blocks
        LevelGenBase.setBlockAndMetadata(world, baseX + 3, baseY + 0, baseZ + 7, SokobanMod.BlockUnbreakableSolids.blockID, 0); //tile.Unbreakable Solid Blocks
        LevelGenBase.setBlockAndMetadata(world, baseX + 3, baseY + 0, baseZ + 8, SokobanMod.BlockUnbreakableSolids.blockID, 0); //tile.Unbreakable Solid Blocks
        LevelGenBase.setBlockAndMetadata(world, baseX + 3, baseY + 0, baseZ + 9, SokobanMod.BlockUnbreakableSolids.blockID, 0); //tile.Unbreakable Solid Blocks
        LevelGenBase.setBlockAndMetadata(world, baseX + 3, baseY + 0, baseZ + 10, SokobanMod.BlockUnbreakableSolids.blockID, 0); //tile.Unbreakable Solid Blocks
        LevelGenBase.setBlockAndMetadata(world, baseX + 3, baseY + 0, baseZ + 11, SokobanMod.BlockUnbreakableSolids.blockID, 0); //tile.Unbreakable Solid Blocks
        LevelGenBase.setBlockAndMetadata(world, baseX + 3, baseY + 0, baseZ + 12, SokobanMod.BlockUnbreakableSolids.blockID, 0); //tile.Unbreakable Solid Blocks
        LevelGenBase.setBlockAndMetadata(world, baseX + 3, baseY + 0, baseZ + 13, SokobanMod.BlockUnbreakableSolids.blockID, 0); //tile.Unbreakable Solid Blocks
        LevelGenBase.setBlockAndMetadata(world, baseX + 3, baseY + 0, baseZ + 14, SokobanMod.BlockUnbreakableSolids.blockID, 0); //tile.Unbreakable Solid Blocks
        LevelGenBase.setBlockAndMetadata(world, baseX + 3, baseY + 0, baseZ + 15, SokobanMod.BlockUnbreakableSolids.blockID, 0); //tile.Unbreakable Solid Blocks
        LevelGenBase.setBlockAndMetadata(world, baseX + 3, baseY + 1, baseZ + 0, SokobanMod.BlockUnbreakableSolids.blockID, 0); //tile.Unbreakable Solid Blocks
        LevelGenBase.setBlockAndMetadata(world, baseX + 3, baseY + 1, baseZ + 14, SokobanMod.BlockUnbreakableLamps.blockID, 7); //tile.Unbreakable Lamp Blocks
        LevelGenBase.setBlockAndMetadata(world, baseX + 3, baseY + 1, baseZ + 15, SokobanMod.BlockUnbreakableSolids.blockID, 0); //tile.Unbreakable Solid Blocks
        LevelGenBase.setBlockAndMetadata(world, baseX + 3, baseY + 2, baseZ + 0, SokobanMod.BlockUnbreakableSolids.blockID, 0); //tile.Unbreakable Solid Blocks
        LevelGenBase.setBlockAndMetadata(world, baseX + 3, baseY + 2, baseZ + 15, SokobanMod.BlockUnbreakableSolids.blockID, 0); //tile.Unbreakable Solid Blocks
        LevelGenBase.setBlockAndMetadata(world, baseX + 3, baseY + 3, baseZ + 0, SokobanMod.BlockUnbreakableSolids.blockID, 0); //tile.Unbreakable Solid Blocks
        LevelGenBase.setBlockAndMetadata(world, baseX + 3, baseY + 3, baseZ + 1, Block.bedrock.blockID, 0); //tile.bedrock
        LevelGenBase.setBlockAndMetadata(world, baseX + 3, baseY + 3, baseZ + 8, Block.stone.blockID, 0); //tile.stone
        LevelGenBase.setBlockAndMetadata(world, baseX + 3, baseY + 3, baseZ + 15, SokobanMod.BlockUnbreakableSolids.blockID, 0); //tile.Unbreakable Solid Blocks
        LevelGenBase.setBlockAndMetadata(world, baseX + 3, baseY + 4, baseZ + 0, SokobanMod.BlockUnbreakableSolids.blockID, 0); //tile.Unbreakable Solid Blocks
        LevelGenBase.setBlockAndMetadata(world, baseX + 3, baseY + 4, baseZ + 7, SokobanMod.BlockUnbreakableSolids.blockID, 0); //tile.Unbreakable Solid Blocks
        LevelGenBase.setBlockAndMetadata(world, baseX + 3, baseY + 4, baseZ + 9, SokobanMod.BlockUnbreakableSolids.blockID, 0); //tile.Unbreakable Solid Blocks
        LevelGenBase.setBlockAndMetadata(world, baseX + 3, baseY + 4, baseZ + 15, SokobanMod.BlockUnbreakableSolids.blockID, 0); //tile.Unbreakable Solid Blocks
        LevelGenBase.setBlockAndMetadata(world, baseX + 3, baseY + 5, baseZ + 0, SokobanMod.BlockUnbreakableSolids.blockID, 0); //tile.Unbreakable Solid Blocks
        LevelGenBase.setBlockAndMetadata(world, baseX + 3, baseY + 5, baseZ + 1, SokobanMod.BlockUnbreakableSolids.blockID, 0); //tile.Unbreakable Solid Blocks
        LevelGenBase.setBlockAndMetadata(world, baseX + 3, baseY + 5, baseZ + 2, SokobanMod.BlockUnbreakableSolids.blockID, 0); //tile.Unbreakable Solid Blocks
        LevelGenBase.setBlockAndMetadata(world, baseX + 3, baseY + 5, baseZ + 3, SokobanMod.BlockUnbreakableSolids.blockID, 0); //tile.Unbreakable Solid Blocks
        LevelGenBase.setBlockAndMetadata(world, baseX + 3, baseY + 5, baseZ + 4, SokobanMod.BlockUnbreakableSolids.blockID, 0); //tile.Unbreakable Solid Blocks
        LevelGenBase.setBlockAndMetadata(world, baseX + 3, baseY + 5, baseZ + 5, SokobanMod.BlockUnbreakableSolids.blockID, 0); //tile.Unbreakable Solid Blocks
        LevelGenBase.setBlockAndMetadata(world, baseX + 3, baseY + 5, baseZ + 6, SokobanMod.BlockUnbreakableSolids.blockID, 0); //tile.Unbreakable Solid Blocks
        LevelGenBase.setBlockAndMetadata(world, baseX + 3, baseY + 5, baseZ + 7, SokobanMod.BlockUnbreakableSolids.blockID, 0); //tile.Unbreakable Solid Blocks
        LevelGenBase.setBlockAndMetadata(world, baseX + 3, baseY + 5, baseZ + 8, SokobanMod.BlockTarget.blockID, 0); //tile.Target
        LevelGenBase.setBlockAndMetadata(world, baseX + 3, baseY + 5, baseZ + 9, SokobanMod.BlockTarget.blockID, 0); //tile.Target
        LevelGenBase.setBlockAndMetadata(world, baseX + 3, baseY + 5, baseZ + 10, SokobanMod.BlockUnbreakableSolids.blockID, 0); //tile.Unbreakable Solid Blocks
        LevelGenBase.setBlockAndMetadata(world, baseX + 3, baseY + 5, baseZ + 15, SokobanMod.BlockUnbreakableSolids.blockID, 0); //tile.Unbreakable Solid Blocks
        LevelGenBase.setBlockAndMetadata(world, baseX + 3, baseY + 6, baseZ + 0, SokobanMod.BlockUnbreakableSolids.blockID, 0); //tile.Unbreakable Solid Blocks
        LevelGenBase.setBlockAndMetadata(world, baseX + 3, baseY + 6, baseZ + 10, SokobanMod.BlockUnbreakableSolids.blockID, 0); //tile.Unbreakable Solid Blocks
        LevelGenBase.setBlockAndMetadata(world, baseX + 3, baseY + 6, baseZ + 11, SokobanMod.BlockUnbreakableSolids.blockID, 0); //tile.Unbreakable Solid Blocks
        LevelGenBase.setBlockAndMetadata(world, baseX + 3, baseY + 6, baseZ + 12, SokobanMod.BlockUnbreakableSolids.blockID, 0); //tile.Unbreakable Solid Blocks
        LevelGenBase.setBlockAndMetadata(world, baseX + 3, baseY + 6, baseZ + 15, SokobanMod.BlockUnbreakableSolids.blockID, 0); //tile.Unbreakable Solid Blocks
        LevelGenBase.setBlockAndMetadata(world, baseX + 3, baseY + 7, baseZ + 0, SokobanMod.BlockUnbreakableGlasses.blockID, 0); //tile.Unbreakable Glass Blocks
        LevelGenBase.setBlockAndMetadata(world, baseX + 3, baseY + 7, baseZ + 10, SokobanMod.BlockUnbreakableLamps.blockID, 7); //tile.Unbreakable Lamp Blocks
        LevelGenBase.setBlockAndMetadata(world, baseX + 3, baseY + 7, baseZ + 11, SokobanMod.BlockUnbreakableLamps.blockID, 7); //tile.Unbreakable Lamp Blocks
        LevelGenBase.setBlockAndMetadata(world, baseX + 3, baseY + 7, baseZ + 12, SokobanMod.BlockUnbreakableLamps.blockID, 7); //tile.Unbreakable Lamp Blocks
        LevelGenBase.setBlockAndMetadata(world, baseX + 3, baseY + 7, baseZ + 13, SokobanMod.BlockUnbreakableSolids.blockID, 0); //tile.Unbreakable Solid Blocks
        LevelGenBase.setBlockAndMetadata(world, baseX + 3, baseY + 7, baseZ + 14, Block.bedrock.blockID, 0); //tile.bedrock
        LevelGenBase.setBlockAndMetadata(world, baseX + 3, baseY + 7, baseZ + 15, SokobanMod.BlockUnbreakableSolids.blockID, 0); //tile.Unbreakable Solid Blocks
        LevelGenBase.setBlockAndMetadata(world, baseX + 3, baseY + 8, baseZ + 0, SokobanMod.BlockUnbreakableGlasses.blockID, 0); //tile.Unbreakable Glass Blocks
        LevelGenBase.setBlockAndMetadata(world, baseX + 3, baseY + 8, baseZ + 10, SokobanMod.BlockUnbreakableSolids.blockID, 0); //tile.Unbreakable Solid Blocks
        LevelGenBase.setBlockAndMetadata(world, baseX + 3, baseY + 8, baseZ + 11, SokobanMod.BlockUnbreakableSolids.blockID, 0); //tile.Unbreakable Solid Blocks
        LevelGenBase.setBlockAndMetadata(world, baseX + 3, baseY + 8, baseZ + 12, SokobanMod.BlockUnbreakableSolids.blockID, 0); //tile.Unbreakable Solid Blocks
        LevelGenBase.setBlockAndMetadata(world, baseX + 3, baseY + 8, baseZ + 13, SokobanMod.BlockUnbreakableSolids.blockID, 0); //tile.Unbreakable Solid Blocks
        LevelGenBase.setBlockAndMetadata(world, baseX + 3, baseY + 8, baseZ + 15, SokobanMod.BlockUnbreakableSolids.blockID, 0); //tile.Unbreakable Solid Blocks
        LevelGenBase.setBlockAndMetadata(world, baseX + 3, baseY + 9, baseZ + 0, SokobanMod.BlockUnbreakableSolids.blockID, 0); //tile.Unbreakable Solid Blocks
        LevelGenBase.setBlockAndMetadata(world, baseX + 3, baseY + 9, baseZ + 1, SokobanMod.BlockUnbreakableSolids.blockID, 0); //tile.Unbreakable Solid Blocks
        LevelGenBase.setBlockAndMetadata(world, baseX + 3, baseY + 9, baseZ + 2, SokobanMod.BlockUnbreakableSolids.blockID, 0); //tile.Unbreakable Solid Blocks
        LevelGenBase.setBlockAndMetadata(world, baseX + 3, baseY + 9, baseZ + 3, SokobanMod.BlockUnbreakableSolids.blockID, 0); //tile.Unbreakable Solid Blocks
        LevelGenBase.setBlockAndMetadata(world, baseX + 3, baseY + 9, baseZ + 4, SokobanMod.BlockUnbreakableSolids.blockID, 0); //tile.Unbreakable Solid Blocks
        LevelGenBase.setBlockAndMetadata(world, baseX + 3, baseY + 9, baseZ + 5, SokobanMod.BlockUnbreakableSolids.blockID, 0); //tile.Unbreakable Solid Blocks
        LevelGenBase.setBlockAndMetadata(world, baseX + 3, baseY + 9, baseZ + 6, SokobanMod.BlockUnbreakableSolids.blockID, 0); //tile.Unbreakable Solid Blocks
        LevelGenBase.setBlockAndMetadata(world, baseX + 3, baseY + 9, baseZ + 7, SokobanMod.BlockUnbreakableLamps.blockID, 0); //tile.Unbreakable Lamp Blocks
        LevelGenBase.setBlockAndMetadata(world, baseX + 3, baseY + 9, baseZ + 8, SokobanMod.BlockUnbreakableLamps.blockID, 0); //tile.Unbreakable Lamp Blocks
        LevelGenBase.setBlockAndMetadata(world, baseX + 3, baseY + 9, baseZ + 9, SokobanMod.BlockUnbreakableGlasses.blockID, 0); //tile.Unbreakable Glass Blocks
        LevelGenBase.setBlockAndMetadata(world, baseX + 3, baseY + 9, baseZ + 10, SokobanMod.BlockUnbreakableSolids.blockID, 0); //tile.Unbreakable Solid Blocks
        LevelGenBase.setBlockAndMetadata(world, baseX + 3, baseY + 9, baseZ + 11, SokobanMod.BlockUnbreakableSolids.blockID, 0); //tile.Unbreakable Solid Blocks
        LevelGenBase.setBlockAndMetadata(world, baseX + 3, baseY + 9, baseZ + 12, SokobanMod.BlockUnbreakableSolids.blockID, 0); //tile.Unbreakable Solid Blocks
        LevelGenBase.setBlockAndMetadata(world, baseX + 3, baseY + 9, baseZ + 13, SokobanMod.BlockUnbreakableSolids.blockID, 0); //tile.Unbreakable Solid Blocks
        LevelGenBase.setBlockAndMetadata(world, baseX + 3, baseY + 9, baseZ + 15, SokobanMod.BlockUnbreakableSolids.blockID, 0); //tile.Unbreakable Solid Blocks
        LevelGenBase.setBlockAndMetadata(world, baseX + 3, baseY + 10, baseZ + 0, SokobanMod.BlockUnbreakableSolids.blockID, 0); //tile.Unbreakable Solid Blocks
        LevelGenBase.setBlockAndMetadata(world, baseX + 3, baseY + 10, baseZ + 10, SokobanMod.BlockUnbreakableSolids.blockID, 0); //tile.Unbreakable Solid Blocks
        LevelGenBase.setBlockAndMetadata(world, baseX + 3, baseY + 10, baseZ + 11, SokobanMod.BlockUnbreakableSolids.blockID, 0); //tile.Unbreakable Solid Blocks
        LevelGenBase.setBlockAndMetadata(world, baseX + 3, baseY + 10, baseZ + 12, SokobanMod.BlockUnbreakableSolids.blockID, 0); //tile.Unbreakable Solid Blocks
        LevelGenBase.setBlockAndMetadata(world, baseX + 3, baseY + 10, baseZ + 13, SokobanMod.BlockUnbreakableSolids.blockID, 0); //tile.Unbreakable Solid Blocks
        LevelGenBase.setBlockAndMetadata(world, baseX + 3, baseY + 10, baseZ + 15, SokobanMod.BlockUnbreakableSolids.blockID, 0); //tile.Unbreakable Solid Blocks
        LevelGenBase.setBlockAndMetadata(world, baseX + 3, baseY + 11, baseZ + 0, SokobanMod.BlockUnbreakableGlasses.blockID, 0); //tile.Unbreakable Glass Blocks
        LevelGenBase.setBlockAndMetadata(world, baseX + 3, baseY + 11, baseZ + 10, SokobanMod.BlockUnbreakableLamps.blockID, 7); //tile.Unbreakable Lamp Blocks
        LevelGenBase.setBlockAndMetadata(world, baseX + 3, baseY + 11, baseZ + 11, SokobanMod.BlockUnbreakableLamps.blockID, 7); //tile.Unbreakable Lamp Blocks
        LevelGenBase.setBlockAndMetadata(world, baseX + 3, baseY + 11, baseZ + 12, SokobanMod.BlockUnbreakableLamps.blockID, 7); //tile.Unbreakable Lamp Blocks
        LevelGenBase.setBlockAndMetadata(world, baseX + 3, baseY + 11, baseZ + 13, SokobanMod.BlockUnbreakableLamps.blockID, 7); //tile.Unbreakable Lamp Blocks
        LevelGenBase.setBlockAndMetadata(world, baseX + 3, baseY + 11, baseZ + 14, SokobanMod.BlockUnbreakableLamps.blockID, 7); //tile.Unbreakable Lamp Blocks
        LevelGenBase.setBlockAndMetadata(world, baseX + 3, baseY + 11, baseZ + 15, SokobanMod.BlockUnbreakableSolids.blockID, 0); //tile.Unbreakable Solid Blocks
        LevelGenBase.setBlockAndMetadata(world, baseX + 3, baseY + 12, baseZ + 0, SokobanMod.BlockUnbreakableSolids.blockID, 0); //tile.Unbreakable Solid Blocks
        LevelGenBase.setBlockAndMetadata(world, baseX + 3, baseY + 12, baseZ + 1, SokobanMod.BlockUnbreakableGlasses.blockID, 0); //tile.Unbreakable Glass Blocks
        LevelGenBase.setBlockAndMetadata(world, baseX + 3, baseY + 12, baseZ + 2, SokobanMod.BlockUnbreakableGlasses.blockID, 0); //tile.Unbreakable Glass Blocks
        LevelGenBase.setBlockAndMetadata(world, baseX + 3, baseY + 12, baseZ + 3, SokobanMod.BlockUnbreakableGlasses.blockID, 0); //tile.Unbreakable Glass Blocks
        LevelGenBase.setBlockAndMetadata(world, baseX + 3, baseY + 12, baseZ + 4, SokobanMod.BlockUnbreakableGlasses.blockID, 0); //tile.Unbreakable Glass Blocks
        LevelGenBase.setBlockAndMetadata(world, baseX + 3, baseY + 12, baseZ + 5, SokobanMod.BlockUnbreakableGlasses.blockID, 0); //tile.Unbreakable Glass Blocks
        LevelGenBase.setBlockAndMetadata(world, baseX + 3, baseY + 12, baseZ + 6, SokobanMod.BlockUnbreakableGlasses.blockID, 0); //tile.Unbreakable Glass Blocks
        LevelGenBase.setBlockAndMetadata(world, baseX + 3, baseY + 12, baseZ + 7, SokobanMod.BlockUnbreakableGlasses.blockID, 0); //tile.Unbreakable Glass Blocks
        LevelGenBase.setBlockAndMetadata(world, baseX + 3, baseY + 12, baseZ + 8, SokobanMod.BlockUnbreakableGlasses.blockID, 0); //tile.Unbreakable Glass Blocks
        LevelGenBase.setBlockAndMetadata(world, baseX + 3, baseY + 12, baseZ + 9, SokobanMod.BlockUnbreakableGlasses.blockID, 0); //tile.Unbreakable Glass Blocks
        LevelGenBase.setBlockAndMetadata(world, baseX + 3, baseY + 12, baseZ + 10, SokobanMod.BlockUnbreakableSolids.blockID, 0); //tile.Unbreakable Solid Blocks
        LevelGenBase.setBlockAndMetadata(world, baseX + 3, baseY + 12, baseZ + 11, SokobanMod.BlockUnbreakableSolids.blockID, 0); //tile.Unbreakable Solid Blocks
        LevelGenBase.setBlockAndMetadata(world, baseX + 3, baseY + 12, baseZ + 12, SokobanMod.BlockUnbreakableSolids.blockID, 0); //tile.Unbreakable Solid Blocks
        LevelGenBase.setBlockAndMetadata(world, baseX + 3, baseY + 12, baseZ + 13, SokobanMod.BlockUnbreakableSolids.blockID, 0); //tile.Unbreakable Solid Blocks
        LevelGenBase.setBlockAndMetadata(world, baseX + 3, baseY + 12, baseZ + 14, SokobanMod.BlockUnbreakableSolids.blockID, 0); //tile.Unbreakable Solid Blocks
        LevelGenBase.setBlockAndMetadata(world, baseX + 3, baseY + 12, baseZ + 15, SokobanMod.BlockUnbreakableSolids.blockID, 0); //tile.Unbreakable Solid Blocks
        LevelGenBase.setBlockAndMetadata(world, baseX + 4, baseY + 0, baseZ + 0, SokobanMod.BlockUnbreakableSolids.blockID, 0); //tile.Unbreakable Solid Blocks
        LevelGenBase.setBlockAndMetadata(world, baseX + 4, baseY + 0, baseZ + 1, SokobanMod.BlockUnbreakableSolids.blockID, 0); //tile.Unbreakable Solid Blocks
        LevelGenBase.setBlockAndMetadata(world, baseX + 4, baseY + 0, baseZ + 2, SokobanMod.BlockUnbreakableSolids.blockID, 0); //tile.Unbreakable Solid Blocks
        LevelGenBase.setBlockAndMetadata(world, baseX + 4, baseY + 0, baseZ + 3, SokobanMod.BlockUnbreakableSolids.blockID, 0); //tile.Unbreakable Solid Blocks
        LevelGenBase.setBlockAndMetadata(world, baseX + 4, baseY + 0, baseZ + 4, SokobanMod.BlockUnbreakableSolids.blockID, 0); //tile.Unbreakable Solid Blocks
        LevelGenBase.setBlockAndMetadata(world, baseX + 4, baseY + 0, baseZ + 5, SokobanMod.BlockUnbreakableSolids.blockID, 0); //tile.Unbreakable Solid Blocks
        LevelGenBase.setBlockAndMetadata(world, baseX + 4, baseY + 0, baseZ + 6, SokobanMod.BlockUnbreakableSolids.blockID, 0); //tile.Unbreakable Solid Blocks
        LevelGenBase.setBlockAndMetadata(world, baseX + 4, baseY + 0, baseZ + 7, SokobanMod.BlockUnbreakableSolids.blockID, 0); //tile.Unbreakable Solid Blocks
        LevelGenBase.setBlockAndMetadata(world, baseX + 4, baseY + 0, baseZ + 8, SokobanMod.BlockUnbreakableSolids.blockID, 0); //tile.Unbreakable Solid Blocks
        LevelGenBase.setBlockAndMetadata(world, baseX + 4, baseY + 0, baseZ + 9, SokobanMod.BlockUnbreakableSolids.blockID, 0); //tile.Unbreakable Solid Blocks
        LevelGenBase.setBlockAndMetadata(world, baseX + 4, baseY + 0, baseZ + 10, SokobanMod.BlockUnbreakableSolids.blockID, 0); //tile.Unbreakable Solid Blocks
        LevelGenBase.setBlockAndMetadata(world, baseX + 4, baseY + 0, baseZ + 11, SokobanMod.BlockUnbreakableSolids.blockID, 0); //tile.Unbreakable Solid Blocks
        LevelGenBase.setBlockAndMetadata(world, baseX + 4, baseY + 0, baseZ + 12, SokobanMod.BlockUnbreakableSolids.blockID, 0); //tile.Unbreakable Solid Blocks
        LevelGenBase.setBlockAndMetadata(world, baseX + 4, baseY + 0, baseZ + 13, SokobanMod.BlockUnbreakableSolids.blockID, 0); //tile.Unbreakable Solid Blocks
        LevelGenBase.setBlockAndMetadata(world, baseX + 4, baseY + 0, baseZ + 14, SokobanMod.BlockUnbreakableSolids.blockID, 0); //tile.Unbreakable Solid Blocks
        LevelGenBase.setBlockAndMetadata(world, baseX + 4, baseY + 0, baseZ + 15, SokobanMod.BlockUnbreakableSolids.blockID, 0); //tile.Unbreakable Solid Blocks
        LevelGenBase.setBlockAndMetadata(world, baseX + 4, baseY + 1, baseZ + 0, SokobanMod.BlockUnbreakableSolids.blockID, 0); //tile.Unbreakable Solid Blocks
        LevelGenBase.setBlockAndMetadata(world, baseX + 4, baseY + 1, baseZ + 15, SokobanMod.BlockUnbreakableSolids.blockID, 0); //tile.Unbreakable Solid Blocks
        LevelGenBase.setBlockAndMetadata(world, baseX + 4, baseY + 2, baseZ + 0, SokobanMod.BlockUnbreakableSolids.blockID, 0); //tile.Unbreakable Solid Blocks
        LevelGenBase.setBlockAndMetadata(world, baseX + 4, baseY + 2, baseZ + 15, SokobanMod.BlockUnbreakableSolids.blockID, 0); //tile.Unbreakable Solid Blocks
        LevelGenBase.setBlockAndMetadata(world, baseX + 4, baseY + 3, baseZ + 0, SokobanMod.BlockUnbreakableSolids.blockID, 0); //tile.Unbreakable Solid Blocks
        LevelGenBase.setBlockAndMetadata(world, baseX + 4, baseY + 3, baseZ + 1, Block.bedrock.blockID, 0); //tile.bedrock
        LevelGenBase.setBlockAndMetadata(world, baseX + 4, baseY + 3, baseZ + 2, Block.bedrock.blockID, 0); //tile.bedrock
        LevelGenBase.setBlockAndMetadata(world, baseX + 4, baseY + 3, baseZ + 3, Block.bedrock.blockID, 0); //tile.bedrock
        LevelGenBase.setBlockAndMetadata(world, baseX + 4, baseY + 3, baseZ + 4, Block.bedrock.blockID, 0); //tile.bedrock
        LevelGenBase.setBlockAndMetadata(world, baseX + 4, baseY + 3, baseZ + 8, Block.stone.blockID, 0); //tile.stone
        LevelGenBase.setBlockAndMetadata(world, baseX + 4, baseY + 3, baseZ + 9, SokobanMod.BlockUnbreakableSolids.blockID, 0); //tile.Unbreakable Solid Blocks
        LevelGenBase.setBlockAndMetadata(world, baseX + 4, baseY + 3, baseZ + 10, SokobanMod.BlockUnbreakableSolids.blockID, 0); //tile.Unbreakable Solid Blocks
        LevelGenBase.setBlockAndMetadata(world, baseX + 4, baseY + 3, baseZ + 11, SokobanMod.BlockUnbreakableSolids.blockID, 0); //tile.Unbreakable Solid Blocks
        LevelGenBase.setBlockAndMetadata(world, baseX + 4, baseY + 3, baseZ + 15, SokobanMod.BlockUnbreakableSolids.blockID, 0); //tile.Unbreakable Solid Blocks
        LevelGenBase.setBlockAndMetadata(world, baseX + 4, baseY + 4, baseZ + 0, SokobanMod.BlockUnbreakableSolids.blockID, 0); //tile.Unbreakable Solid Blocks
        LevelGenBase.setBlockAndMetadata(world, baseX + 4, baseY + 4, baseZ + 7, SokobanMod.BlockUnbreakableSolids.blockID, 0); //tile.Unbreakable Solid Blocks
        LevelGenBase.setBlockAndMetadata(world, baseX + 4, baseY + 4, baseZ + 9, SokobanMod.BlockUnbreakableSolids.blockID, 0); //tile.Unbreakable Solid Blocks
        LevelGenBase.setBlockAndMetadata(world, baseX + 4, baseY + 4, baseZ + 10, SokobanMod.BlockUnbreakableSolids.blockID, 0); //tile.Unbreakable Solid Blocks
        LevelGenBase.setBlockAndMetadata(world, baseX + 4, baseY + 4, baseZ + 11, SokobanMod.BlockUnbreakableSolids.blockID, 0); //tile.Unbreakable Solid Blocks
        LevelGenBase.setBlockAndMetadata(world, baseX + 4, baseY + 4, baseZ + 12, SokobanMod.BlockUnbreakableSolids.blockID, 0); //tile.Unbreakable Solid Blocks
        LevelGenBase.setBlockAndMetadata(world, baseX + 4, baseY + 4, baseZ + 13, SokobanMod.BlockUnbreakableSolids.blockID, 0); //tile.Unbreakable Solid Blocks
        LevelGenBase.setBlockAndMetadata(world, baseX + 4, baseY + 4, baseZ + 15, SokobanMod.BlockUnbreakableSolids.blockID, 0); //tile.Unbreakable Solid Blocks
        LevelGenBase.setBlockAndMetadata(world, baseX + 4, baseY + 5, baseZ + 0, SokobanMod.BlockUnbreakableSolids.blockID, 0); //tile.Unbreakable Solid Blocks
        LevelGenBase.setBlockAndMetadata(world, baseX + 4, baseY + 5, baseZ + 1, SokobanMod.BlockUnbreakableSolids.blockID, 0); //tile.Unbreakable Solid Blocks
        LevelGenBase.setBlockAndMetadata(world, baseX + 4, baseY + 5, baseZ + 2, SokobanMod.BlockUnbreakableSolids.blockID, 0); //tile.Unbreakable Solid Blocks
        LevelGenBase.setBlockAndMetadata(world, baseX + 4, baseY + 5, baseZ + 3, SokobanMod.BlockUnbreakableSolids.blockID, 0); //tile.Unbreakable Solid Blocks
        LevelGenBase.setBlockAndMetadata(world, baseX + 4, baseY + 5, baseZ + 4, SokobanMod.BlockUnbreakableSolids.blockID, 0); //tile.Unbreakable Solid Blocks
        LevelGenBase.setBlockAndMetadata(world, baseX + 4, baseY + 5, baseZ + 5, SokobanMod.BlockUnbreakableSolids.blockID, 0); //tile.Unbreakable Solid Blocks
        LevelGenBase.setBlockAndMetadata(world, baseX + 4, baseY + 5, baseZ + 6, SokobanMod.BlockUnbreakableSolids.blockID, 0); //tile.Unbreakable Solid Blocks
        LevelGenBase.setBlockAndMetadata(world, baseX + 4, baseY + 5, baseZ + 7, SokobanMod.BlockUnbreakableSolids.blockID, 0); //tile.Unbreakable Solid Blocks
        LevelGenBase.setBlockAndMetadata(world, baseX + 4, baseY + 5, baseZ + 8, SokobanMod.BlockUnbreakableGlasses.blockID, 0); //tile.Unbreakable Glass Blocks
        LevelGenBase.setBlockAndMetadata(world, baseX + 4, baseY + 5, baseZ + 9, SokobanMod.BlockUnbreakableSolids.blockID, 0); //tile.Unbreakable Solid Blocks
        LevelGenBase.setBlockAndMetadata(world, baseX + 4, baseY + 5, baseZ + 10, SokobanMod.BlockUnbreakableSolids.blockID, 0); //tile.Unbreakable Solid Blocks
        LevelGenBase.setBlockAndMetadata(world, baseX + 4, baseY + 5, baseZ + 11, SokobanMod.BlockUnbreakableSolids.blockID, 0); //tile.Unbreakable Solid Blocks
        LevelGenBase.setBlockAndMetadata(world, baseX + 4, baseY + 5, baseZ + 12, SokobanMod.BlockUnbreakableSolids.blockID, 0); //tile.Unbreakable Solid Blocks
        LevelGenBase.setBlockAndMetadata(world, baseX + 4, baseY + 5, baseZ + 15, SokobanMod.BlockUnbreakableSolids.blockID, 0); //tile.Unbreakable Solid Blocks
        LevelGenBase.setBlockAndMetadata(world, baseX + 4, baseY + 6, baseZ + 0, SokobanMod.BlockUnbreakableSolids.blockID, 0); //tile.Unbreakable Solid Blocks
        LevelGenBase.setBlockAndMetadata(world, baseX + 4, baseY + 6, baseZ + 13, SokobanMod.BlockUnbreakableSolids.blockID, 0); //tile.Unbreakable Solid Blocks
        LevelGenBase.setBlockAndMetadata(world, baseX + 4, baseY + 6, baseZ + 15, SokobanMod.BlockUnbreakableSolids.blockID, 0); //tile.Unbreakable Solid Blocks
        LevelGenBase.setBlockAndMetadata(world, baseX + 4, baseY + 7, baseZ + 0, SokobanMod.BlockUnbreakableGlasses.blockID, 0); //tile.Unbreakable Glass Blocks
        LevelGenBase.setBlockAndMetadata(world, baseX + 4, baseY + 7, baseZ + 13, SokobanMod.BlockUnbreakableLamps.blockID, 7); //tile.Unbreakable Lamp Blocks
        LevelGenBase.setBlockAndMetadata(world, baseX + 4, baseY + 7, baseZ + 14, Block.bedrock.blockID, 0); //tile.bedrock
        LevelGenBase.setBlockAndMetadata(world, baseX + 4, baseY + 7, baseZ + 15, SokobanMod.BlockUnbreakableSolids.blockID, 0); //tile.Unbreakable Solid Blocks
        LevelGenBase.setBlockAndMetadata(world, baseX + 4, baseY + 8, baseZ + 0, SokobanMod.BlockUnbreakableGlasses.blockID, 0); //tile.Unbreakable Glass Blocks
        LevelGenBase.setBlockAndMetadata(world, baseX + 4, baseY + 8, baseZ + 13, SokobanMod.BlockUnbreakableSolids.blockID, 0); //tile.Unbreakable Solid Blocks
        LevelGenBase.setBlockAndMetadata(world, baseX + 4, baseY + 8, baseZ + 15, SokobanMod.BlockUnbreakableSolids.blockID, 0); //tile.Unbreakable Solid Blocks
        LevelGenBase.setBlockAndMetadata(world, baseX + 4, baseY + 9, baseZ + 0, SokobanMod.BlockUnbreakableSolids.blockID, 0); //tile.Unbreakable Solid Blocks
        LevelGenBase.setBlockAndMetadata(world, baseX + 4, baseY + 9, baseZ + 1, SokobanMod.BlockUnbreakableGlasses.blockID, 0); //tile.Unbreakable Glass Blocks
        LevelGenBase.setBlockAndMetadata(world, baseX + 4, baseY + 9, baseZ + 2, SokobanMod.BlockUnbreakableGlasses.blockID, 0); //tile.Unbreakable Glass Blocks
        LevelGenBase.setBlockAndMetadata(world, baseX + 4, baseY + 9, baseZ + 3, SokobanMod.BlockUnbreakableGlasses.blockID, 0); //tile.Unbreakable Glass Blocks
        LevelGenBase.setBlockAndMetadata(world, baseX + 4, baseY + 9, baseZ + 4, SokobanMod.BlockUnbreakableGlasses.blockID, 0); //tile.Unbreakable Glass Blocks
        LevelGenBase.setBlockAndMetadata(world, baseX + 4, baseY + 9, baseZ + 5, SokobanMod.BlockUnbreakableGlasses.blockID, 0); //tile.Unbreakable Glass Blocks
        LevelGenBase.setBlockAndMetadata(world, baseX + 4, baseY + 9, baseZ + 6, SokobanMod.BlockUnbreakableGlasses.blockID, 0); //tile.Unbreakable Glass Blocks
        LevelGenBase.setBlockAndMetadata(world, baseX + 4, baseY + 9, baseZ + 7, SokobanMod.BlockUnbreakableGlasses.blockID, 0); //tile.Unbreakable Glass Blocks
        LevelGenBase.setBlockAndMetadata(world, baseX + 4, baseY + 9, baseZ + 8, SokobanMod.BlockUnbreakableGlasses.blockID, 0); //tile.Unbreakable Glass Blocks
        LevelGenBase.setBlockAndMetadata(world, baseX + 4, baseY + 9, baseZ + 9, SokobanMod.BlockUnbreakableGlasses.blockID, 0); //tile.Unbreakable Glass Blocks
        LevelGenBase.setBlockAndMetadata(world, baseX + 4, baseY + 9, baseZ + 10, SokobanMod.BlockUnbreakableGlasses.blockID, 0); //tile.Unbreakable Glass Blocks
        LevelGenBase.setBlockAndMetadata(world, baseX + 4, baseY + 9, baseZ + 11, SokobanMod.BlockUnbreakableGlasses.blockID, 0); //tile.Unbreakable Glass Blocks
        LevelGenBase.setBlockAndMetadata(world, baseX + 4, baseY + 9, baseZ + 12, SokobanMod.BlockUnbreakableGlasses.blockID, 0); //tile.Unbreakable Glass Blocks
        LevelGenBase.setBlockAndMetadata(world, baseX + 4, baseY + 9, baseZ + 13, SokobanMod.BlockUnbreakableSolids.blockID, 0); //tile.Unbreakable Solid Blocks
        LevelGenBase.setBlockAndMetadata(world, baseX + 4, baseY + 9, baseZ + 15, SokobanMod.BlockUnbreakableSolids.blockID, 0); //tile.Unbreakable Solid Blocks
        LevelGenBase.setBlockAndMetadata(world, baseX + 4, baseY + 10, baseZ + 0, SokobanMod.BlockUnbreakableSolids.blockID, 0); //tile.Unbreakable Solid Blocks
        LevelGenBase.setBlockAndMetadata(world, baseX + 4, baseY + 10, baseZ + 13, SokobanMod.BlockUnbreakableSolids.blockID, 0); //tile.Unbreakable Solid Blocks
        LevelGenBase.setBlockAndMetadata(world, baseX + 4, baseY + 10, baseZ + 14, SokobanMod.BlockUnbreakableSolids.blockID, 0); //tile.Unbreakable Solid Blocks
        LevelGenBase.setBlockAndMetadata(world, baseX + 4, baseY + 10, baseZ + 15, SokobanMod.BlockUnbreakableSolids.blockID, 0); //tile.Unbreakable Solid Blocks
        LevelGenBase.setBlockAndMetadata(world, baseX + 4, baseY + 11, baseZ + 0, SokobanMod.BlockUnbreakableGlasses.blockID, 0); //tile.Unbreakable Glass Blocks
        LevelGenBase.setBlockAndMetadata(world, baseX + 4, baseY + 11, baseZ + 15, SokobanMod.BlockUnbreakableGlasses.blockID, 0); //tile.Unbreakable Glass Blocks
        LevelGenBase.setBlockAndMetadata(world, baseX + 4, baseY + 12, baseZ + 0, SokobanMod.BlockUnbreakableSolids.blockID, 0); //tile.Unbreakable Solid Blocks
        LevelGenBase.setBlockAndMetadata(world, baseX + 4, baseY + 12, baseZ + 1, SokobanMod.BlockUnbreakableGlasses.blockID, 0); //tile.Unbreakable Glass Blocks
        LevelGenBase.setBlockAndMetadata(world, baseX + 4, baseY + 12, baseZ + 2, SokobanMod.BlockUnbreakableGlasses.blockID, 0); //tile.Unbreakable Glass Blocks
        LevelGenBase.setBlockAndMetadata(world, baseX + 4, baseY + 12, baseZ + 3, SokobanMod.BlockUnbreakableGlasses.blockID, 0); //tile.Unbreakable Glass Blocks
        LevelGenBase.setBlockAndMetadata(world, baseX + 4, baseY + 12, baseZ + 4, SokobanMod.BlockUnbreakableGlasses.blockID, 0); //tile.Unbreakable Glass Blocks
        LevelGenBase.setBlockAndMetadata(world, baseX + 4, baseY + 12, baseZ + 5, SokobanMod.BlockUnbreakableGlasses.blockID, 0); //tile.Unbreakable Glass Blocks
        LevelGenBase.setBlockAndMetadata(world, baseX + 4, baseY + 12, baseZ + 6, SokobanMod.BlockUnbreakableGlasses.blockID, 0); //tile.Unbreakable Glass Blocks
        LevelGenBase.setBlockAndMetadata(world, baseX + 4, baseY + 12, baseZ + 7, SokobanMod.BlockUnbreakableGlasses.blockID, 0); //tile.Unbreakable Glass Blocks
        LevelGenBase.setBlockAndMetadata(world, baseX + 4, baseY + 12, baseZ + 8, SokobanMod.BlockUnbreakableGlasses.blockID, 0); //tile.Unbreakable Glass Blocks
        LevelGenBase.setBlockAndMetadata(world, baseX + 4, baseY + 12, baseZ + 9, SokobanMod.BlockUnbreakableGlasses.blockID, 0); //tile.Unbreakable Glass Blocks
        LevelGenBase.setBlockAndMetadata(world, baseX + 4, baseY + 12, baseZ + 10, SokobanMod.BlockUnbreakableGlasses.blockID, 0); //tile.Unbreakable Glass Blocks
        LevelGenBase.setBlockAndMetadata(world, baseX + 4, baseY + 12, baseZ + 11, SokobanMod.BlockUnbreakableGlasses.blockID, 0); //tile.Unbreakable Glass Blocks
        LevelGenBase.setBlockAndMetadata(world, baseX + 4, baseY + 12, baseZ + 12, SokobanMod.BlockUnbreakableGlasses.blockID, 0); //tile.Unbreakable Glass Blocks
        LevelGenBase.setBlockAndMetadata(world, baseX + 4, baseY + 12, baseZ + 13, SokobanMod.BlockUnbreakableSolids.blockID, 0); //tile.Unbreakable Solid Blocks
        LevelGenBase.setBlockAndMetadata(world, baseX + 4, baseY + 12, baseZ + 14, SokobanMod.BlockUnbreakableSolids.blockID, 0); //tile.Unbreakable Solid Blocks
        LevelGenBase.setBlockAndMetadata(world, baseX + 4, baseY + 12, baseZ + 15, SokobanMod.BlockUnbreakableSolids.blockID, 0); //tile.Unbreakable Solid Blocks
